Workbook
Name _1st_shift_percentage: Data!$B$60
Name _2nd_shift_percentage: Data!$B$59
Name Amazon_Replen: Data!$B$58
Name Autobagger_Bander: Data!$B$28
Name Autobagger_Operator: Data!$B$27
Name Average_units_per_bin: Data!$B$52
Name Cartbuilding: Data!$B$18
Name Cartons_per_hour_Cubiscan: Data!$B$38
Name Cubiscan: Data!$B$36
Name DD: #REF!
Name DTC: Data!$B$9
Name DTC_to_replen: Data!$B$35
Name Exceptions: Data!$B$42
Name Gift_cards: Data!$B$21
Name Gift_cards_per_hour: Data!$B$26
Name Hours_1st: Data!$B$3
Name Hours_2nd: Data!$B$4
Name Inventory: Data!$B$50
Name Narvar: Data!$B$41
Name Open_orders: Data!$B$54
Name Overstock: Data!$B$33
Name Overstock_cycle_count: Data!$B$53
Name Pecentage_of_goal_2nd: Data!$B$6
Name Percentage_1st_Goal: Data!$B$43
Name Percentage_2nd_Goal: Data!$B$44
Name Percentage_Exceptions: Data!$B$47
Name Percentage_Narvar: Data!$B$45
Name Percentage_Non_Narvar: Data!$B$46
Name Percentage_of_goal_1st: Data!$B$5
Name Percentage_regular: Data!$B$14
Name Percentage_singles: Data!$B$15
Name Picking_cycle_count: Data!$B$51
Name Pieces_per_package: Data!$B$48
Name Planning: Data!$B$2
Name Receiving: Data!$B$34
Name Receiving_DD: #REF!
Name Region_1: Data!$B$10
Name Region_2: Data!$B$11
Name Region_7: Data!$B$12
Name Repack: Data!$B$22
Name Repack_goal: Data!$B$23
Name Replenishment_pull: Data!$B$31
Name Replenishment_throw: Data!$B$32
Name Resets: Data!$B$24
Name Resets_per_hour: Data!$B$25
Name Returns: Data!$B$39
Name Returns_put_away: Data!$B$40
Name Ship_bulk: Data!$B$16
Name Ship_singles: Data!$B$17
Name Stocking: Data!$B$30
Name Taper: Data!$B$19
Name Truck_loader: Data!$B$20
Name Units_per_carton: Data!$B$37
Name UPT: Data!$B$13
Name Wholesale: Data!$B$57

Sheet Outbound
A1: Fiscal Week | B1: =VLOOKUP(B3,FiscalCalendar!$A:$C,3,FALSE) -> 1 | C1: =VLOOKUP(C3,FiscalCalendar!$A:$C,3,FALSE) -> 1 | D1: =VLOOKUP(D3,FiscalCalendar!$A:$C,3,FALSE) -> 1 | E1: =VLOOKUP(E3,FiscalCalendar!$A:$C,3,FALSE) -> 1 | F1: =VLOOKUP(F3,FiscalCalendar!$A:$C,3,FALSE) -> 1 | G1: =VLOOKUP(G3,FiscalCalendar!$A:$C,3,FALSE) -> 1 | H1: =VLOOKUP(H3,FiscalCalendar!$A:$C,3,FALSE) -> 1 | I1: =VLOOKUP(I3,FiscalCalendar!$A:$C,3,FALSE) -> 2 | ... NA1: =VLOOKUP(NA3,FiscalCalendar!$A:$C,3,FALSE) -> 52
B2: Sunday | C2: Monday | D2: Tuesday | E2: Wednesday | F2: Thursday | G2: Friday | H2: Saturday | I2: Sunday | J2: Monday | K2: Tuesday | L2: Wednesday | M2: Thursday | N2: Friday | O2: Saturday | P2: Sunday | Q2: Monday | R2: Tuesday | S2: Wednesday | T2: Thursday | U2: Friday | V2: Saturday | W2: Sunday | X2: Monday | Y2: Tuesday | Z2: Wednesday | AA2: Thursday | AB2: Friday | AC2: Saturday | AD2: Sunday | AE2: Monday | AF2: Tuesday | AG2: Wednesday | AH2: Thursday | AI2: Friday | AJ2: Saturday | AK2: Sunday | AL2: Monday | AM2: Tuesday | AN2: Wednesday | AO2: Thursday | AP2: Friday | AQ2: Saturday | AR2: Sunday | AS2: Monday | AT2: Tuesday | AU2: Wednesday | AV2: Thursday | AW2: Friday | AX2: Saturday | AY2: Sunday | AZ2: Monday | BA2: Tuesday | BB2: Wednesday | BC2: Thursday | BD2: Friday | BE2: Saturday | BF2: Sunday | BG2: Monday | BH2: Tuesday | BI2: Wednesday | BJ2: Thursday | BK2: Friday | BL2: Saturday | BM2: Sunday | BN2: Monday | BO2: Tuesday | BP2: Wednesday | BQ2: Thursday | BR2: Friday | BS2: Saturday | BT2: Sunday | BU2: Monday | BV2: Tuesday | BW2: Wednesday | BX2: Thursday | BY2: Friday | BZ2: Saturday | CA2: Sunday | CB2: Monday | CC2: Tuesday | CD2: Wednesday | CE2: Thursday | CF2: Friday | CG2: Saturday | CH2: Sunday | CI2: Monday | CJ2: Tuesday | CK2: Wednesday | CL2: Thursday | CM2: Friday | CN2: Saturday | CO2: Sunday | CP2: Monday | CQ2: Tuesday | CR2: Wednesday | CS2: Thursday | CT2: Friday | CU2: Saturday | CV2: Sunday | CW2: Monday | CX2: Tuesday | CY2: Wednesday | CZ2: Thursday | DA2: Friday | DB2: Saturday | DC2: Sunday | DD2: Monday | DE2: Tuesday | DF2: Wednesday | DG2: Thursday | DH2: Friday | DI2: Saturday | DJ2: Sunday | DK2: Monday | DL2: Tuesday | DM2: Wednesday | DN2: Thursday | DO2: Friday | DP2: Saturday | DQ2: Sunday | DR2: Monday | DS2: Tuesday | DT2: Wednesday | DU2: Thursday | DV2: Friday | DW2: Saturday | DX2: Sunday | DY2: Monday | DZ2: Tuesday | EA2: Wednesday | EB2: Thursday | EC2: Friday | ED2: Saturday | EE2: Sunday | EF2: Monday | EG2: Tuesday | EH2: Wednesday | EI2: Thursday | EJ2: Friday | EK2: Saturday | EL2: Sunday | EM2: Monday | EN2: Tuesday | EO2: Wednesday | EP2: Thursday | EQ2: Friday | ER2: Saturday | ES2: Sunday | ET2: Monday | EU2: Tuesday | EV2: Wednesday | EW2: Thursday | EX2: Friday | EY2: Saturday | EZ2: Sunday | FA2: Monday | FB2: Tuesday | FC2: Wednesday | FD2: Thursday | FE2: Friday | FF2: Saturday | FG2: Sunday | FH2: Monday | FI2: Tuesday | FJ2: Wednesday | FK2: Thursday | FL2: Friday | FM2: Saturday | FN2: Sunday | FO2: Monday | FP2: Tuesday | FQ2: Wednesday | FR2: Thursday | FS2: Friday | FT2: Saturday | FU2: Sunday | FV2: Monday | FW2: Tuesday | FX2: Wednesday | FY2: Thursday | FZ2: Friday | GA2: Saturday | GB2: Sunday | GC2: Monday | GD2: Tuesday | GE2: Wednesday | GF2: Thursday | GG2: Friday | GH2: Saturday | GI2: Sunday | GJ2: Monday | GK2: Tuesday | GL2: Wednesday | GM2: Thursday | GN2: Friday | GO2: Saturday | GP2: Sunday | GQ2: Monday | GR2: Tuesday | GS2: Wednesday | GT2: Thursday | GU2: Friday | GV2: Saturday | GW2: Sunday | GX2: Monday | GY2: Tuesday | GZ2: Wednesday | HA2: Thursday | HB2: Friday | HC2: Saturday | HD2: Sunday | HE2: Monday | HF2: Tuesday | HG2: Wednesday | HH2: Thursday | HI2: Friday | HJ2: Saturday | HK2: Sunday | HL2: Monday | HM2: Tuesday | HN2: Wednesday | HO2: Thursday | HP2: Friday | HQ2: Saturday | HR2: Sunday | HS2: Monday | HT2: Tuesday | HU2: Wednesday | HV2: Thursday | HW2: Friday | HX2: Saturday | HY2: Sunday | HZ2: Monday | IA2: Tuesday | IB2: Wednesday | IC2: Thursday | ID2: Friday | IE2: Saturday | IF2: Sunday | IG2: Monday | IH2: Tuesday | II2: Wednesday | IJ2: Thursday | IK2: Friday | IL2: Saturday | IM2: Sunday | IN2: Monday | IO2: Tuesday | IP2: Wednesday | IQ2: Thursday | IR2: Friday | IS2: Saturday | IT2: Sunday | IU2: Monday | IV2: Tuesday | IW2: Wednesday | IX2: Thursday | IY2: Friday | IZ2: Saturday | JA2: Sunday | JB2: Monday | JC2: Tuesday | JD2: Wednesday | JE2: Thursday | JF2: Friday | JG2: Saturday | JH2: Sunday | JI2: Monday | JJ2: Tuesday | JK2: Wednesday | JL2: Thursday | JM2: Friday | JN2: Saturday | JO2: Sunday | JP2: Monday | JQ2: Tuesday | JR2: Wednesday | JS2: Thursday | JT2: Friday | JU2: Saturday | JV2: Sunday | JW2: Monday | JX2: Tuesday | JY2: Wednesday | JZ2: Thursday | KA2: Friday | KB2: Saturday | KC2: Sunday | KD2: Monday | KE2: Tuesday | KF2: Wednesday | KG2: Thursday | KH2: Friday | KI2: Saturday | KJ2: Sunday | KK2: Monday | KL2: Tuesday | KM2: Wednesday | KN2: Thursday | KO2: Friday | KP2: Saturday | KQ2: Sunday | KR2: Monday | KS2: Tuesday | KT2: Wednesday | KU2: Thursday | KV2: Friday | KW2: Saturday | KX2: Sunday | KY2: Monday | KZ2: Tuesday | LA2: Wednesday | LB2: Thursday | LC2: Friday | LD2: Saturday | LE2: Sunday | LF2: Monday | LG2: Tuesday | LH2: Wednesday | LI2: Thursday | LJ2: Friday | LK2: Saturday | LL2: Sunday | LM2: Monday | LN2: Tuesday | LO2: Wednesday | LP2: Thursday | LQ2: Friday | LR2: Saturday | LS2: Sunday | LT2: Monday | LU2: Tuesday | LV2: Wednesday | LW2: Thursday | LX2: Friday | LY2: Saturday | LZ2: Sunday | MA2: Monday | MB2: Tuesday | MC2: Wednesday | MD2: Thursday | ME2: Friday | MF2: Saturday | MG2: Sunday | MH2: Monday | MI2: Tuesday | MJ2: Wednesday | MK2: Thursday | ML2: Friday | MM2: Saturday | MN2: Sunday | MO2: Monday | MP2: Tuesday | MQ2: Wednesday | MR2: Thursday | MS2: Friday | MT2: Saturday | MU2: Sunday | MV2: Monday | MW2: Tuesday | MX2: Wednesday | MY2: Thursday | MZ2: Friday | NA2: Saturday | NB2: Sunday | NC2: Monday | ND2: Tuesday
B3: 45326 | C3: 45327 | D3: 45328 | E3: 45329 | F3: 45330 | G3: 45331 | H3: 45332 | I3: 45333 | J3: 45334 | K3: 45335 | L3: 45336 | M3: 45337 | N3: 45338 | O3: 45339 | P3: 45340 | Q3: 45341 | R3: 45342 | S3: 45343 | T3: 45344 | U3: 45345 | V3: 45346 | W3: 45347 | X3: 45348 | Y3: 45349 | Z3: 45350 | AA3: 45351 | AB3: 45352 | AC3: 45353 | AD3: 45354 | AE3: 45355 | AF3: 45356 | AG3: 45357 | AH3: 45358 | AI3: 45359 | AJ3: 45360 | AK3: 45361 | AL3: 45362 | AM3: 45363 | AN3: 45364 | AO3: 45365 | AP3: 45366 | AQ3: 45367 | AR3: 45368 | AS3: 45369 | AT3: 45370 | AU3: 45371 | AV3: 45372 | AW3: 45373 | AX3: 45374 | AY3: 45375 | AZ3: 45376 | BA3: 45377 | BB3: 45378 | BC3: 45379 | BD3: 45380 | BE3: 45381 | BF3: 45382 | BG3: 45383 | BH3: 45384 | BI3: 45385 | BJ3: 45386 | BK3: 45387 | BL3: 45388 | BM3: 45389 | BN3: 45390 | BO3: 45391 | BP3: 45392 | BQ3: 45393 | BR3: 45394 | BS3: 45395 | BT3: 45396 | BU3: 45397 | BV3: 45398 | BW3: 45399 | BX3: 45400 | BY3: 45401 | BZ3: 45402 | CA3: 45403 | CB3: 45404 | CC3: 45405 | CD3: 45406 | CE3: 45407 | CF3: 45408 | CG3: 45409 | CH3: 45410 | CI3: 45411 | CJ3: 45412 | CK3: 45413 | CL3: 45414 | CM3: 45415 | CN3: 45416 | CO3: 45417 | CP3: 45418 | CQ3: 45419 | CR3: 45420 | CS3: 45421 | CT3: 45422 | CU3: 45423 | CV3: 45424 | CW3: 45425 | CX3: 45426 | CY3: 45427 | CZ3: 45428 | DA3: 45429 | DB3: 45430 | DC3: 45431 | DD3: 45432 | DE3: 45433 | DF3: 45434 | DG3: 45435 | DH3: 45436 | DI3: 45437 | DJ3: 45438 | DK3: 45439 | DL3: 45440 | DM3: 45441 | DN3: 45442 | DO3: 45443 | DP3: 45444 | DQ3: 45445 | DR3: 45446 | DS3: 45447 | DT3: 45448 | DU3: 45449 | DV3: 45450 | DW3: 45451 | DX3: 45452 | DY3: 45453 | DZ3: 45454 | EA3: 45455 | EB3: 45456 | EC3: 45457 | ED3: 45458 | EE3: 45459 | EF3: 45460 | EG3: 45461 | EH3: 45462 | EI3: 45463 | EJ3: 45464 | EK3: 45465 | EL3: 45466 | EM3: 45467 | EN3: 45468 | EO3: 45469 | EP3: 45470 | EQ3: 45471 | ER3: 45472 | ES3: 45473 | ET3: 45474 | EU3: 45475 | EV3: 45476 | EW3: 45477 | EX3: 45478 | EY3: 45479 | EZ3: 45480 | FA3: 45481 | FB3: 45482 | FC3: 45483 | FD3: 45484 | FE3: 45485 | FF3: 45486 | FG3: 45487 | FH3: 45488 | FI3: 45489 | FJ3: 45490 | FK3: 45491 | FL3: 45492 | FM3: 45493 | FN3: 45494 | FO3: 45495 | FP3: 45496 | FQ3: 45497 | FR3: 45498 | FS3: 45499 | FT3: 45500 | FU3: 45501 | FV3: 45502 | FW3: 45503 | FX3: 45504 | FY3: 45505 | FZ3: 45506 | GA3: 45507 | GB3: 45508 | GC3: 45509 | GD3: 45510 | GE3: 45511 | GF3: 45512 | GG3: 45513 | GH3: 45514 | GI3: 45515 | GJ3: 45516 | GK3: 45517 | GL3: 45518 | GM3: 45519 | GN3: 45520 | GO3: 45521 | GP3: 45522 | GQ3: 45523 | GR3: 45524 | GS3: 45525 | GT3: 45526 | GU3: 45527 | GV3: 45528 | GW3: 45529 | GX3: 45530 | GY3: 45531 | GZ3: 45532 | HA3: 45533 | HB3: 45534 | HC3: 45535 | HD3: 45536 | HE3: 45537 | HF3: 45538 | HG3: 45539 | HH3: 45540 | HI3: 45541 | HJ3: 45542 | HK3: 45543 | HL3: 45544 | HM3: 45545 | HN3: 45546 | HO3: 45547 | HP3: 45548 | HQ3: 45549 | HR3: 45550 | HS3: 45551 | HT3: 45552 | HU3: 45553 | HV3: 45554 | HW3: 45555 | HX3: 45556 | HY3: 45557 | HZ3: 45558 | IA3: 45559 | IB3: 45560 | IC3: 45561 | ID3: 45562 | IE3: 45563 | IF3: 45564 | IG3: 45565 | IH3: 45566 | II3: 45567 | IJ3: 45568 | IK3: 45569 | IL3: 45570 | IM3: 45571 | IN3: 45572 | IO3: 45573 | IP3: 45574 | IQ3: 45575 | IR3: 45576 | IS3: 45577 | IT3: 45578 | IU3: 45579 | IV3: 45580 | IW3: 45581 | IX3: 45582 | IY3: 45583 | IZ3: 45584 | JA3: 45585 | JB3: 45586 | JC3: 45587 | JD3: 45588 | JE3: 45589 | JF3: 45590 | JG3: 45591 | JH3: 45592 | JI3: 45593 | JJ3: 45594 | JK3: 45595 | JL3: 45596 | JM3: 45597 | JN3: 45598 | JO3: 45599 | JP3: 45600 | JQ3: 45601 | JR3: 45602 | JS3: 45603 | JT3: 45604 | JU3: 45605 | JV3: 45606 | JW3: 45607 | JX3: 45608 | JY3: 45609 | JZ3: 45610 | KA3: 45611 | KB3: 45612 | KC3: 45613 | KD3: 45614 | KE3: 45615 | KF3: 45616 | KG3: 45617 | KH3: 45618 | KI3: 45619 | KJ3: 45620 | KK3: 45621 | KL3: 45622 | KM3: 45623 | KN3: 45624 | KO3: 45625 | KP3: 45626 | KQ3: 45627 | KR3: 45628 | KS3: 45629 | KT3: 45630 | KU3: 45631 | KV3: 45632 | KW3: 45633 | KX3: 45634 | KY3: 45635 | KZ3: 45636 | LA3: 45637 | LB3: 45638 | LC3: 45639 | LD3: 45640 | LE3: 45641 | LF3: 45642 | LG3: 45643 | LH3: 45644 | LI3: 45645 | LJ3: 45646 | LK3: 45647 | LL3: 45648 | LM3: 45649 | LN3: 45650 | LO3: 45651 | LP3: 45652 | LQ3: 45653 | LR3: 45654 | LS3: 45655 | LT3: 45656 | LU3: 45657 | LV3: 45658 | LW3: 45659 | LX3: 45660 | LY3: 45661 | LZ3: 45662 | MA3: 45663 | MB3: 45664 | MC3: 45665 | MD3: 45666 | ME3: 45667 | MF3: 45668 | MG3: 45669 | MH3: 45670 | MI3: 45671 | MJ3: 45672 | MK3: 45673 | ML3: 45674 | MM3: 45675 | MN3: 45676 | MO3: 45677 | MP3: 45678 | MQ3: 45679 | MR3: 45680 | MS3: 45681 | MT3: 45682 | MU3: 45683 | MV3: 45684 | MW3: 45685 | MX3: 45686 | MY3: 45687 | MZ3: 45688 | NA3: 45689 | NB3: 45690 | NC3: 45691 | ND3: 45692
A4: Orders | BG4: Stress Test | BW4: OT for next Friday? | CE4: F&F Sale | CF4: OT/GIG? | CH4: 2nd 10 hours | CI4: Goals w/ 10 GIG + 50 | CQ4: One truck for FedEx | CW4: Gigs for next week? | CY4: Updated | CZ4: Gigs for Sun? | DA4: Updated | DD4: 5 GIG per day, WE at 40 | DF4: Memorial Day Sale | DJ4: Goals at 50 hrs + 5 GIG | DZ4: Schedule for week of 6/23- Days off Monday? | EG4: Dayshift off next Monday for Fri/Sat? | EM4: Days off? | EO4: 20 GIG 10/10 | ES4: 2nd 10 hrs | EX4: OT 1st | FB4: OT WE | FE4: OT 1st and 2nd | FF4: Vol Days | GA4: Quarter End | GE4: Bastian- shipping down | GQ4: Review OT/GIG next week | HB4: Vol 1st? | HE4: GIGs, WE OT- 2nd 10 hrs | IA4: UPDATED | IB4: F&F schedule for Week of 10/6 | IX4: Updated | KM4: Updated | KY4: SP (GE) Cut-off | LE4: Last Day for Ground | LH4: Last Day for 3D | LI4: 2D HI/AK Cut-off | LL4: Last Day for Overnights | LW4: GIG??
A5: Remaining Volume (Units) | B5: 9965 | C5: =B5-B7+B10 -> 11431 | D5: =C5-C7+C10 -> 8974 | E5: =D5-D7+D10 -> 10764 | F5: =E5-E7+E10 -> 10533 | G5: =F5-F7+F10 -> 9827 | H5: =G5-G7+G10 -> 13249 | I5: =H5-H7+H10 -> 14210 | J5: =I5-I7+I10 -> 11337 | ... CI5: =CH5-CH7+CH10 -> 30949 | CJ5: 18054 | CK5: =CJ5-CJ7+CJ10 -> 33890 | CL5: =CK5-CK7+CK10 -> 42204 | CM5: =CL5-CL7+CL10 -> 32075 | CN5: =CM5-CM7+CM10 -> 35636 | CO5: =CN5-CN7+CN10 -> 25965 | CP5: =CO5-CO7+CO10 -> 36277 | CQ5: =CP5-CP7+CP10 -> 33617 | CR5: =CQ5-CQ7+CQ10 -> 24566 | ... DD5: =DC5-DC7+DC10 -> 18254 | DE5: 18965 | DF5: =DE5-DE7+DE10 -> 28229 | DG5: =DF5-DF7+DF10 -> 36985 | DH5: =DG5-DG7+DG10 -> 45624 | DI5: =DH5-DH7+DH10 -> 55493 | DJ5: =DI5-DI7+DI10 -> 62235 | DK5: =DJ5-DJ7+DJ10 -> 70220 | DL5: =DK5-DK7+DK10 -> 108277 | DM5: =DL5-DL7+DL10 -> 69962 | ... DZ5: =DY5-DY7+DY10 -> 8093 | EA5: 5768 | EB5: =EA5-EA7+EA10 -> 4843 | EC5: =EB5-EB7+EB10 -> 4562 | ED5: =EC5-EC7+EC10 -> 9101 | EE5: =ED5-ED7+ED10 -> 11163 | EF5: =EE5-EE7+EE10 -> 26378 | EG5: =EF5-EF7+EF10 -> 13124 | EH5: =EG5-EG7+EG10 -> 11541 | EI5: =EH5-EH7+EH10 -> 11172 | ... FY5: =FX5-FX7+FX10 -> 10049 | FZ5: 7779 | GA5: 13927 | GB5: =GA5-GA7+GA10 -> 15705 | GC5: =GB5-GB7+GB10 -> 12603 | GD5: =GC5-GC7+GC10 -> 11548.009 | GE5: =GD5-GD7+GD10 -> 12801.009 | GF5: =GE5-GE7+GE10 -> 14468.009 | GG5: =GF5-GF7+GF10 -> 16739.009 | GH5: =GG5-GG7+GG10 -> 20707.009 | GI5: =GH5-GH7+GH10 -> 28152.009 | ... HA5: =GZ5-GZ7+GZ10 -> 42571.009 | HB5: 54078 | HC5: =HB5-HB7+HB10 -> 69991 | HD5: =HC5-HC7+HC10 -> 87979 | HE5: 93071 | HF5: =HE5-HE7+HE10 -> 127150 | HG5: =HF5-HF7+HF10 -> 106472 | HH5: =HG5-HG7+HG10 -> 82545 | HI5: =HH5-HH7+HH10 -> 64138 | HJ5: =HI5-HI7+HI10 -> 50172 | HK5: =HJ5-HJ7+HJ10 -> 40535 | HL5: =HK5-HK7+HK10 -> 27630 | HM5: =HL5-HL7+HL10 -> 16259 | ... IU5: =IT5-IT7+IT10 -> 51542 | IV5: 32004 | IW5: =IV5-IV7+IV10 -> 34416 | IX5: 78856 | IY5: =IX5-IX7+IX10 -> 82299 | IZ5: =IY5-IY7+IY10 -> 61385 | JA5: =IZ5-IZ7+IZ10 -> 103811 | JB5: =JA5-JA7+JA10 -> 110100 | JC5: =JB5-JB7+JB10 -> 79974 | JD5: =JC5-JC7+JC10 -> 50023 | JE5: =JD5-JD7+JD10 -> 23320 | JF5: =JE5-JE7+JE10 -> 11652 | ... KK5: =KJ5-KJ7+KJ10 -> 97869 | KL5: 91178 | KM5: =KL5-KL7+KL10 -> 63908 | KN5: =KM5-KM7+KM10 -> 46894 | KO5: =KN5-KN7+KN10 -> 115726 | KP5: =KO5-KO7+KO10 -> 166564 | KQ5: =KP5-KP7+KP10 -> 163408 | KR5: =KQ5-KQ7+KQ10 -> 159112 | KS5: 237918 | KT5: =KS5-KS7+KS10 -> 237574 | KU5: 183511 | KV5: =KU5-KU7+KU10 -> 142506 | KW5: =KV5-KV7+KV10 -> 94813 | KX5: =KW5-KW7+KW10 -> 104177 | KY5: =KX5-KX7+KX10 -> 81923 | KZ5: =KY5-KY7+KY10 -> 50815 | LA5: =KZ5-KZ7+KZ10 -> 28770 | LB5: =LA5-LA7+LA10 -> 22584 | LC5: =LB5-LB7+LB10 -> 42907 | ... LO5: =LN5-LN7+LN10 -> 6675 | LP5: 23720 | LQ5: =LP5-LP7+LP10 -> 33631 | LR5: =LQ5-LQ7+LQ10 -> 15343 | LS5: =LR5-LR7+LR10 -> 40873 | LT5: =LS5-LS7+LS10 -> 37990 | LU5: =LT5-LT7+LT10 -> 41344 | LV5: =LU5-LU7+LU10 -> 79623 | LW5: =LV5-LV7+LV10 -> 124540 | LX5: =LW5-LW7+LW10 -> 96216 | ... ND5: =NC5-NC7+NC10 -> #N/A
A6: Units Shipped Goal | B6: 9000 | C6: 10000 | D6: 8000 | E6: 8000 | F6: 10000 | G6: 7000 | H6: 7000 | I6: 10000 | J6: 10000 | K6: 8000 | L6: 8000 | M6: 7000 | N6: 10000 | O6: 15000 | P6: 15000 | Q6: 19000 | R6: 22000 | S6: 16000 | T6: 7000 | U6: 7000 | V6: 11000 | W6: 11000 | X6: 7500 | Y6: 9000 | Z6: 10000 | AA6: 10000 | AB6: 10000 | AC6: 10000 | AD6: 12000 | AE6: 10000 | AF6: 12000 | AG6: 10000 | AH6: 10000 | AI6: 8000 | AJ6: 12000 | AK6: 14000 | AL6: 12000 | AM6: 12000 | AN6: 12000 | AO6: 10000 | AP6: 11000 | AQ6: 12000 | AR6: 14000 | AS6: 14000 | AT6: 12000 | AU6: 9000 | AV6: 10000 | AW6: 13000 | AX6: 14000 | AY6: 25000 | AZ6: 30000 | BA6: 25000 | BB6: 14000 | BC6: 9000 | BD6: 7000 | BE6: 11000 | BF6: 0 | BG6: 30000 | BH6: 13000 | BI6: 14000 | BJ6: 13000 | BK6: 11000 | BL6: 14000 | BM6: 20000 | BN6: 21000 | BO6: 16000 | BP6: 6000 | BQ6: 11000 | BR6: 7000 | BS6: 11000 | BT6: 13000 | BU6: 10000 | BV6: 11000 | BW6: 10000 | BX6: 11000 | BY6: 8000 | BZ6: 7000 | CA6: 16000 | CB6: 12000 | CC6: 12000 | CD6: 8000 | CE6: 25000 | CF6: 34000 | CG6: 24000 | CH6: 32000 | CI6: 40000 | CJ6: 38000 | CK6: 28000 | CL6: 38000 | CM6: 40000 | CN6: 24500 | CO6: 25000 | CP6: 30000 | CQ6: 20000 | CR6: 20000 | CS6: 15000 | CT6: 13000 | CU6: 13000 | CV6: 0 | CW6: 23000 | CX6: 14000 | CY6: 12000 | CZ6: 10000 | DA6: 9000 | DB6: 9000 | DC6: 23000 | DD6: 37000 | DE6: 24000 | DF6: 24000 | DG6: 24000 | DH6: 14000 | DI6: 16000 | DJ6: 30000 | DK6: 41000 | DL6: 38000 | DM6: 34000 | DN6: 24000 | DO6: 20000 | DP6: 14000 | DQ6: 20000 | DR6: 15000 | DS6: 11000 | DT6: 11000 | DU6: 10000 | DV6: 8000 | DW6: 10000 | DX6: 14000 | DY6: 20000 | DZ6: 10000 | EA6: 8000 | EB6: 8000 | EC6: 7000 | ED6: 8000 | EE6: 0 | EF6: 26000 | EG6: 11000 | EH6: 11000 | EI6: 13000 | EJ6: 10000 | EK6: 10000 | EL6: 11000 | EM6: 13000 | EN6: 10000 | EO6: 26000 | EP6: 38000 | EQ6: 22000 | ER6: 18000 | ES6: 35000 | ET6: 35000 | EU6: 38000 | EV6: 30000 | EW6: 35000 | EX6: 25000 | EY6: 20000 | EZ6: 36000 | FA6: 30000 | FB6: 45000 | FC6: 37000 | FD6: 40000 | FE6: 48000 | FF6: 26000 | FG6: 36000 | FH6: 50000 | FI6: 25000 | FJ6: 13000 | FK6: 12000 | FL6: 13000 | FM6: =FM5 -> 10701 | FN6: =FN5 -> 14852 | FO6: 15000 | FP6: 9000 | FQ6: 10000 | FR6: 10000 | FS6: 10000 | FT6: 16000 | FU6: 22000 | FV6: 15000 | FW6: 13000 | FX6: 12000 | FY6: 12000 | FZ6: 10000 | GA6: 13000 | GB6: 11000 | GC6: 15000 | GD6: 10000 | GE6: 12000 | GF6: 12000 | GG6: 14000 | GH6: 14000 | GI6: 30000 | GJ6: 32000 | GK6: 15000 | GL6: 14000 | GM6: 15000 | GN6: 10000 | GO6: 16000 | GP6: 20000 | GQ6: 13000 | GR6: 13000 | GS6: 14000 | GT6: 14000 | GU6: 10000 | GV6: 14000 | GW6: 35000 | GX6: 40000 | GY6: 30000 | GZ6: 30000 | HA6: 30000 | HB6: 18000 | HC6: 18000 | HD6: 34000 | HE6: 65000 | HF6: 50000 | HG6: 45000 | HH6: 30000 | HI6: 30000 | HJ6: 28000 | HK6: 35000 | HL6: 20000 | HM6: 18000 | HN6: 15000 | HO6: 12000 | HP6: 18000 | HQ6: 20000 | HR6: 30000 | HS6: 15000 | HT6: 11000 | HU6: 10000 | HV6: 14000 | HW6: 18000 | HX6: 20000 | HY6: 35000 | HZ6: 30000 | IA6: 22000 | IB6: 20000 | IC6: 12000 | ID6: 8000 | IE6: 13000 | IF6: 21500 | IG6: 21000 | IH6: 17000 | II6: 12000 | IJ6: 13500 | IK6: 12000 | IL6: 12000 | IM6: 20000 | IN6: 18000 | IO6: 18000 | IP6: 42000 | IQ6: 60000 | IR6: 30000 | IS6: 35000 | IT6: 55000 | IU6: 65000 | IV6: 50000 | IW6: 45000 | IX6: 55000 | IY6: 70000 | IZ6: 30000 | JA6: 55000 | JB6: 75000 | JC6: 46000 | JD6: 44000 | JE6: 25000 | JF6: 15000 | JG6: 18000 | JH6: 40000 | JI6: 19000 | JJ6: 17000 | JK6: 15000 | JL6: 10000 | JM6: 20000 | JN6: 25000 | JO6: 40000 | JP6: 65000 | JQ6: 40000 | JR6: 25000 | JS6: 15000 | JT6: 20000 | JU6: 25000 | JV6: 40000 | JW6: 55000 | JX6: 27000 | JY6: 27000 | JZ6: 20000 | KA6: 25000 | KB6: 25000 | KC6: 50000 | KD6: 70000 | KE6: 60000 | KF6: 60000 | KG6: 60000 | KH6: 30000 | KI6: 25000 | KJ6: 90000 | KK6: 90000 | KL6: 85000 | KM6: 85000 | KN6: 0 | KO6: 90000 | KP6: 90000 | KQ6: 90000 | KR6: 90000 | KS6: 80000 | KT6: 85000 | KU6: 75000 | KV6: 85000 | KW6: 30000 | KX6: 70000 | KY6: 65000 | KZ6: 50000 | LA6: 40000 | LB6: 40000 | LC6: 27000 | LD6: 35000 | LE6: 60000 | LF6: 60000 | LG6: 42000 | LH6: 30000 | LI6: 13000 | LJ6: 13000 | LK6: 13000 | LL6: 13000 | LM6: 6000 | LN6: 0 | LO6: 0 | LP6: 40000 | LQ6: 60000 | LR6: 30000 | LS6: 55000 | LT6: 60000 | LU6: 0 | LV6: 0 | LW6: 75000 | LX6: 70000 | LY6: 35000 | LZ6: 15000 | MA6: 0 | MB6: 55000 | MC6: 55000 | MD6: 55000 | ME6: 30000 | MF6: 15000 | MG6: 20000 | MH6: 10000 | MI6: 10000 | MJ6: 8000 | MK6: 10000 | ML6: 7000 | MM6: 7000 | MN6: 25000 | MO6: 15000 | MP6: 12000 | MQ6: 9000 | MR6: 6000 | MS6: 6000 | MT6: 6000 | MU6: 8000 | MV6: 8000 | MW6: 6000 | MX6: 8000 | MY6: 8000 | MZ6: 10000 | NA6: 10000 | NB6: =NB5 -> -346.88145 | NC6: =NC5 -> #N/A | ND6: =ND5 -> #N/A
A7: Shipped Units (PowerBi) | B7: 7028 | C7: 11030 | D7: 8301 | E7: 10006 | F7: 10004 | G7: 6291 | H7: 8069 | I7: 12243 | J7: 9297 | K7: 9386 | L7: 6868 | M7: 7892 | N7: 7975 | O7: 15736 | P7: 20970 | Q7: 24808 | R7: 26065 | S7: 17029 | T7: 8019 | U7: 5746 | V7: 9452 | W7: 13993 | X7: 10907 | Y7: 12035 | Z7: 9572 | AA7: 9434 | AB7: 8403 | AC7: 6558 | AD7: 15333 | AE7: 11306 | AF7: 13076 | AG7: 10315 | AH7: 10452 | AI7: 5085 | AJ7: 11236 | AK7: 17689 | AL7: 11291 | AM7: 12483 | AN7: 12935 | AO7: 12623 | AP7: 6157 | AQ7: 13536 | AR7: 20112 | AS7: 16489 | AT7: 12764 | AU7: 9864 | AV7: 10346 | AW7: 8165 | AX7: 10566 | AY7: 23002 | AZ7: 32841 | BA7: 22053 | BB7: 18085 | BC7: 7627 | BD7: 4856 | BE7: 9019 | BF7: =BF6 -> 0 | BG7: 24586 | BH7: 12921 | BI7: 17255 | BJ7: 14174 | BK7: 11336 | BL7: 12058 | BM7: 18952 | BN7: 24838 | BO7: 19092 | BP7: 9269 | BQ7: 14181 | BR7: 5411 | BS7: 6780 | BT7: 13908 | BU7: 10961 | BV7: 11394 | BW7: 12254 | BX7: 9859 | BY7: 5519 | BZ7: 8556 | CA7: 19542 | CB7: 16314 | CC7: 12676 | CD7: 7957 | CE7: 19580 | CF7: 33404 | CG7: 19630 | CH7: 32010 | CI7: 39427 | CJ7: 30972 | CK7: 28828 | CL7: 43159 | CM7: 39396 | CN7: 31727 | CO7: 24422 | CP7: 30693 | CQ7: 21439 | CR7: 16601 | CS7: 15830 | CT7: 8666 | CU7: 16817 | CV7: =CV6 -> 0 | CW7: 27162 | CX7: 18896 | CY7: 14896 | CZ7: 11224 | DA7: 5745 | DB7: 9894 | DC7: 25657 | DD7: 32179 | DE7: 27715 | DF7: 25482 | DG7: 25048 | DH7: 16334 | DI7: 21985 | DJ7: 34778 | DK7: 41805 | DL7: 50920 | DM7: 40342 | DN7: 20073 | DO7: 15649 | DP7: 15770 | DQ7: 20523 | DR7: 13722 | DS7: 13642 | DT7: 13141 | DU7: 14180 | DV7: 5934 | DW7: 9112 | DX7: 18096 | DY7: 21317 | DZ7: 11681 | EA7: 11679 | EB7: 10402 | EC7: 5362 | ED7: 10310 | EE7: =EE6 -> 0 | EF7: 26734 | EG7: 14944 | EH7: 14550 | EI7: 14206 | EJ7: 8144 | EK7: 11953 | EL7: 14900 | EM7: 18549 | EN7: 12945 | EO7: 25171 | EP7: 33691 | EQ7: 21643 | ER7: 18895 | ES7: 36048 | ET7: 41273 | EU7: 38597 | EV7: 29666 | EW7: 37283 | EX7: 23624 | EY7: 12514 | EZ7: 35384 | FA7: 27990 | FB7: 39934 | FC7: 34520 | FD7: 46802 | FE7: 47655 | FF7: 27540 | FG7: 37660 | FH7: 41640 | FI7: 21442 | FJ7: 15699 | FK7: 14084 | FL7: 3298 | FM7: 8309 | FN7: 18774 | FO7: 12677 | FP7: 9451 | FQ7: 12156 | FR7: 10463 | FS7: 5536 | FT7: 6760 | FU7: 20553 | FV7: 15052 | FW7: 12710 | FX7: 12152 | FY7: 10802 | FZ7: 5543 | GA7: 11418 | GB7: 18336 | GC7: 16113 | GD7: 13510 | GE7: 13486 | GF7: 12878 | GG7: 10612 | GH7: 16829 | GI7: 28443 | GJ7: 32020 | GK7: 16873 | GL7: 14724 | GM7: 16154 | GN7: 10635 | GO7: 12435 | GP7: 24239 | GQ7: 18169 | GR7: 14276 | GS7: 16699 | GT7: 15711 | GU7: 11928 | GV7: 14766 | GW7: 29966 | GX7: 35579 | GY7: 26341 | GZ7: 27557 | HA7: 25741 | HB7: 15997 | HC7: 30360 | HD7: 44340 | HE7: 54910 | HF7: 51584 | HG7: 36912 | HH7: 30896 | HI7: 24869 | HJ7: 25768 | HK7: 29803 | HL7: 25284 | HM7: 12738 | HN7: 13499 | HO7: 16286 | HP7: 11566 | HQ7: 15035 | HR7: 21623 | HS7: 16605 | HT7: 15823 | HU7: 14872 | HV7: 20227 | HW7: 12590 | HX7: 21523 | HY7: 36301 | HZ7: 31672 | IA7: 26319 | IB7: 24025 | IC7: 14186 | ID7: 8952 | IE7: 12471 | IF7: 28083 | IG7: 23659 | IH7: 22508 | II7: 17117 | IJ7: 15879 | IK7: 12599 | IL7: 15475 | IM7: 26151 | IN7: 21606 | IO7: 16346 | IP7: 38456 | IQ7: 55582 | IR7: 31418 | IS7: 34426 | IT7: 66498 | IU7: 74373 | IV7: 45916 | IW7: 45004 | IX7: 62109 | IY7: 75246 | IZ7: 38157 | JA7: 57722 | JB7: 78871 | JC7: 47944 | JD7: 44548 | JE7: 29808 | JF7: 16945 | JG7: 18675 | JH7: 36626 | JI7: 28941 | JJ7: 21947 | JK7: 17802 | JL7: 14095 | JM7: 11109 | JN7: 31568 | JO7: 45700 | JP7: 73083 | JQ7: 45448 | JR7: 28874 | JS7: 21260 | JT7: 16847 | JU7: 19781 | JV7: 42653 | JW7: 55282 | JX7: 37432 | JY7: 30270 | JZ7: 27852 | KA7: 19448 | KB7: 26397 | KC7: 52388 | KD7: 64049 | KE7: 55183 | KF7: 58974 | KG7: 63658 | KH7: 36346 | KI7: 28569 | KJ7: 94944 | KK7: 92928 | KL7: 91515 | KM7: 79687 | KN7: 22 | KO7: 100193 | KP7: 106929 | KQ7: 101950 | KR7: 91683 | KS7: 85799 | KT7: 89009 | KU7: 79183 | KV7: 81542 | KW7: 32234 | KX7: 71248 | KY7: 69013 | KZ7: 58985 | LA7: 43366 | LB7: 43095 | LC7: 20709 | LD7: 23897 | LE7: 63732 | LF7: 60785 | LG7: 58941 | LH7: 33558 | LI7: 17819 | LJ7: 15880 | LK7: 14458 | LL7: 14695 | LM7: 7192 | LN7: =LN6 -> 0 | LO7: =LO6 -> 0 | LP7: 44016 | LQ7: 54967 | LR7: 24897 | LS7: 48455 | LT7: 56680 | LU7: 47 | LV7: =LV6 -> 0 | LW7: 70652 | LX7: 65144 | LY7: 39070 | LZ7: 9229 | MA7: =MA6 -> 0 | MB7: 39511 | MC7: 65999 | MD7: 59234 | ME7: 25152 | MF7: 21493 | MG7: 21716 | MH7: 13330 | MI7: 11918 | MJ7: 10918 | MK7: 11954 | ML7: 7574 | MM7: 8046 | MN7: 22951 | MO7: 18491 | MP7: 15183 | MQ7: 13373 | MR7: 8588 | MS7: 8081 | MT7: 8198 | MU7: 11641 | MV7: 11159 | MW7: 8474 | MX7: 8817 | MY7: 7942 | MZ7: 5169 | NA7: 10346 | NB7: 7700 | NC7: =NC6 -> #N/A | ND7: =ND6 -> #N/A
A8: Forecasted Demand (Units) | B8: =VLOOKUP(B$3,'KPI DC Forecast link file'!$B:$C,2,FALSE) -> 8494.0048 | C8: =VLOOKUP(C$3,'KPI DC Forecast link file'!$B:$C,2,FALSE) -> 8573.003 | D8: =VLOOKUP(D$3,'KPI DC Forecast link file'!$B:$C,2,FALSE) -> 10091.005 | E8: =VLOOKUP(E$3,'KPI DC Forecast link file'!$B:$C,2,FALSE) -> 9774.9927 | F8: =VLOOKUP(F$3,'KPI DC Forecast link file'!$B:$C,2,FALSE) -> 9297.9975 | G8: =VLOOKUP(G$3,'KPI DC Forecast link file'!$B:$C,2,FALSE) -> 9713.0109 | H8: =VLOOKUP(H$3,'KPI DC Forecast link file'!$B:$C,2,FALSE) -> 9030.0076 | I8: =VLOOKUP(I$3,'KPI DC Forecast link file'!$B:$C,2,FALSE) -> 9370.0009 | ... FM8: =VLOOKUP(FM$3,'KPI DC Forecast link file'!$B:$C,2,FALSE) -> 12460.001 | FN8: 12395 | FO8: =VLOOKUP(FO$3,'KPI DC Forecast link file'!$B:$C,2,FALSE) -> 8930.0095 | FP8: =VLOOKUP(FP$3,'KPI DC Forecast link file'!$B:$C,2,FALSE) -> 11373.013 | FQ8: =VLOOKUP(FQ$3,'KPI DC Forecast link file'!$B:$C,2,FALSE) -> 12759.003 | FR8: =VLOOKUP(FR$3,'KPI DC Forecast link file'!$B:$C,2,FALSE) -> 8781.005 | FS8: =VLOOKUP(FS$3,'KPI DC Forecast link file'!$B:$C,2,FALSE) -> 11359.993 | FT8: =VLOOKUP(FT$3,'KPI DC Forecast link file'!$B:$C,2,FALSE) -> 10645.003 | FU8: =VLOOKUP(FU$3,'KPI DC Forecast link file'!$B:$C,2,FALSE) -> 13618.005 | FV8: =VLOOKUP(FV$3,'KPI DC Forecast link file'!$B:$C,2,FALSE) -> 16522.995 | FW8: 10637 | FX8: 10008 | FY8: 11166 | FZ8: =VLOOKUP(FZ$3,'KPI DC Forecast link file'!$B:$C,2,FALSE) -> 11879.993 | GA8: =VLOOKUP(GA$3,'KPI DC Forecast link file'!$B:$C,2,FALSE) -> 13195.986 | GB8: =VLOOKUP(GB$3,'KPI DC Forecast link file'!$B:$C,2,FALSE) -> 15233.987 | GC8: =VLOOKUP(GC$3,'KPI DC Forecast link file'!$B:$C,2,FALSE) -> 15058.009 | GD8: =VLOOKUP(GD$3,'KPI DC Forecast link file'!$B:$C,2,FALSE) -> 14762.995 | GE8: =VLOOKUP(GE$3,'KPI DC Forecast link file'!$B:$C,2,FALSE) -> 15152.006 | GF8: =VLOOKUP(GF$3,'KPI DC Forecast link file'!$B:$C,2,FALSE) -> 15148.979 | GG8: =VLOOKUP(GG$3,'KPI DC Forecast link file'!$B:$C,2,FALSE) -> 14580.003 | ... IO8: =VLOOKUP(IO$3,'KPI DC Forecast link file'!$B:$C,2,FALSE) -> 15341.015 | IP8: 85287 | IQ8: 53043 | IR8: 57771 | IS8: 63886 | IT8: 64006 | IU8: 58801 | IV8: 61610 | IW8: 46298 | IX8: 69307 | IY8: 65340 | IZ8: 107939 | JA8: 71110 | JB8: 62421 | JC8: 27908 | JD8: =VLOOKUP(JD$3,'KPI DC Forecast link file'!$B:$C,2,FALSE) -> 17844.992 | JE8: =VLOOKUP(JE$3,'KPI DC Forecast link file'!$B:$C,2,FALSE) -> 18140.005 | JF8: =VLOOKUP(JF$3,'KPI DC Forecast link file'!$B:$C,2,FALSE) -> 17682.01 | JG8: =VLOOKUP(JG$3,'KPI DC Forecast link file'!$B:$C,2,FALSE) -> 26884.025 | JH8: =VLOOKUP(JH$3,'KPI DC Forecast link file'!$B:$C,2,FALSE) -> 30915.027 | JI8: =VLOOKUP(JI$3,'KPI DC Forecast link file'!$B:$C,2,FALSE) -> 22065.004 | JJ8: =VLOOKUP(JJ$3,'KPI DC Forecast link file'!$B:$C,2,FALSE) -> 18033.006 | JK8: =VLOOKUP(JK$3,'KPI DC Forecast link file'!$B:$C,2,FALSE) -> 17083.999 | ... KA8: =VLOOKUP(KA$3,'KPI DC Forecast link file'!$B:$C,2,FALSE) -> 28467.022 | KB8: 45960 | KC8: 45647 | KD8: 43441 | KE8: 81560 | KF8: 64193 | KG8: 57970 | KH8: 57970 | KI8: 71538 | KJ8: 79106 | KK8: 86932 | KL8: 73412 | KM8: 61256 | KN8: 64798 | KO8: 155083 | KP8: 103836 | KQ8: 115582 | KR8: 128162 | KS8: =VLOOKUP(KS$3,'KPI DC Forecast link file'!$B:$C,2,FALSE) -> 85454.891 | KT8: 32997 | KU8: 33457 | KV8: =VLOOKUP(KV$3,'KPI DC Forecast link file'!$B:$C,2,FALSE) -> 33848.971 | KW8: =VLOOKUP(KW$3,'KPI DC Forecast link file'!$B:$C,2,FALSE) -> 41597.961 | KX8: =VLOOKUP(KX$3,'KPI DC Forecast link file'!$B:$C,2,FALSE) -> 48994.03 | KY8: =VLOOKUP(KY$3,'KPI DC Forecast link file'!$B:$C,2,FALSE) -> 37905.018 | KZ8: =VLOOKUP(KZ$3,'KPI DC Forecast link file'!$B:$C,2,FALSE) -> 36939.993 | LA8: =VLOOKUP(LA$3,'KPI DC Forecast link file'!$B:$C,2,FALSE) -> 37180.02 | LB8: =VLOOKUP(LB$3,'KPI DC Forecast link file'!$B:$C,2,FALSE) -> 63417.96 | LC8: =VLOOKUP(LC$3,'KPI DC Forecast link file'!$B:$C,2,FALSE) -> 48838.96 | ... MG8: =VLOOKUP(MG$3,'KPI DC Forecast link file'!$B:$C,2,FALSE) -> 12389.014 | MH8: 11917 | MI8: =VLOOKUP(MI$3,'KPI DC Forecast link file'!$B:$C,2,FALSE) -> 11498.001 | MJ8: =VLOOKUP(MJ$3,'KPI DC Forecast link file'!$B:$C,2,FALSE) -> 12341.991 | MK8: =VLOOKUP(MK$3,'KPI DC Forecast link file'!$B:$C,2,FALSE) -> 10700.015 | ML8: =VLOOKUP(ML$3,'KPI DC Forecast link file'!$B:$C,2,FALSE) -> 9790.0002 | MM8: =VLOOKUP(MM$3,'KPI DC Forecast link file'!$B:$C,2,FALSE) -> 19109.983 | MN8: =VLOOKUP(MN$3,'KPI DC Forecast link file'!$B:$C,2,FALSE) -> 17233.999 | MO8: =VLOOKUP(MO$3,'KPI DC Forecast link file'!$B:$C,2,FALSE) -> 20318.014 | MP8: =VLOOKUP(MP$3,'KPI DC Forecast link file'!$B:$C,2,FALSE) -> 9349.0069 | ... MV8: =VLOOKUP(MV$3,'KPI DC Forecast link file'!$B:$C,2,FALSE) -> 8686.0033 | MW8: 7642 | MX8: 7825 | MY8: =VLOOKUP(MY$3,'KPI DC Forecast link file'!$B:$C,2,FALSE) -> 7555.5556 | MZ8: =VLOOKUP(MZ$3,'KPI DC Forecast link file'!$B:$C,2,FALSE) -> 7496.063 | NA8: =VLOOKUP(NA$3,'KPI DC Forecast link file'!$B:$C,2,FALSE) -> 7437.5 | NB8: =VLOOKUP(NB$3,'KPI DC Forecast link file'!$B:$C,2,FALSE) -> #N/A | NC8: =VLOOKUP(NC$3,'KPI DC Forecast link file'!$B:$C,2,FALSE) -> #N/A | ND8: =VLOOKUP(ND$3,'KPI DC Forecast link file'!$B:$C,2,FALSE) -> #N/A
A9: OPS (8/18 and earlier) or IMF Plan Forecasted (Units) | B9: 8798 | C9: 8597 | D9: 11619 | E9: 8979 | F9: 9031 | G9: 8399 | H9: 8845 | I9: 8546 | J9: 7972 | K9: 10199 | L9: 9289 | M9: 9311 | N9: 17038 | O9: 16371 | P9: 17601 | Q9: 23466 | R9: 8843 | S9: 8534 | T9: 7530 | U9: 7919 | V9: 7599 | W9: 9018 | X9: 8361 | Y9: 16908 | Z9: 11890 | AA9: 12361 | AB9: 11004 | AC9: 11392 | AD9: 11286 | AE9: 11178 | AF9: 12738 | AG9: 16124 | AH9: 15074 | AI9: 13937 | AJ9: 14233 | AK9: 15010 | AL9: 14650 | AM9: 14502 | AN9: 14120 | AO9: 14571 | AP9: 14561 | AQ9: 14836 | AR9: 15726 | AS9: 14903 | AT9: 15448 | AU9: 15444 | AV9: 15322 | AW9: 20622 | AX9: 20440 | AY9: 19027 | AZ9: 29952 | BA9: 14672 | BB9: 13622 | BC9: 13329 | BD9: 13790 | BE9: 13595 | BF9: 14129 | BG9: 13595 | BH9: 14362 | BI9: 12888 | BJ9: 12244 | BK9: 11811 | BL9: 13582 | BM9: 12338 | BN9: 12373 | BO9: 16297 | BP9: 14442 | BQ9: 13338 | BR9: 12921 | BS9: 13129 | BT9: 13210 | BU9: 12948 | BV9: 15218 | BW9: 13151 | BX9: 13527 | BY9: 12776 | BZ9: 13055 | CA9: 12637 | CB9: 12389 | CC9: 13056 | CD9: 13315 | CE9: 43882 | CF9: 31278 | CG9: 33001 | CH9: 31895 | CI9: 22596 | CJ9: 28987 | CK9: 28149 | CL9: 23673 | CM9: 22392 | CN9: 23474 | CO9: 30179 | CP9: 23766 | CQ9: 11886 | CR9: 11937 | CS9: 11191 | CT9: 10742 | CU9: 10520 | CV9: 10840 | CW9: 10840 | CX9: 12599 | CY9: 12018 | CZ9: 12019 | DA9: 11465 | DB9: 11465 | DC9: 41999 | DD9: 32156 | DE9: 31200 | DF9: 26197 | DG9: 26250 | DH9: 38007 | DI9: 36946 | DJ9: 43498 | DK9: 62281 | DL9: 14117 | DM9: 14843 | DN9: 14790 | DO9: 13149 | DP9: 14326 | DQ9: 14326 | DR9: 12594 | DS9: 12938 | DT9: 13225 | DU9: 13132 | DV9: 11269 | DW9: 11394 | DX9: 9947 | DY9: 9766 | DZ9: 13494 | EA9: 12712 | EB9: 11930 | EC9: 11784 | ED9: 11930 | EE9: 12094 | EF9: 12088 | EG9: 13506 | EH9: 12735 | EI9: 12735 | EJ9: 12735 | EK9: 12940 | EL9: 13466 | EM9: 13466 | EN9: 13466 | EO9: 47166 | EP9: 32510 | EQ9: 28997 | ER9: 31453 | ES9: 40409 | ET9: 52690 | EU9: 42329 | EV9: 52959 | EW9: 38918 | EX9: 39471 | EY9: 50518 | EZ9: 36920 | FA9: 55185 | FB9: 25132 | FC9: 22388 | FD9: 22349 | FE9: 16920 | FF9: 15028 | FG9: 15733 | FH9: 14669 | FI9: 13987 | FJ9: 13557 | FK9: 13516 | FL9: 13178 | FM9: 15776 | FN9: 12395 | FO9: 12809 | FP9: 13989 | FQ9: 13093 | FR9: 13093 | FS9: 12884 | FT9: 13189 | FU9: 13286 | FV9: 13255 | FW9: 15088 | FX9: 14508 | FY9: 14485 | FZ9: 14099 | GA9: 14099 | GB9: 11071 | GC9: 11826 | GD9: 13538 | GE9: 13877 | GF9: 13741 | GG9: 14682 | GH9: 18486 | GI9: 22641 | GJ9: 13877 | GK9: 15925 | GL9: 15681 | GM9: 14419 | GN9: 15853 | GO9: 16365 | GP9: =VLOOKUP(GP$3,'KPI DC Forecast link file'!$B:$C,2,FALSE) -> 19035.984 | GQ9: =VLOOKUP(GQ$3,'KPI DC Forecast link file'!$B:$C,2,FALSE) -> 15960.989 | GR9: =VLOOKUP(GR$3,'KPI DC Forecast link file'!$B:$C,2,FALSE) -> 16278.006 | GS9: =VLOOKUP(GS$3,'KPI DC Forecast link file'!$B:$C,2,FALSE) -> 15657.016 | GT9: =VLOOKUP(GT$3,'KPI DC Forecast link file'!$B:$C,2,FALSE) -> 13881.005 | GU9: =VLOOKUP(GU$3,'KPI DC Forecast link file'!$B:$C,2,FALSE) -> 14379.997 | GV9: =VLOOKUP(GV$3,'KPI DC Forecast link file'!$B:$C,2,FALSE) -> 33439.983 | GW9: =VLOOKUP(GW$3,'KPI DC Forecast link file'!$B:$C,2,FALSE) -> 32900.004 | ... NA9: =VLOOKUP(NA$3,'KPI DC Forecast link file'!$B:$C,2,FALSE) -> 7437.5
A10: Actual Demand (units) | B10: 8494 | C10: 8573 | D10: 10091 | E10: 9775 | F10: 9298 | G10: 9713 | H10: 9030 | I10: 9370 | J10: 8183 | K10: 8365 | L10: 7194 | M10: 8582 | N10: 17990 | O10: 18648 | P10: 20264 | Q10: 29105 | R10: 17657 | S10: 7256 | T10: 8973 | U10: 8141 | V10: 10326 | W10: 11330 | X10: 11604 | Y10: 9962 | Z10: 10047 | AA10: 11302 | AB10: 8418 | AC10: 10194 | AD10: 11535 | AE10: 11526 | AF10: 10939 | AG10: 10055 | AH10: 9849 | AI10: 9328 | AJ10: 13617 | AK10: 13459 | AL10: 10979 | AM10: 12475 | AN10: 11941 | AO10: 12809 | AP10: 12067 | AQ10: 13420 | AR10: 18191 | AS10: 12610 | AT10: 10980 | AU10: 10607 | AV10: 12365 | AW10: 21681 | AX10: 20752 | AY10: 26051 | AZ10: 25634 | BA10: 7867 | BB10: 8859 | BC10: 7746 | BD10: 7642 | BE10: 12792 | BF10: 15315 | BG10: 10672 | BH10: 11332 | BI10: 13349 | BJ10: 21127 | BK10: 18976 | BL10: 21110 | BM10: 20641 | BN10: 12063 | BO10: 7841 | BP10: 10031 | BQ10: 8633 | BR10: 7588 | BS10: 8798 | BT10: 12123 | BU10: 10742 | BV10: 10675 | BW10: 12194 | BX10: 9196 | BY10: 8942 | BZ10: 9361 | CA10: 19270 | CB10: 14772 | CC10: 8401 | CD10: 8949 | CE10: 31398 | CF10: 28199 | CG10: 29678 | CH10: 40787 | CI10: 25665 | CJ10: 46808 | CK10: 37142 | CL10: 33030 | CM10: 42957 | CN10: 22056 | CO10: 34734 | CP10: 28033 | CQ10: 12388 | CR10: 11102 | CS10: 12077 | CT10: 9761 | CU10: 12763 | CV10: 15309 | CW10: 17309 | CX10: 10364 | CY10: 11323 | CZ10: 9707 | DA10: 9169 | DB10: 12029 | DC10: 34163 | DD10: 28736 | DE10: 36979 | DF10: 34238 | DG10: 33687 | DH10: 26203 | DI10: 28727 | DJ10: 42763 | DK10: 79862 | DL10: 12605 | DM10: 10847 | DN10: 9602 | DO10: 8953 | DP10: 10388 | DQ10: 13237 | DR10: 15207 | DS10: 12690 | DT10: 11286 | DU10: 12782 | DV10: 10158 | DW10: 14160 | DX10: 19064 | DY10: 11258 | DZ10: 10992 | EA10: 10754 | EB10: 10121 | EC10: 9901 | ED10: 12372 | EE10: 15215 | EF10: 13480 | EG10: 13361 | EH10: 14181 | EI10: 12458 | EJ10: 11174 | EK10: 12484 | EL10: 13850 | EM10: 13169 | EN10: 12370 | EO10: 41828 | EP10: 28368 | EQ10: 27201 | ER10: 27297 | ES10: 33684 | ET10: 55698 | EU10: 40042 | EV10: 35424 | EW10: 31839 | EX10: 33068 | EY10: 40920 | EZ10: 47862 | FA10: 62669 | FB10: 72163 | FC10: 30482 | FD10: 34349 | FE10: 9475 | FF10: 9182 | FG10: 8838 | FH10: 8233 | FI10: 11312 | FJ10: 11753 | FK10: 6425 | FL10: 8662 | FM10: 12460 | FN10: 14681 | FO10: 8930 | FP10: 11373 | FQ10: 12759 | FR10: 8781 | FS10: 11360 | FT10: 10645 | FU10: 13618 | FV10: 16523 | FW10: 12803 | FX10: 10008 | FY10: =FY8 -> 11166 | FZ10: 11880 | GA10: 13196 | GB10: 15234 | GC10: =GC8 -> 15058.009 | GD10: 14763 | GE10: 15153 | GF10: 15149 | GG10: 14580 | GH10: 24274 | GI10: 37671 | GJ10: 16217 | GK10: 13081 | GL10: 12537 | GM10: 13657 | GN10: 12480 | GO10: 14449 | GP10: 19036 | GQ10: 15961 | GR10: 16278 | GS10: 15657 | GT10: 13883 | GU10: 14381 | GV10: 33440 | GW10: 32900 | GX10: 31800 | GY10: 31098 | GZ10: 36408 | HA10: 34167 | HB10: 31910 | HC10: 48348 | HD10: 49880 | HE10: 88989 | HF10: 30906 | HG10: 12985 | HH10: 12489 | HI10: 10903 | HJ10: 16131 | HK10: 16898 | HL10: 13913 | HM10: 14608 | HN10: 11551 | HO10: 11257 | HP10: 13793 | HQ10: 14949 | HR10: 17810 | HS10: 17082 | HT10: 12233 | HU10: 23906 | HV10: 24899 | HW10: 26444 | HX10: 25527 | HY10: 39536 | HZ10: 17548 | IA10: 14752 | IB10: 14319 | IC10: 12520 | ID10: 12658 | IE10: 23549 | IF10: 32029 | IG10: 13621 | IH10: 15089 | II10: 15970 | IJ10: 15315 | IK10: 16510 | IL10: 16232 | IM10: 26482 | IN10: 17228 | IO10: 15341 | IP10: 58740 | IQ10: 45470 | IR10: 50731 | IS10: 58928 | IT10: 60772 | IU10: 52076 | IV10: 48328 | IW10: 82443 | IX10: 65552 | IY10: 54332 | IZ10: 80583 | JA10: 64011 | JB10: 48745 | JC10: 17993 | JD10: 17845 | JE10: 18140 | JF10: 17682 | JG10: 26884 | JH10: 30915 | JI10: 22065 | JJ10: 18033 | JK10: 17084 | JL10: 14088 | JM10: 37590 | JN10: 48318 | JO10: 75270 | JP10: 29025 | JQ10: 23602 | JR10: 20178 | JS10: 24113 | JT10: 30611 | JU10: 34920 | JV10: 47947 | JW10: 31725 | JX10: 30534 | JY10: 25357 | JZ10: 31118 | KA10: 28467 | KB10: 48780 | KC10: 54885 | KD10: 43998 | KE10: 79395 | KF10: 61411 | KG10: 57489 | KH10: 55881 | KI10: 75161 | KJ10: 85837 | KK10: 77747 | KL10: 64245 | KM10: 62673 | KN10: 68854 | KO10: 151031 | KP10: 103773 | KQ10: 97654 | KR10: 149130 | KS10: 85455 | KT10: 36685 | KU10: 38178 | KV10: 33849 | KW10: 41598 | KX10: 48994 | KY10: 37905 | KZ10: 36940 | LA10: 37180 | LB10: 63418 | LC10: 48839 | LD10: 46307 | LE10: 50943 | LF10: 32753 | LG10: 26668 | LH10: 22203 | LI10: 16573 | LJ10: 15215 | LK10: 12369 | LL10: 11388 | LM10: 6355 | LN10: 5821 | LO10: 11136 | LP10: 53927 | LQ10: 36679 | LR10: 50427 | LS10: 45572 | LT10: 60034 | LU10: 38326 | LV10: 44917 | LW10: 42328 | LX10: 37588 | LY10: 34631 | LZ10: 30547 | MA10: 42912 | MB10: 31530 | MC10: 29791 | MD10: 13288 | ME10: 12104 | MF10: 12828 | MG10: 12389 | MH10: =MH8 -> 11917 | MI10: 11498 | MJ10: 12342 | MK10: 10700 | ML10: 9790 | MM10: 19110 | MN10: 17234 | MO10: 20318 | MP10: 9349 | MQ10: 8783 | MR10: 10122 | MS10: 8621 | MT10: 8444 | MU10: 9660 | MV10: 8686 | MW10: =MW8 -> 7642 | MX10: =MX8 -> 7825 | MY10: =MY8 -> 7555.5556 | MZ10: =MZ8 -> 7496.063 | NA10: =NA8 -> 7437.5 | NB10: =NB8 -> #N/A | NC10: =NC8 -> #N/A | ND10: =ND8 -> #N/A
A11: Percentage demand vs. forecast | B11: =IFERROR(B10/B9,0) -> 0.96544669 | C11: =IFERROR(C10/C9,0) -> 0.99720833 | D11: =IFERROR(D10/D9,0) -> 0.86849126 | E11: =IFERROR(E10/E9,0) -> 1.0886513 | F11: =IFERROR(F10/F9,0) -> 1.0295648 | G11: =IFERROR(G10/G9,0) -> 1.1564472 | H11: =IFERROR(H10/H9,0) -> 1.0209158 | I11: =IFERROR(I10/I9,0) -> 1.0964194 | ... IT11: =IFERROR(IT10/IT9,0) -> 1.0000002 | IU11: =IFERROR(IU10/IU8,0) -> 0.8856312 | IV11: =IFERROR(IV10/IV8,0) -> 0.78441811 | IW11: =IFERROR(IW10/IW8,0) -> 1.7807033 | IX11: =IFERROR(IX10/IX8,0) -> 0.94582077 | IY11: =IFERROR(IY10/IY8,0) -> 0.8315274 | IZ11: =IFERROR(IZ10/IZ8,0) -> 0.74656056 | JA11: =IFERROR(JA10/JA8,0) -> 0.90016875 | JB11: =IFERROR(JB10/JB8,0) -> 0.78090707 | ... ND11: =IFERROR(ND10/ND8,0) -> 0
A12: Shipped Shipments (Power BI) | B12: 2056 | C12: 2847 | D12: 2324 | E12: 2608 | F12: 2657 | G12: 1517 | H12: 2117 | I12: 3156 | J12: 2315 | K12: 2321 | L12: 1840 | M12: 2054 | N12: 1954 | O12: 3840 | P12: 4603 | Q12: 6295 | R12: 5476 | S12: 4498 | T12: 2401 | U12: 1478 | V12: 2456 | W12: 3601 | X12: 2769 | Y12: 3155 | Z12: 2486 | AA12: 2439 | AB12: 2176 | AC12: 1834 | AD12: 3839 | AE12: 3040 | AF12: 3317 | AG12: 2799 | AH12: 2846 | AI12: 1273 | AJ12: 2755 | AK12: 4812 | AL12: 2937 | AM12: 3365 | AN12: 3314 | AO12: 3189 | AP12: 1568 | AQ12: 3496 | AR12: 5037 | AS12: 4206 | AT12: 3254 | AU12: 2681 | AV12: 2680 | AW12: 2148 | AX12: 2903 | AY12: 5256 | AZ12: 7939 | BA12: 4949 | BB12: 4970 | BC12: 2192 | BD12: 1372 | BE12: 2222 | BF12: 0 | BG12: 6106 | BH12: 3149 | BI12: 4572 | BJ12: 3517 | BK12: 2247 | BL12: 2529 | BM12: 4340 | BN12: 5317 | BO12: 4493 | BP12: 2320 | BQ12: 3754 | BR12: 1335 | BS12: 1721 | BT12: 3530 | BU12: 2422 | BV12: 2786 | BW12: 2940 | BX12: 2336 | BY12: 1374 | BZ12: 2191 | CA12: 4668 | CB12: 3711 | CC12: 2972 | CD12: 2050 | CE12: 3731 | CF12: 7501 | CG12: 3695 | CH12: 5886 | CI12: 8360 | CJ12: 5734 | CK12: 5652 | CL12: 7983 | CM12: 7492 | CN12: 5503 | CO12: 5007 | CP12: 5911 | CQ12: 4402 | CR12: 3548 | CS12: 3625 | CT12: 2000 | CU12: 4306 | CV12: 0 | CW12: 6418 | CX12: 4479 | CY12: 3629 | CZ12: 2792 | DA12: 1367 | DB12: 2273 | DC12: 5370 | DD12: 6439 | DE12: 5269 | DF12: 5207 | DG12: 4803 | DH12: 2885 | DI12: 3997 | DJ12: 6734 | DK12: 8341 | DL12: 8566 | DM12: 7739 | DN12: 4257 | DO12: 4134 | DP12: 3759 | DQ12: 5293 | DR12: 3505 | DS12: 3386 | DT12: 3448 | DU12: 3484 | DV12: 1513 | DW12: 2237 | DX12: 4253 | DY12: 5569 | DZ12: 2747 | EA12: 2766 | EB12: 2686 | EC12: 1154 | ED12: 2555 | EE12: 0 | EF12: 5896 | EG12: 3979 | EH12: 3488 | EI12: 3193 | EJ12: 2076 | EK12: 3005 | EL12: 3822 | EM12: 4523 | EN12: 3214 | EO12: 4961 | EP12: 6775 | EQ12: 4157 | ER12: 3783 | ES12: 6729 | ET12: 7862 | EU12: 7209 | EV12: 4968 | EW12: 5643 | EX12: 4113 | EY12: 2218 | EZ12: 6769 | FA12: 5667 | FB12: 7301 | FC12: 5938 | FD12: 7429 | FE12: 8172 | FF12: 4226 | FG12: 6284 | FH12: 8248 | FI12: 4890 | FJ12: 4245 | FK12: 3508 | FL12: 790 | FM12: 2088 | FN12: 4566 | FO12: 3086 | FP12: 2486 | FQ12: 3023 | FR12: 2518 | FS12: 1567 | FT12: 1689 | FU12: 5435 | FV12: 3729 | FW12: 2852 | FX12: 3060 | FY12: 2451 | FZ12: =FZ8/4.3 -> 2762.7892 | GA12: =GA8/4.3 -> 3068.8341 | GB12: 4187 | GC12: 3584 | GD12: 3019 | GE12: 3014 | GF12: 2959 | GG12: 2185 | GH12: 3879 | GI12: 5962 | GJ12: 6252 | GK12: 3418 | GL12: 3673 | GM12: 3805 | GN12: 2587 | GO12: 2850 | GP12: 5498 | GQ12: 4171 | GR12: 3067 | GS12: 3523 | GT12: 3456 | GU12: 2945 | GV12: 3059 | GW12: 5742 | GX12: 7358 | GY12: 5210 | GZ12: 5698 | HA12: 5066 | HB12: 2959 | HC12: 5320 | HD12: 9818 | HE12: 10909 | HF12: 1052 | HG12: 6806 | HH12: =HH8/4.3 -> 2904.4187 | HI12: =HI8/4.3 -> 2535.3495 | HJ12: =HJ8/4.3 -> 3751.1664 | HK12: =HK8/4.3 -> 3929.7684 | HL12: 6876 | HM12: 3236 | HN12: 3362 | HO12: 4158 | HP12: 3107 | HQ12: 4023 | HR12: 5530 | HS12: 4279 | HT12: 4119 | HU12: 3673 | HV12: 4426 | HW12: 2759 | HX12: 4479 | HY12: 7726 | HZ12: 6840 | IA12: 6031 | IB12: 6061 | IC12: 3881 | ID12: 2360 | IE12: 3343 | IF12: 6859 | IG12: 5604 | IH12: 5650 | II12: 4480 | IJ12: 4106 | IK12: 3108 | IL12: 4229 | IM12: 6814 | IN12: 5805 | IO12: 4263 | IP12: 8522 | IQ12: 12256 | IR12: 6854 | IS12: 7148 | IT12: 14687 | IU12: 16734 | IV12: 9938 | IW12: 10284 | IX12: 13036 | IY12: 15221 | IZ12: 8254 | JA12: 12607 | JB12: 16716 | JC12: 9786 | JD12: 10013 | JE12: 7428 | JF12: 4350 | JG12: 4826 | JH12: 8404 | JI12: 7037 | JJ12: 5505 | JK12: 4549 | JL12: 3448 | JM12: 2975 | JN12: 7523 | JO12: 11052 | JP12: 16240 | JQ12: 10550 | JR12: 7178 | JS12: 5327 | JT12: 4318 | JU12: 5078 | JV12: 9710 | JW12: 12741 | JX12: 9984 | JY12: 7785 | JZ12: 6969 | KA12: 4768 | KB12: 6679 | KC12: 12203 | KD12: 15284 | KE12: 13344 | KF12: 14549 | KG12: 15305 | KH12: 8800 | KI12: 7008 | KJ12: 21014 | KK12: 21154 | KL12: 21078 | KM12: 16782 | KN12: 5 | KO12: 21964 | KP12: 24239 | KQ12: 22621 | KR12: 21795 | KS12: 20632 | KT12: 19909 | KU12: 18143 | KV12: 18362 | KW12: 9616 | KX12: 18330 | KY12: 19041 | KZ12: 17381 | LA12: 11375 | LB12: 11240 | LC12: 5447 | LD12: 6168 | LE12: 16631 | LF12: 16699 | LG12: 14216 | LH12: 9282 | LI12: 4745 | LJ12: 4297 | LK12: 4107 | LL12: 3874 | LM12: 2105 | LN12: =LN8/4.3 -> 1353.7207 | LO12: =LO8/4.3 -> 2589.7684 | LP12: 10598 | LQ12: 11229 | LR12: 5376 | LS12: 9445 | LT12: 10554 | LU12: 11 | LV12: 0 | LW12: 13574 | LX12: 12135 | LY12: 7481 | LZ12: 1917 | MA12: 0 | MB12: 8787 | MC12: 13609 | MD12: 11119 | ME12: 5098 | MF12: 5126 | MG12: 5390 | MH12: 3506 | MI12: 3225 | MJ12: 2699 | MK12: 3190 | ML12: 2022 | MM12: 2262 | MN12: 5394 | MO12: 4329 | MP12: 3440 | MQ12: 3658 | MR12: 2068 | MS12: 2003 | MT12: 2189 | MU12: 3311 | MV12: 2913 | MW12: 2342 | MX12: 2467 | MY12: 2193 | MZ12: 1280 | NA12: 2856 | NB12: 7700 | NC12: =NC8/4.3 -> #N/A | ND12: =ND8/4.3 -> #N/A
A13: UPT | B13: =IFERROR(B7/B12,0) -> 3.4182879 | C13: =IFERROR(C7/C12,0) -> 3.8742536 | D13: =IFERROR(D7/D12,0) -> 3.5718589 | E13: =IFERROR(E7/E12,0) -> 3.8366564 | F13: =IFERROR(F7/F12,0) -> 3.7651487 | G13: =IFERROR(G7/G12,0) -> 4.1470007 | H13: =IFERROR(H7/H12,0) -> 3.8115257 | I13: =IFERROR(I7/I12,0) -> 3.8792776 | ... ND13: =IFERROR(ND7/ND12,0) -> 0
A14: AB Utilization | B14: 0.8079 | C14: 0.7824 | D14: 0.8465 | E14: 0.7461 | F14: 0.7501 | G14: 0.7706 | H14: 0.849 | I14: 0.8385 | J14: 0.7757 | K14: 0.8078 | L14: 0.807 | M14: 0.8083 | N14: 0.7785 | O14: 0.7962 | P14: 0.7201 | Q14: 0.8076 | R14: 0.7248 | S14: 0.7986 | T14: 0.686 | U14: 0.8086 | V14: 0.8309 | W14: 0.6478 | X14: 0.8123 | Y14: 0.8326 | Z14: 0.8303 | AA14: 0.7929 | AB14: 0.8332 | AC14: 0.8365 | AD14: 0.7967 | AE14: 0.6325 | AF14: 0.3898 | AG14: 0.8393 | AH14: 0.815 | AI14: 0.7541 | AJ14: 0.8366 | AK14: 0.8317 | AL14: 0.8358 | AM14: 0.848 | AN14: 0.822 | AO14: 0.8202 | AP14: 0.7857 | AQ14: 0.818 | AR14: 0.825 | AS14: 0.7815 | AT14: 0.773 | AU14: 0.8027 | AV14: 0.6933 | AW14: 0.8376 | AX14: 0.5646 | AY14: 0.7001 | AZ14: 0.7718 | BA14: 0.7232 | BB14: 0.8771 | BC14: 0.8438 | BD14: 0.8166 | BE14: 0.8104 | BG14: 0.7683 | BH14: 0.8693 | BI14: 0.8639 | BJ14: 0.8166 | BK14: 0.6464 | BL14: 0.6609 | BM14: 0.7193 | BN14: 0.6951 | BO14: 0.8141 | BP14: 0.8615 | BQ14: 0.8522 | BR14: 0.7738 | BS14: 0.8117 | BT14: 0.8102 | BU14: 0.7924 | BV14: 0.8241 | BW14: 0.8191 | BX14: 0.7514 | BY14: 0.8799 | BZ14: 0.7072 | CA14: 0.7967 | CB14: 0.7848 | CC14: 0.7989 | CD14: 0.8429 | CE14: 0.6918 | CF14: 0.8489 | CG14: 0.8051 | CH14: 0.7535 | CI14: 0.879 | CJ14: 0.8006 | CK14: 0.8325 | CL14: 0.7548 | CM14: 0.8034 | CN14: 0.6959 | CO14: 0.7196 | CP14: 0.6975 | CQ14: 0.742 | CR14: 0.769 | CS14: 0.7973 | CT14: 0.3499 | CU14: 0.7591 | CV14: 0 | CW14: 0.7829 | CX14: 0.8566 | CY14: 0.8916 | CZ14: 0.8585 | DA14: 0.8471 | DB14: 0.8181 | DC14: 0.8111 | DD14: 0.8157 | DE14: 0.8421 | DF14: 0.7774 | DG14: 0.7951 | DH14: 0.8116 | DI14: 0.7871 | DJ14: 0.7573 | DK14: 0.79 | DL14: 0.7545 | DM14: 0.7516 | DN14: 0.8606 | DO14: 0.9772 | DP14: 0.8815 | DQ14: 0.8806 | DR14: 0.8555 | DS14: 0.8603 | DT14: 0.8883 | DU14: 0.8582 | DV14: 0.8674 | DW14: 0.8506 | DX14: 0.8339 | DY14: 0.9063 | DZ14: 0.837 | EA14: 0.8591 | EB14: 0.8375 | EC14: 0.7916 | ED14: 0.8769 | EE14: 0 | EF14: 0.7807 | EG14: 0.9322 | EH14: 0.8625 | EI14: 0.8566 | EJ14: 0.8909 | EK14: 0.8093 | EL14: 0.8709 | EM14: 0.8996 | EN14: 0.889 | EO14: 0.7464 | EP14: 0.7214 | EQ14: 0.6178 | ER14: 0.7283 | ES14: 0.6541 | ET14: 0.7697 | EU14: 0.6894 | EV14: 0.563 | EW14: 0.4055 | EX14: 0.6412 | EY14: 0.6335 | EZ14: 0.6259 | FA14: 0.7125 | FB14: 0.5501 | FC14: 0.5186 | FD14: 0.6374 | FE14: 0.58 | FF14: 0.6251 | FG14: 0.5807 | FH14: 0.7191 | FI14: 0.7659 | FJ14: 0.7326 | FK14: 0.8627 | FL14: 0.8315 | FM14: 0.8473 | FN14: 0.9015 | FO14: 0.8987 | FP14: 0.7198 | FQ14: 0.8846 | FR14: 0.8567 | FS14: 0.9139 | FT14: 0.7546 | FU14: 0.9129 | FV14: 0.8739 | FW14: 0.8615 | FX14: 0.8795 | FY14: 0.8506 | FZ14: 0.8469 | GA14: 0.8618 | GB14: 0.8385 | GC14: 0.8371 | GD14: 0.8494 | GE14: 0.8098 | GF14: 0.8782 | GG14: 0.746 | GH14: 0.8286 | GI14: 0.7887 | GJ14: 0.7681 | GK14: 0.8424 | GL14: 0.8983 | GM14: 0.8427 | GN14: 0.8817 | GO14: 0.8357 | GP14: 0.8173 | GQ14: 0.8406 | GR14: 0.7338 | GS14: 0.8042 | GT14: 0.835 | GU14: 0.8665 | GV14: 0.7042 | GW14: 0.7223 | GX14: 0.7857 | GY14: 0.7701 | GZ14: 0.7958 | HA14: 0.772 | HB14: 0.6586 | HC14: 0.676 | HD14: 0.7728 | HE14: 0.7071 | HF14: 0.6476 | HG14: 0.6419 | HH14: 0.6079 | HI14: 0.6974 | HJ14: 0.738 | HK14: 0.7423 | HL14: 0.839 | HM14: 0.8006 | HN14: 0.7412 | HO14: 0.8092 | HP14: 0.7863 | HQ14: 0.8129 | HR14: 0.7849 | HS14: 0.8237 | HT14: 0.818 | HU14: 0.813 | HV14: 0.7447 | HW14: 0.7618 | HX14: 0.7261 | HY14: 0.7637 | HZ14: 0.6923 | IA14: 0.7629 | IB14: 0.8314 | IC14: 0.7806 | ID14: 0.7663 | IE14: 0.7653 | IF14: 0.749 | IG14: 0.7367 | IH14: 0.7831 | II14: 0.8073 | IJ14: 0.7817 | IK14: 0.7774 | IL14: 0.8026 | IM14: 0.7893 | IN14: 0.7722 | IO14: 0.7761 | IP14: 0.6899 | IQ14: 0.7281 | IR14: 0.6086 | IS14: 0.5872 | IT14: 0.6394 | IU14: 0.6858 | IV14: 0.6317 | IW14: 0.6452 | IX14: 0.6497 | IY14: 0.5565 | IZ14: 0.7217 | JA14: 0.6214 | JB14: 0.6128 | JC14: 0.7052 | JD14: 0.61 | JE14: 0.706 | JF14: 0.7626 | JG14: 0.7393 | JH14: 0.7205 | JI14: 0.7581 | JJ14: 0.7399 | JK14: 0.7367 | JL14: 0.6893 | JM14: 0.7223 | JN14: 0.6907 | JO14: 0.7055 | JP14: 0.6977 | JQ14: 0.7033 | JR14: 0.7719 | JS14: 0.7764 | JT14: 0.7809 | JU14: 0.7818 | JV14: 0.6473 | JW14: 0.7345 | JX14: 0.7676 | JY14: 0.7716 | JZ14: 0.7857 | KA14: 0.7838 | KB14: 0.75 | KC14: 0.6997 | KD14: 0.7047 | KE14: 0.706 | KF14: 0.7202 | KG14: 0.7017 | KH14: 0.6853 | KI14: 0.7734 | KJ14: 0.5823 | KK14: 0.6374 | KL14: 0.6753 | KM14: 0.6497 | KN14: 0.5217 | KO14: 0.5587 | KP14: 0.4979 | KQ14: 0.6391 | KR14: 0.618 | KS14: 0.6321 | KT14: 0.6356 | KU14: 0.6836 | KV14: 0.6592 | KW14: 0.743 | KX14: 0.6607 | KY14: 0.7576 | KZ14: 0.7654 | LA14: 0.6746 | LB14: 0.7071 | LC14: 0.7616 | LD14: 0.7952 | LE14: 0.7503 | LF14: 0.8186 | LG14: 0.3935 | LH14: 0.0098 | LI14: 0.0018 | LJ14: 0.5845 | LK14: 0.7971 | LL14: 0.792 | LM14: 0.7293 | LN14: 0 | LO14: 0 | LP14: 0.6827 | LQ14: 0.6947 | LR14: 0.7143 | LS14: 0.6587 | LT14: 0.5975 | LU14: 0.86 | LV14: 0 | LW14: 0.636 | LX14: 0.7069 | LY14: 0.6348 | LZ14: 0.7381 | MA14: 0 | MB14: 0.6979 | MC14: 0.6903 | MD14: 0.747 | ME14: 0.7819 | MF14: 0.8421 | MG14: 0.8224 | MH14: 0.8284 | MI14: 0.819 | MJ14: 0.805 | MK14: 0.8173 | ML14: 0.8308 | MM14: 0.8096 | MN14: 0.7731 | MO14: 0.8012 | MP14: 0.805 | MQ14: 0.8454 | MR14: 0.817 | MS14: 0.7652 | MT14: 0.8387 | MU14: 0.8598 | MV14: 0.7741
A15: Out of 48 | D15: =MAX(0,D5-C10-B10) -> 0 | E15: =MAX(0,E5-D10-C10) -> 0 | F15: 0 | G15: 0 | H15: =MAX(0,H5-G10-F10) -> 0 | I15: =MAX(0,I5-H10-G10) -> 0 | J15: =MAX(0,J5-I10-H10) -> 0 | K15: =MAX(0,K5-J10-I10) -> 0 | L15: =MAX(0,L5-K10-J10) -> 0 | M15: =MAX(0,M5-L10-K10) -> 0 | N15: =MAX(0,N5-M10-L10) -> 0 | O15: =MAX(0,O5-N10-M10) -> 0 | ... MU15: =MAX(0,MU5-MT10-MS10) -> 0 | MV15: 0 | MW15: =MAX(0,MW5-MV10-MU10) -> 0 | MX15: =MAX(0,MX5-MW10-MV10) -> 0 | MY15: =MAX(0,MY5-MX10-MW10) -> 0 | MZ15: =MAX(0,MZ5-MY10-MX10) -> 0 | NA15: =MAX(0,NA5-MZ10-MY10) -> 0 | NB15: =MAX(0,NB5-NA10-MZ10) -> 0 | NC15: =MAX(0,NC5-NB10-NA10) -> #N/A | ND15: =MAX(0,ND5-NC10-NB10) -> #N/A
A16: Out of 72 | E16: =MAX(0,E5-D10-C10-B10) -> 0 | F16: 0 | G16: 0 | H16: =MAX(0,H5-G10-F10-E10) -> 0 | I16: =MAX(0,I5-H10-G10-F10) -> 0 | J16: =MAX(0,J5-I10-H10-G10) -> 0 | K16: =MAX(0,K5-J10-I10-H10) -> 0 | L16: =MAX(0,L5-K10-J10-I10) -> 0 | M16: =MAX(0,M5-L10-K10-J10) -> 0 | N16: =MAX(0,N5-M10-L10-K10) -> 0 | O16: =MAX(0,O5-N10-M10-L10) -> 0 | ... MU16: =MAX(0,MU5-MT10-MS10-MR10) -> 0 | MV16: 0 | MW16: =MAX(0,MW5-MV10-MU10-MT10) -> 0 | MX16: =MAX(0,MX5-MW10-MV10-MU10) -> 0 | MY16: =MAX(0,MY5-MX10-MW10-MV10) -> 0 | MZ16: =MAX(0,MZ5-MY10-MX10-MW10) -> 0 | NA16: =MAX(0,NA5-MZ10-MY10-MX10) -> 0 | NB16: =MAX(0,NB5-NA10-MZ10-MY10) -> 0 | NC16: =MAX(0,NC5-NB10-NA10-MZ10) -> #N/A | ND16: =MAX(0,ND5-NC10-NB10-NA10) -> #N/A
A17: Out of 96 | F17: 0 | G17: 0 | H17: =MAX(0,H5-G10-F10-E10-D10) -> 0 | I17: =MAX(0,I5-H10-G10-F10-E10) -> 0 | J17: =MAX(0,J5-I10-H10-G10-F10) -> 0 | K17: =MAX(0,K5-J10-I10-H10-G10) -> 0 | L17: =MAX(0,L5-K10-J10-I10-H10) -> 0 | M17: =MAX(0,M5-L10-K10-J10-I10) -> 0 | N17: =MAX(0,N5-M10-L10-K10-J10) -> 0 | O17: =MAX(0,O5-N10-M10-L10-K10) -> 0 | ... MU17: =MAX(0,MU5-MT10-MS10-MR10-MQ10) -> 0 | MV17: 0 | MW17: =MAX(0,MW5-MV10-MU10-MT10-MS10) -> 0 | MX17: =MAX(0,MX5-MW10-MV10-MU10-MT10) -> 0 | MY17: =MAX(0,MY5-MX10-MW10-MV10-MU10) -> 0 | MZ17: =MAX(0,MZ5-MY10-MX10-MW10-MV10) -> 0 | NA17: =MAX(0,NA5-MZ10-MY10-MX10-MW10) -> 0 | NB17: =MAX(0,NB5-NA10-MZ10-MY10-MX10) -> 0 | NC17: =MAX(0,NC5-NB10-NA10-MZ10-MY10) -> #N/A | ND17: =MAX(0,ND5-NC10-NB10-NA10-MZ10) -> #N/A
A18: Out of 120 | G18: =MAX(0,G5-F10-E10-D10-C10-B10) -> 0 | H18: =MAX(0,H5-G10-F10-E10-D10-C10) -> 0 | I18: =MAX(0,I5-H10-G10-F10-E10-D10) -> 0 | J18: =MAX(0,J5-I10-H10-G10-F10-E10) -> 0 | K18: =MAX(0,K5-J10-I10-H10-G10-F10) -> 0 | L18: =MAX(0,L5-K10-J10-I10-H10-G10) -> 0 | M18: =MAX(0,M5-L10-K10-J10-I10-H10) -> 0 | N18: =MAX(0,N5-M10-L10-K10-J10-I10) -> 0 | ... GS18: =MAX(0,GS5-GR10-GQ10-GP10-GO10-GN10) -> 0 | GU18: =MAX(0,GU5-GT10-GS10-GR10-GQ10-GP10) -> 0 | GV18: =MAX(0,GV5-GU10-GT10-GS10-GR10-GQ10) -> 0 | GW18: =MAX(0,GW5-GV10-GU10-GT10-GS10-GR10) -> 0 | GX18: =MAX(0,GX5-GW10-GV10-GU10-GT10-GS10) -> 0 | GY18: =MAX(0,GY5-GX10-GW10-GV10-GU10-GT10) -> 0 | GZ18: =MAX(0,GZ5-GY10-GX10-GW10-GV10-GU10) -> 0 | HA18: =MAX(0,HA5-GZ10-GY10-GX10-GW10-GV10) -> 0 | HB18: =MAX(0,HB5-HA10-GZ10-GY10-GX10-GW10) -> 0 | ... MU18: =MAX(0,MU5-MT10-MS10-MR10-MQ10-MP10) -> 0 | MV18: 0 | MW18: =MAX(0,MW5-MV10-MU10-MT10-MS10-MR10) -> 0 | MX18: =MAX(0,MX5-MW10-MV10-MU10-MT10-MS10) -> 0 | MY18: =MAX(0,MY5-MX10-MW10-MV10-MU10-MT10) -> 0 | MZ18: =MAX(0,MZ5-MY10-MX10-MW10-MV10-MU10) -> 0 | NA18: =MAX(0,NA5-MZ10-MY10-MX10-MW10-MV10) -> 0 | NB18: =MAX(0,NB5-NA10-MZ10-MY10-MX10-MW10) -> 0 | NC18: =MAX(0,NC5-NB10-NA10-MZ10-MY10-MX10) -> #N/A | ND18: =MAX(0,ND5-NC10-NB10-NA10-MZ10-MY10) -> #N/A
A19: Out of 144 | H19: =MAX(0,H5-G10-F10-E10-D10-C10-B10) -> 0 | I19: =MAX(0,I5-H10-G10-F10-E10-D10-C10) -> 0 | J19: =MAX(0,J5-I10-H10-G10-F10-E10-D10) -> 0 | K19: =MAX(0,K5-J10-I10-H10-G10-F10-E10) -> 0 | L19: =MAX(0,L5-K10-J10-I10-H10-G10-F10) -> 0 | M19: =MAX(0,M5-L10-K10-J10-I10-H10-G10) -> 0 | N19: =MAX(0,N5-M10-L10-K10-J10-I10-H10) -> 0 | O19: =MAX(0,O5-N10-M10-L10-K10-J10-I10) -> 0 | ... ND19: =MAX(0,ND5-NC10-NB10-NA10-MZ10-MY10-MX10) -> #N/A
A21: Labor Planning | LW21: Updated
A22: FTE Needed | B22: ='[1]Deployment needs'!$J$3 -> 35.356687 | C22: ='Deployment needs'!D3 -> 25.128314 | D22: ='Deployment needs'!E3 -> 23.4337 | E22: ='Deployment needs'!F3 -> 23.366014 | F22: ='Deployment needs'!G3 -> 26.258885 | G22: ='Deployment needs'!H3 -> 19.115286 | H22: ='Deployment needs'!I3 -> 18.289149 | I22: ='Deployment needs'!J3 -> 25.980977 | J22: ='Deployment needs'!K3 -> 26.805131 | ... MZ22: ='Deployment needs'!NA3 -> 24.478703 | NA22: ='Deployment needs'!NC3 -> 31.548721
