Workbook
Name _1st_shift_percentage: Data!$B$60
Name _2nd_shift_percentage: Data!$B$59
Name Amazon_Replen: Data!$B$58
Name Autobagger_Bander: Data!$B$28
Name Autobagger_Operator: Data!$B$27
Name Average_units_per_bin: Data!$B$52
Name Cartbuilding: Data!$B$18
Name Cartons_per_hour_Cubiscan: Data!$B$38
Name Cubiscan: Data!$B$36
Name DD: #REF!
Name DTC: Data!$B$9
Name DTC_to_replen: Data!$B$35
Name Exceptions: Data!$B$42
Name Gift_cards: Data!$B$21
Name Gift_cards_per_hour: Data!$B$26
Name Hours_1st: Data!$B$3
Name Hours_2nd: Data!$B$4
Name Inventory: Data!$B$50
Name Narvar: Data!$B$41
Name Open_orders: Data!$B$54
Name Overstock: Data!$B$33
Name Overstock_cycle_count: Data!$B$53
Name Pecentage_of_goal_2nd: Data!$B$6
Name Percentage_1st_Goal: Data!$B$43
Name Percentage_2nd_Goal: Data!$B$44
Name Percentage_Exceptions: Data!$B$47
Name Percentage_Narvar: Data!$B$45
Name Percentage_Non_Narvar: Data!$B$46
Name Percentage_of_goal_1st: Data!$B$5
Name Percentage_regular: Data!$B$14
Name Percentage_singles: Data!$B$15
Name Picking_cycle_count: Data!$B$51
Name Pieces_per_package: Data!$B$48
Name Planning: Data!$B$2
Name Receiving: Data!$B$34
Name Receiving_DD: #REF!
Name Region_1: Data!$B$10
Name Region_2: Data!$B$11
Name Region_7: Data!$B$12
Name Repack: Data!$B$22
Name Repack_goal: Data!$B$23
Name Replenishment_pull: Data!$B$31
Name Replenishment_throw: Data!$B$32
Name Resets: Data!$B$24
Name Resets_per_hour: Data!$B$25
Name Returns: Data!$B$39
Name Returns_put_away: Data!$B$40
Name Ship_bulk: Data!$B$16
Name Ship_singles: Data!$B$17
Name Stocking: Data!$B$30
Name Taper: Data!$B$19
Name Truck_loader: Data!$B$20
Name Units_per_carton: Data!$B$37
Name UPT: Data!$B$13
Name Wholesale: Data!$B$57

Sheet October Projects
B1: Daily FTE | C1: 1st shift | D1: 2nd shift | E1: WE | F1: Add to Planner
A2: Offsite | B2: 6 | C2: 3 | D2: 3 | E2: 2
A3: Flue space/Inv. location | B3: 0 | C3: 0 | D3: 0 | E3: 0
A4: Receiving Exceptions | B4: 2 | C4: 1 | D4: 1 | E4: 0
A5: Vendor Compliance | B5: 2 | C5: 1 | D5: 1 | E5: 0 | F5: X
A6: Bucket reconcilliation | B6: 2 | C6: 1 | D6: 1 | E6: 1
A7: Gaylords/transfer (SPACE) | B7: 0 | C7: 0 | D7: 0 | E7: 0
A12: Total | B12: =SUM(B2:B10) -> 12

Sheet Outbound
A1: Fiscal Week | B1: =VLOOKUP(B3,FiscalCalendar!$A:$C,3,FALSE) -> 1 | C1: =VLOOKUP(C3,FiscalCalendar!$A:$C,3,FALSE) -> 1 | D1: =VLOOKUP(D3,FiscalCalendar!$A:$C,3,FALSE) -> 1 | E1: =VLOOKUP(E3,FiscalCalendar!$A:$C,3,FALSE) -> 1 | F1: =VLOOKUP(F3,FiscalCalendar!$A:$C,3,FALSE) -> 1 | G1: =VLOOKUP(G3,FiscalCalendar!$A:$C,3,FALSE) -> 1 | H1: =VLOOKUP(H3,FiscalCalendar!$A:$C,3,FALSE) -> 1 | I1: =VLOOKUP(I3,FiscalCalendar!$A:$C,3,FALSE) -> 2 | ... IN1: =VLOOKUP(IN3,FiscalCalendar!$A:$C,3,FALSE) -> 36 | IP1: =VLOOKUP(IP3,FiscalCalendar!$A:$C,3,FALSE) -> 36 | IQ1: =VLOOKUP(IQ3,FiscalCalendar!$A:$C,3,FALSE) -> 36 | IR1: =VLOOKUP(IR3,FiscalCalendar!$A:$C,3,FALSE) -> 36 | IS1: =VLOOKUP(IS3,FiscalCalendar!$A:$C,3,FALSE) -> 36 | IT1: =VLOOKUP(IT3,FiscalCalendar!$A:$C,3,FALSE) -> 37 | IU1: =VLOOKUP(IU3,FiscalCalendar!$A:$C,3,FALSE) -> 37 | IV1: =VLOOKUP(IV3,FiscalCalendar!$A:$C,3,FALSE) -> 37 | IW1: =VLOOKUP(IW3,FiscalCalendar!$A:$C,3,FALSE) -> 37 | ... NI1: =VLOOKUP(NI3,FiscalCalendar!$A:$C,3,FALSE) -> #N/A
B2: Sunday | C2: Monday | D2: Tuesday | E2: Wednesday | F2: Thursday | G2: Friday | H2: Saturday | I2: Sunday | J2: Monday | K2: Tuesday | L2: Wednesday | M2: Thursday | N2: Friday | O2: Saturday | P2: Sunday | Q2: Monday | R2: Tuesday | S2: Wednesday | T2: Thursday | U2: Friday | V2: Saturday | W2: Sunday | X2: Monday | Y2: Tuesday | Z2: Wednesday | AA2: Thursday | AB2: Friday | AC2: Saturday | AD2: Sunday | AE2: Monday | AF2: Tuesday | AG2: Wednesday | AH2: Thursday | AI2: Friday | AJ2: Saturday | AK2: Sunday | AL2: Monday | AM2: Tuesday | AN2: Wednesday | AO2: Thursday | AP2: Friday | AQ2: Saturday | AR2: Sunday | AS2: Monday | AT2: Tuesday | AU2: Wednesday | AV2: Thursday | AW2: Friday | AX2: Saturday | AY2: Sunday | AZ2: Monday | BA2: Tuesday | BB2: Wednesday | BC2: Thursday | BD2: Friday | BE2: Saturday | BF2: Sunday | BG2: Monday | BH2: Tuesday | BI2: Wednesday | BJ2: Thursday | BK2: Friday | BL2: Saturday | BM2: Sunday | BN2: Monday | BO2: Tuesday | BP2: Wednesday | BQ2: Thursday | BR2: Friday | BS2: Saturday | BT2: Sunday | BU2: Monday | BV2: Tuesday | BW2: Wednesday | BX2: Thursday | BY2: Friday | BZ2: Saturday | CA2: Sunday | CB2: Monday | CC2: Tuesday | CD2: Wednesday | CE2: Thursday | CF2: Friday | CG2: Saturday | CH2: Sunday | CI2: Monday | CJ2: Tuesday | CK2: Wednesday | CL2: Thursday | CM2: Friday | CN2: Saturday | CO2: Sunday | CP2: Monday | CQ2: Tuesday | CR2: Wednesday | CS2: Thursday | CT2: Friday | CU2: Saturday | CV2: Sunday | CW2: Monday | CX2: Tuesday | CY2: Wednesday | CZ2: Thursday | DA2: Friday | DB2: Saturday | DC2: Sunday | DD2: Monday | DE2: Tuesday | DF2: Wednesday | DG2: Thursday | DH2: Friday | DI2: Saturday | DJ2: Sunday | DK2: Monday | DL2: Tuesday | DM2: Wednesday | DN2: Thursday | DO2: Friday | DP2: Saturday | DQ2: Sunday | DR2: Monday | DS2: Tuesday | DT2: Wednesday | DU2: Thursday | DV2: Friday | DW2: Saturday | DX2: Sunday | DY2: Monday | DZ2: Tuesday | EA2: Wednesday | EB2: Thursday | EC2: Friday | ED2: Saturday | EE2: Sunday | EF2: Monday | EG2: Tuesday | EH2: Wednesday | EI2: Thursday | EJ2: Friday | EK2: Saturday | EL2: Sunday | EM2: Monday | EN2: Tuesday | EO2: Wednesday | EP2: Thursday | EQ2: Friday | ER2: Saturday | ES2: Sunday | ET2: Monday | EU2: Tuesday | EV2: Wednesday | EW2: Thursday | EX2: Friday | EY2: Saturday | EZ2: Sunday | FA2: Monday | FB2: Tuesday | FC2: Wednesday | FD2: Thursday | FE2: Friday | FF2: Saturday | FG2: Sunday | FH2: Monday | FI2: Tuesday | FJ2: Wednesday | FK2: Thursday | FL2: Friday | FM2: Saturday | FN2: Sunday | FO2: Monday | FP2: Tuesday | FQ2: Wednesday | FR2: Thursday | FS2: Friday | FT2: Saturday | FU2: Sunday | FV2: Monday | FW2: Tuesday | FX2: Wednesday | FY2: Thursday | FZ2: Friday | GA2: Saturday | GB2: Sunday | GC2: Monday | GD2: Tuesday | GE2: Wednesday | GF2: Thursday | GG2: Friday | GH2: Saturday | GI2: Sunday | GJ2: Monday | GK2: Tuesday | GL2: Wednesday | GM2: Thursday | GN2: Friday | GO2: Saturday | GP2: Sunday | GQ2: Monday | GR2: Tuesday | GS2: Wednesday | GT2: Thursday | GU2: Friday | GV2: Saturday | GW2: Sunday | GX2: Monday | GY2: Tuesday | GZ2: Wednesday | HA2: Thursday | HB2: Friday | HC2: Saturday | HD2: Sunday | HE2: Monday | HF2: Tuesday | HG2: Wednesday | HH2: Thursday | HI2: Friday | HJ2: Saturday | HK2: Sunday | HL2: Monday | HM2: Tuesday | HN2: Wednesday | HO2: Thursday | HP2: Friday | HQ2: Saturday | HR2: Sunday | HS2: Monday | HT2: Tuesday | HU2: Wednesday | HV2: Thursday | HW2: Friday | HX2: Saturday | HY2: Sunday | HZ2: Monday | IA2: Tuesday | IB2: Wednesday | IC2: Thursday | ID2: Friday | IE2: Saturday | IF2: Sunday | IG2: Monday | IH2: Tuesday | II2: Wednesday | IJ2: Thursday | IK2: Friday | IL2: Saturday | IM2: Sunday | IN2: Monday | IO2: Tuesday | IP2: Wednesday | IQ2: Thursday | IR2: Friday | IS2: Saturday | IT2: Sunday | IU2: Monday | IV2: Tuesday | IW2: Wednesday | IX2: Thursday | IY2: Friday | IZ2: Saturday | JA2: Sunday | JB2: Monday | JC2: Tuesday | JD2: Wednesday | JE2: Thursday | JF2: Friday | JG2: Saturday | JH2: Sunday | JI2: Monday | JJ2: Tuesday | JK2: Wednesday | JL2: Thursday | JM2: Friday | JN2: Saturday | JO2: Sunday | JP2: Monday | JQ2: Tuesday | JR2: Wednesday | JS2: Thursday | JT2: Friday | JU2: Saturday | JV2: Sunday | JW2: Monday | JX2: Tuesday | JY2: Wednesday | JZ2: Thursday | KA2: Friday | KB2: Saturday | KC2: Sunday | KD2: Monday | KE2: Tuesday | KF2: Wednesday | KG2: Thursday | KH2: Friday | KI2: Saturday | KJ2: Sunday | KK2: Monday | KL2: Tuesday | KM2: Wednesday | KN2: Thursday | KO2: Friday | KP2: Saturday | KQ2: Sunday | KR2: Monday | KS2: Tuesday | KT2: Wednesday | KU2: Thursday | KV2: Friday | KW2: Saturday | KX2: Sunday | KY2: Monday | KZ2: Tuesday | LA2: Wednesday | LB2: Thursday | LC2: Friday | LD2: Saturday | LE2: Sunday | LF2: Monday | LG2: Tuesday | LH2: Wednesday | LI2: Thursday | LJ2: Friday | LK2: Saturday | LL2: Sunday | LM2: Monday | LN2: Tuesday | LO2: Wednesday | LP2: Thursday | LQ2: Friday | LR2: Saturday | LS2: Sunday | LT2: Monday | LU2: Tuesday | LV2: Wednesday | LW2: Thursday | LX2: Friday | LY2: Saturday | LZ2: Sunday | MA2: Monday | MB2: Tuesday | MC2: Wednesday | MD2: Thursday | ME2: Friday | MF2: Saturday | MG2: Sunday | MH2: Monday | MI2: Tuesday | MJ2: Wednesday | MK2: Thursday | ML2: Friday | MM2: Saturday | MN2: Sunday | MO2: Monday | MP2: Tuesday | MQ2: Wednesday | MR2: Thursday | MS2: Friday | MT2: Saturday | MU2: Sunday | MV2: Monday | MW2: Tuesday | MX2: Wednesday | MY2: Thursday | MZ2: Friday | NA2: Saturday | NB2: Sunday | NC2: Monday | ND2: Tuesday | NE2: Wednesday | NF2: Thursday | NG2: Friday | NH2: Saturday | NI2: Sunday
B3: 45690 | C3: 45691 | D3: 45692 | E3: 45693 | F3: 45694 | G3: 45695 | H3: 45696 | I3: 45697 | J3: 45698 | K3: 45699 | L3: 45700 | M3: 45701 | N3: 45702 | O3: 45703 | P3: 45704 | Q3: 45705 | R3: 45706 | S3: 45707 | T3: 45708 | U3: 45709 | V3: 45710 | W3: 45711 | X3: 45712 | Y3: 45713 | Z3: 45714 | AA3: 45715 | AB3: 45716 | AC3: 45717 | AD3: 45718 | AE3: 45719 | AF3: 45720 | AG3: 45721 | AH3: 45722 | AI3: 45723 | AJ3: 45724 | AK3: 45725 | AL3: 45726 | AM3: 45727 | AN3: 45728 | AO3: 45729 | AP3: 45730 | AQ3: 45731 | AR3: 45732 | AS3: 45733 | AT3: 45734 | AU3: 45735 | AV3: 45736 | AW3: 45737 | AX3: 45738 | AY3: 45739 | AZ3: 45740 | BA3: 45741 | BB3: 45742 | BC3: 45743 | BD3: 45744 | BE3: 45745 | BF3: 45746 | BG3: 45747 | BH3: 45748 | BI3: 45749 | BJ3: 45750 | BK3: 45751 | BL3: 45752 | BM3: 45753 | BN3: 45754 | BO3: 45755 | BP3: 45756 | BQ3: 45757 | BR3: 45758 | BS3: 45759 | BT3: 45760 | BU3: 45761 | BV3: 45762 | BW3: 45763 | BX3: 45764 | BY3: 45765 | BZ3: 45766 | CA3: 45767 | CB3: 45768 | CC3: 45769 | CD3: 45770 | CE3: 45771 | CF3: 45772 | CG3: 45773 | CH3: 45774 | CI3: 45775 | CJ3: 45776 | CK3: 45777 | CL3: 45778 | CM3: 45779 | CN3: 45780 | CO3: 45781 | CP3: 45782 | CQ3: 45783 | CR3: 45784 | CS3: 45785 | CT3: 45786 | CU3: 45787 | CV3: 45788 | CW3: 45789 | CX3: 45790 | CY3: 45791 | CZ3: 45792 | DA3: 45793 | DB3: 45794 | DC3: 45795 | DD3: 45796 | DE3: 45797 | DF3: 45798 | DG3: 45799 | DH3: 45800 | DI3: 45801 | DJ3: 45802 | DK3: 45803 | DL3: 45804 | DM3: 45805 | DN3: 45806 | DO3: 45807 | DP3: 45808 | DQ3: 45809 | DR3: 45810 | DS3: 45811 | DT3: 45812 | DU3: 45813 | DV3: 45814 | DW3: 45815 | DX3: 45816 | DY3: 45817 | DZ3: 45818 | EA3: 45819 | EB3: 45820 | EC3: 45821 | ED3: 45822 | EE3: 45823 | EF3: 45824 | EG3: 45825 | EH3: 45826 | EI3: 45827 | EJ3: 45828 | EK3: 45829 | EL3: 45830 | EM3: 45831 | EN3: 45832 | EO3: 45833 | EP3: 45834 | EQ3: 45835 | ER3: 45836 | ES3: 45837 | ET3: 45838 | EU3: 45839 | EV3: 45840 | EW3: 45841 | EX3: 45842 | EY3: 45843 | EZ3: 45844 | FA3: 45845 | FB3: 45846 | FC3: 45847 | FD3: 45848 | FE3: 45849 | FF3: 45850 | FG3: 45851 | FH3: 45852 | FI3: 45853 | FJ3: 45854 | FK3: 45855 | FL3: 45856 | FM3: 45857 | FN3: 45858 | FO3: 45859 | FP3: 45860 | FQ3: 45861 | FR3: 45862 | FS3: 45863 | FT3: 45864 | FU3: 45865 | FV3: 45866 | FW3: 45867 | FX3: 45868 | FY3: 45869 | FZ3: 45870 | GA3: 45871 | GB3: 45872 | GC3: 45873 | GD3: 45874 | GE3: 45875 | GF3: 45876 | GG3: 45877 | GH3: 45878 | GI3: 45879 | GJ3: 45880 | GK3: 45881 | GL3: 45882 | GM3: 45883 | GN3: 45884 | GO3: 45885 | GP3: 45886 | GQ3: 45887 | GR3: 45888 | GS3: 45889 | GT3: 45890 | GU3: 45891 | GV3: 45892 | GW3: 45893 | GX3: 45894 | GY3: 45895 | GZ3: 45896 | HA3: 45897 | HB3: 45898 | HC3: 45899 | HD3: 45900 | HE3: 45901 | HF3: 45902 | HG3: 45903 | HH3: 45904 | HI3: 45905 | HJ3: 45906 | HK3: 45907 | HL3: 45908 | HM3: 45909 | HN3: 45910 | HO3: 45911 | HP3: 45912 | HQ3: 45913 | HR3: 45914 | HS3: 45915 | HT3: 45916 | HU3: 45917 | HV3: 45918 | HW3: 45919 | HX3: 45920 | HY3: 45921 | HZ3: 45922 | IA3: 45923 | IB3: 45924 | IC3: 45925 | ID3: 45926 | IE3: 45927 | IF3: 45928 | IG3: 45929 | IH3: 45930 | II3: 45931 | IJ3: 45932 | IK3: 45933 | IL3: 45934 | IM3: 45935 | IN3: 45936 | IO3: 45937 | IP3: 45938 | IQ3: 45939 | IR3: 45940 | IS3: 45941 | IT3: 45942 | IU3: 45943 | IV3: 45944 | IW3: 45945 | IX3: 45946 | IY3: 45947 | IZ3: 45948 | JA3: 45949 | JB3: 45950 | JC3: 45951 | JD3: 45952 | JE3: 45953 | JF3: 45954 | JG3: 45955 | JH3: 45956 | JI3: 45957 | JJ3: 45958 | JK3: 45959 | JL3: 45960 | JM3: 45961 | JN3: 45962 | JO3: 45963 | JP3: 45964 | JQ3: 45965 | JR3: 45966 | JS3: 45967 | JT3: 45968 | JU3: 45969 | JV3: 45970 | JW3: 45971 | JX3: 45972 | JY3: 45973 | JZ3: 45974 | KA3: 45975 | KB3: 45976 | KC3: 45977 | KD3: 45978 | KE3: 45979 | KF3: 45980 | KG3: 45981 | KH3: 45982 | KI3: 45983 | KJ3: 45984 | KK3: 45985 | KL3: 45986 | KM3: 45987 | KN3: 45988 | KO3: 45989 | KP3: 45990 | KQ3: 45991 | KR3: 45992 | KS3: 45993 | KT3: 45994 | KU3: 45995 | KV3: 45996 | KW3: 45997 | KX3: 45998 | KY3: 45999 | KZ3: 46000 | LA3: 46001 | LB3: 46002 | LC3: 46003 | LD3: 46004 | LE3: 46005 | LF3: 46006 | LG3: 46007 | LH3: 46008 | LI3: 46009 | LJ3: 46010 | LK3: 46011 | LL3: 46012 | LM3: 46013 | LN3: 46014 | LO3: 46015 | LP3: 46016 | LQ3: 46017 | LR3: 46018 | LS3: 46019 | LT3: 46020 | LU3: 46021 | LV3: 46022 | LW3: 46023 | LX3: 46024 | LY3: 46025 | LZ3: 46026 | MA3: 46027 | MB3: 46028 | MC3: 46029 | MD3: 46030 | ME3: 46031 | MF3: 46032 | MG3: 46033 | MH3: 46034 | MI3: 46035 | MJ3: 46036 | MK3: 46037 | ML3: 46038 | MM3: 46039 | MN3: 46040 | MO3: 46041 | MP3: 46042 | MQ3: 46043 | MR3: 46044 | MS3: 46045 | MT3: 46046 | MU3: 46047 | MV3: 46048 | MW3: 46049 | MX3: 46050 | MY3: 46051 | MZ3: 46052 | NA3: 46053 | NB3: 46054 | NC3: 46055 | ND3: 46056 | NE3: 46057 | NF3: 46058 | NG3: 46059 | NH3: 46060 | NI3: 46061
A4: Orders | DP4: Azure switchover after hours | DX4: Azure switchback | DY4: OMS SFSC? | EF4: OMS Phase 2 | EK4: Updated Hanna Sale start | EO4: Hanna Sale | FG4: Potential Azure switchover | GF4: GOTs Audit? | IL4: 40/50/60 | IM4: Only WE | IN4: WE/2nd | IO4: 1st/2nd | IP4: 1st/2nd | IQ4: 1st/2nd | IR4: ALL | IS4: Only WE | IT4: 2nd/WE | IU4: ALL | IV4: 1st/2nd | IW4: 1st/2nd | IX4: ALL | IY4: 1st/WE | IZ4: Only WE | JA4: 2nd/WE | JB4: ALL | JC4: ALL | JD4: 1st/2nd | JE4: ALL | JF4: ALL | JG4: 1st/WE | KI4: 60/60/40 | KJ4: ALL | KK4: ALL | KL4: ALL | KM4: ALL | KO4: ALL | KP4: ALL | KQ4: ALL | KR4: ALL | KS4: ALL | KT4: ALL | KU4: 1st/2nd | KV4: 2nd/WE | KW4: 1st/WE | LB4: SP cust. cut-off | LE4: All SP must be shipped! | LH4: LAST DAY FEDEX/UPS GND | LJ4: 3D cut-off | LM4: 2D cut-off | LN4: Overnight cut-off
A5: Remaining Volume (Units) | B5: 2500 | C5: =B5-B7+B10 -> 4373 | D5: =C5-C7+C10 -> 2903 | E5: =D5-D7+D10 -> 2297 | F5: =E5-E7+E10 -> 2335 | G5: =F5-F7+F10 -> 1878 | H5: =G5-G7+G10 -> 4491 | I5: =H5-H7+H10 -> 8088 | J5: =I5-I7+I10 -> 3446 | ... AD5: =AC5-AC7+AC10 -> 10728 | AE5: 18152 | AF5: =AE5-AE7+AE10 -> 5729 | AG5: =AF5-AF7+AF10 -> 4820 | AH5: =AG5-AG7+AG10 -> 4938 | AI5: =AH5-AH7+AH10 -> 4204 | AJ5: =AI5-AI7+AI10 -> 8051 | AK5: =AJ5-AJ7+AJ10 -> 10719 | AL5: =AK5-AK7+AK10 -> 6242 | AM5: =AL5-AL7+AL10 -> 5274 | ... BO5: =BN5-BN7+BN10 -> 10075 | BP5: 10441 | BQ5: =BP5-BP7+BP10 -> 6981 | BR5: =BQ5-BQ7+BQ10 -> 4949 | BS5: =BR5-BR7+BR10 -> 11812 | BT5: =BS5-BS7+BS10 -> 12529 | BU5: =BT5-BT7+BT10 -> 11429 | BV5: =BU5-BU7+BU10 -> 4777 | BW5: 6426 | BX5: =BW5-BW7+BW10 -> 4505 | BY5: =BX5-BX7+BX10 -> 3139 | BZ5: =BY5-BY7+BY10 -> 6894 | CA5: =BZ5-BZ7+BZ10 -> 6494 | CB5: =CA5-CA7+CA10 -> 17266 | CC5: =CB5-CB7+CB10 -> 5113 | CD5: =CC5-CC7+CC10 -> 5191 | CE5: =CD5-CD7+CD10 -> 17463 | ... CH5: =CG5-CG7+CG10 -> 20831 | CI5: 30198 | CJ5: =CI5-CI7+CI10 -> 14432 | CK5: =CJ5-CJ7+CJ10 -> 12947 | CL5: =CK5-CK7+CK10 -> 41236 | CM5: =CL5-CL7+CL10 -> 39399 | CN5: =CM5-CM7+CM10 -> 44494 | CO5: =CN5-CN7+CN10 -> 74608 | CP5: 73472 | CQ5: =CP5-CP7+CP10 -> 66226 | CR5: =CQ5-CQ7+CQ10 -> 59910 | CS5: =CR5-CR7+CR10 -> 41369 | CT5: =CS5-CS7+CS10 -> 25658 | CU5: =CT5-CT7+CT10 -> 22965.991 | CV5: =CU5-CU7+CU10 -> 17819.996 | CW5: =CV5-CV7+CV10 -> 30564.983 | CX5: =CW5-CW7+CW10 -> 14194.988 | ... DQ5: =DP5-DP7+DP10 -> 17777.988 | DR5: 11363 | DS5: =DR5-DR7+DR10 -> 6503 | DT5: =DS5-DS7+DS10 -> 4518 | DU5: =DT5-DT7+DT10 -> 6173 | DV5: =DU5-DU7+DU10 -> 5374 | DW5: =DV5-DV7+DV10 -> 7788 | DX5: =DW5-DW7+DW10 -> 11299 | DY5: =DX5-DX7+DX10 -> 7199 | DZ5: 9044 | EA5: =DZ5-DZ7+DZ10 -> 6993 | EB5: =EA5-EA7+EA10 -> 6799 | EC5: =EB5-EB7+EB10 -> 5787 | ED5: =EC5-EC7+EC10 -> 8001 | EE5: =ED5-ED7+ED10 -> 14225 | EF5: =EE5-EE7+EE10 -> 29674 | EG5: =EF5-EF7+EF10 -> 22131 | EH5: =EG5-EG7+EG10 -> 12563 | ... GD5: =GC5-GC7+GC10 -> 2564 | GE5: 5042 | GF5: =GE5-GE7+GE10 -> 5211 | GG5: =GF5-GF7+GF10 -> 5482 | GH5: =GG5-GG7+GG10 -> 9045 | GI5: =GH5-GH7+GH10 -> 19736 | GJ5: =GI5-GI7+GI10 -> 14473 | GK5: =GJ5-GJ7+GJ10 -> 11515 | GL5: =GK5-GK7+GK10 -> 5808 | GM5: =GL5-GL7+GL10 -> 5702 | ... GP5: =GO5-GO7+GO10 -> 10951 | GQ5: 7544 | GR5: =GQ5-GQ7+GQ10 -> 7724 | GS5: =GR5-GR7+GR10 -> 7655 | GT5: =GS5-GS7+GS10 -> 9337 | GU5: =GT5-GT7+GT10 -> 21242 | GV5: =GU5-GU7+GU10 -> 29338 | GW5: =GV5-GV7+GV10 -> 41015 | GX5: =GW5-GW7+GW10 -> 43947 | GY5: =GX5-GX7+GX10 -> 43017 | ... HF5: =HE5-HE7+HE10 -> 116321 | HG5: 129828 | HH5: =HG5-HG7+HG10 -> 108857 | HI5: =HH5-HH7+HH10 -> 88919 | HJ5: =HI5-HI7+HI10 -> 76615 | HK5: =HJ5-HJ7+HJ10 -> 65519 | HL5: 46014 | HM5: =HL5-HL7+HL10 -> 29623 | HN5: =HM5-HM7+HM10 -> 22265 | HO5: 12185 | HP5: =HO5-HO7+HO10 -> 10960 | HQ5: =HP5-HP7+HP10 -> 11330 | HR5: =HQ5-HQ7+HQ10 -> 11359 | HS5: =HR5-HR7+HR10 -> 10425 | HT5: =HS5-HS7+HS10 -> 4476 | HU5: =HT5-HT7+HT10 -> 3516 | HV5: 4693 | HW5: =HV5-HV7+HV10 -> 7747 | HX5: =HW5-HW7+HW10 -> 16383 | HY5: =HX5-HX7+HX10 -> 22784 | HZ5: =HY5-HY7+HY10 -> 21920 | IA5: =HZ5-HZ7+HZ10 -> 23977 | IB5: =IA5-IA7+IA10 -> 35660 | IC5: =IB5-IB7+IB10 -> 26021 | ID5: =IC5-IC7+IC10 -> 15685 | ... IM5: =IL5-IL7+IL10 -> 9151 | IN5: 14913 | IO5: =IN5-IN7+IN10 -> 9115 | IP5: =IO5-IO7+IO10 -> 32054 | IQ5: =IP5-IP7+IP10 -> 51305 | IR5: =IQ5-IQ7+IQ10 -> 82041 | IS5: =IR5-IR7+IR10 -> 78719 | IT5: =IS5-IS7+IS10 -> 97247 | IU5: =IT5-IT7+IT10 -> 118066 | IV5: =IU5-IU7+IU10 -> 119023 | ... JH5: =JG5-JG7+JG10 -> 26582 | JI5: 17092 | JJ5: =JI5-JI7+JI10 -> 10618 | JK5: =JJ5-JJ7+JJ10 -> 8672 | JL5: =JK5-JK7+JK10 -> 13651 | JM5: =JL5-JL7+JL10 -> 18750 | JN5: =JM5-JM7+JM10 -> 20664 | JO5: =JN5-JN7+JN10 -> 46950 | JP5: =JO5-JO7+JO10 -> 82500 | JQ5: 79205 | JR5: =JQ5-JQ7+JQ10 -> 53415 | JS5: =JR5-JR7+JR10 -> 31918 | JT5: 19677 | JU5: =JT5-JT7+JT10 -> 20070 | JV5: =JU5-JU7+JU10 -> 34677 | JW5: 47576 | JX5: =JW5-JW7+JW10 -> 24489 | JY5: =JX5-JX7+JX10 -> 16236 | JZ5: 9849 | KA5: =JZ5-JZ7+JZ10 -> 17521 | KB5: =KA5-KA7+KA10 -> 29590 | KC5: =KB5-KB7+KB10 -> 56613 | KD5: =KC5-KC7+KC10 -> 57790 | KE5: =KD5-KD7+KD10 -> 19014 | KF5: =KE5-KE7+KE10 -> 31448 | KG5: =KF5-KF7+KF10 -> 20502 | KH5: =KG5-KG7+KG10 -> 16138 | ... KX5: =KW5-KW7+KW10 -> 72075 | KY5: 88387 | KZ5: =KY5-KY7+KY10 -> 67297 | LA5: =KZ5-KZ7+KZ10 -> 54525 | LB5: =LA5-LA7+LA10 -> 39248 | LC5: =LB5-LB7+LB10 -> 32945 | LD5: =LC5-LC7+LC10 -> 44558 | LE5: =LD5-LD7+LD10 -> 54581 | LF5: =LE5-LE7+LE10 -> 58666 | LG5: =LF5-LF7+LF10 -> 41251 | LH5: 39516 | LI5: =LH5-LH7+LH10 -> 10795 | LJ5: =LI5-LI7+LI10 -> 11156 | LK5: =LJ5-LJ7+LJ10 -> 12212 | LL5: =LK5-LK7+LK10 -> 11479 | LM5: =LL5-LL7+LL10 -> 5492 | LN5: =LM5-LM7+LM10 -> 4247 | LO5: =LN5-LN7+LN10 -> 2741 | LP5: =LO5-LO7+LO10 -> 9008 | ... LS5: =LR5-LR7+LR10 -> 33227 | LT5: 53155 | LU5: =LT5-LT7+LT10 -> 51243 | LV5: =LU5-LU7+LU10 -> 49684 | LW5: =LV5-LV7+LV10 -> 73486 | LX5: =LW5-LW7+LW10 -> 100571 | LY5: =LX5-LX7+LX10 -> 74410 | LZ5: =LY5-LY7+LY10 -> 86736 | MA5: =LZ5-LZ7+LZ10 -> 75276 | MB5: =MA5-MA7+MA10 -> 61310 | ... MK5: =MJ5-MJ7+MJ10 -> 10268 | ML5: 10925 | MM5: =ML5-ML7+ML10 -> 10544 | MN5: =MM5-MM7+MM10 -> 21387 | MO5: =MN5-MN7+MN10 -> 21301 | MP5: =MO5-MO7+MO10 -> 40822 | MQ5: =MP5-MP7+MP10 -> 27942 | MR5: 12573 | MS5: =MR5-MR7+MR10 -> 4034 | MT5: =MS5-MS7+MS10 -> 7298 | MU5: =MT5-MT7+MT10 -> 15545 | MV5: =MU5-MU7+MU10 -> 28231 | MW5: =MV5-MV7+MV10 -> 27464 | MX5: =MW5-MW7+MW10 -> 14867 | MY5: =MX5-MX7+MX10 -> 7385 | MZ5: =MY5-MY7+MY10 -> 3588 | ... NI5: =NH5-NH7+NH10 -> 15780.858
A6: Units Shipped Goal | B6: =B5 -> 2500 | C6: 7000 | D6: 7000 | E6: 8000 | F6: 7000 | G6: 3000 | H6: 5000 | I6: 15000 | J6: 8000 | K6: 7000 | L6: 7000 | M6: 8000 | N6: 7000 | O6: 12000 | P6: 22000 | Q6: 27000 | R6: 14000 | S6: 0 | T6: 15000 | U6: 7000 | V6: 7000 | W6: 15000 | X6: 18000 | Y6: 8000 | Z6: 8000 | AA6: 8000 | AB6: 7000 | AC6: 7000 | AD6: 15000 | AE6: 17000 | AF6: 9000 | AG6: 8000 | AH6: 6000 | AI6: 5000 | AJ6: 7000 | AK6: 17000 | AL6: 17000 | AM6: 12000 | AN6: 12000 | AO6: 10000 | AP6: 12000 | AQ6: 12000 | AR6: 20000 | AS6: 28000 | AT6: 12000 | AU6: 13000 | AV6: 8000 | AW6: 10000 | AX6: 14000 | AY6: 24000 | AZ6: 30000 | BA6: 13500 | BB6: 14000 | BC6: 14000 | BD6: 6000 | BE6: 6000 | BF6: 15000 | BG6: 15000 | BH6: 10000 | BI6: 10000 | BJ6: 10000 | BK6: 7000 | BL6: 12000 | BM6: 25000 | BN6: 23000 | BO6: 13000 | BP6: 13000 | BQ6: 11000 | BR6: 10000 | BS6: 12500 | BT6: 20000 | BU6: 14000 | BV6: 9000 | BW6: 9000 | BX6: 8000 | BY6: 6000 | BZ6: 12000 | CA6: 0 | CB6: 20000 | CC6: 10000 | CD6: 15000 | CE6: 21000 | CF6: 25000 | CG6: 16000 | CH6: 28000 | CI6: 36000 | CJ6: 20000 | CK6: 20000 | CL6: 32000 | CM6: 22000 | CN6: 16000 | CO6: 28000 | CP6: 36000 | CQ6: 26000 | CR6: 26000 | CS6: 26000 | CT6: 15000 | CU6: 15000 | CV6: 0 | CW6: 32000 | CX6: 14000 | CY6: 10000 | CZ6: 9000 | DA6: 15000 | DB6: 15000 | DC6: 28000 | DD6: 32000 | DE6: 26000 | DF6: 24000 | DG6: 23000 | DH6: 20000 | DI6: 20000 | DJ6: 32000 | DK6: 36000 | DL6: 32000 | DM6: 30000 | DN6: 24000 | DO6: 20000 | DP6: 14000 | DQ6: 23000 | DR6: 10000 | DS6: 10000 | DT6: 7000 | DU6: 10000 | DV6: 10000 | DW6: 10000 | DX6: 15000 | DY6: 11000 | DZ6: 10000 | EA6: 8000 | EB6: 10000 | EC6: 6500 | ED6: 9000 | EE6: 0 | EF6: 25000 | EG6: 20000 | EH6: 15000 | EI6: 10000 | EJ6: 11000 | EK6: 15000 | EL6: 30000 | EM6: 40000 | EN6: 25000 | EO6: 25000 | EP6: 24000 | EQ6: 22000 | ER6: 20000 | ES6: 35000 | ET6: 40000 | EU6: 38000 | EV6: 25000 | EW6: 40000 | EX6: 35000 | EY6: 25000 | EZ6: 35000 | FA6: 40000 | FB6: 35000 | FC6: 25000 | FD6: 26000 | FE6: 25000 | FF6: 20000 | FG6: 30000 | FH6: 27000 | FI6: 21000 | FJ6: 20000 | FK6: 16000 | FL6: 6000 | FM6: 8000 | FN6: 16000 | FO6: 10000 | FP6: 8000 | FQ6: 9000 | FR6: 8000 | FS6: 8000 | FT6: 8000 | FU6: 16000 | FV6: 16000 | FW6: 10000 | FX6: 10000 | FY6: 10000 | FZ6: 8000 | GA6: 8000 | GB6: 15000 | GC6: 18000 | GD6: 9000 | GE6: 7000 | GF6: 8000 | GG6: 6000 | GH6: 7000 | GI6: 25000 | GJ6: 19000 | GK6: 12000 | GL6: 7000 | GM6: 10000 | GN6: 7000 | GO6: 8000 | GP6: 15000 | GQ6: 11000 | GR6: 11000 | GS6: 11000 | GT6: 15000 | GU6: 14000 | GV6: 14000 | GW6: 30000 | GX6: 33000 | GY6: 30000 | GZ6: 28000 | HA6: 26000 | HB6: 20000 | HC6: 20000 | HD6: 35000 | HE6: 36000 | HF6: 35000 | HG6: 30000 | HH6: 30000 | HI6: 26000 | HJ6: 20000 | HK6: 35000 | HL6: 30000 | HM6: 17000 | HN6: 17000 | HO6: 13000 | HP6: 11000 | HQ6: 17000 | HR6: 25000 | HS6: 14000 | HT6: 8000 | HU6: 9000 | HV6: 8000 | HW6: 7000 | HX6: 12000 | HY6: 30000 | HZ6: 25000 | IA6: 20000 | IB6: 22000 | IC6: 22000 | ID6: 13500 | IE6: 15000 | IF6: 25000 | IG6: 15000 | IH6: 15000 | II6: 10000 | IJ6: 10000 | IK6: 7000 | IL6: 12000 | IM6: 17000 | IN6: 17000 | IO6: 25000 | IP6: 30000 | IQ6: 30000 | IR6: 55000 | IS6: 20000 | IT6: 38000 | IU6: 50000 | IV6: 40500 | IW6: 41000 | IX6: 50000 | IY6: 40000 | IZ6: 24000 | JA6: 42000 | JB6: 52000 | JC6: 55000 | JD6: 50000 | JE6: 55000 | JF6: 65000 | JG6: 38000 | JH6: 32000 | JI6: 25000 | JJ6: 16000 | JK6: 18000 | JL6: 22000 | JM6: 22000 | JN6: 20000 | JO6: 40000 | JP6: 65000 | JQ6: 45000 | JR6: 45000 | JS6: 30000 | JT6: 15000 | JU6: 22000 | JV6: 40000 | JW6: 45000 | JX6: 30000 | JY6: 32000 | JZ6: 30000 | KA6: 20000 | KB6: 20000 | KC6: 45000 | KD6: 75000 | KE6: 55000 | KF6: 55000 | KG6: 55000 | KH6: 30000 | KI6: 25000 | KJ6: 75000 | KK6: 65000 | KL6: 55000 | KM6: 47000 | KN6: 0 | KO6: 80000 | KP6: 80000 | KQ6: 80000 | KR6: 75000 | KS6: 75000 | KT6: 75000 | KU6: 55000 | KV6: 47500 | KW6: 47500 | KX6: 45000 | KY6: 60000 | KZ6: 45000 | LA6: 45000 | LB6: 35000 | LC6: 18000 | LD6: 20000 | LE6: 40000 | LF6: 50000 | LG6: 46000 | LH6: 46000 | LI6: 20000 | LJ6: 15000 | LK6: 15000 | LL6: 20000 | LM6: 16000 | LN6: 9000 | LO6: 0 | LP6: 0 | LQ6: 50000 | LR6: 20000 | LS6: 40000 | LT6: 50000 | LU6: 40000 | LV6: 0 | LW6: 0 | LX6: 60000 | LY6: 26000 | LZ6: 38000 | MA6: 50000 | MB6: 40000 | MC6: 35000 | MD6: 22000 | ME6: 10000 | MF6: 10000 | MG6: 22000 | MH6: 30000 | MI6: 15000 | MJ6: 15000 | MK6: 12000 | ML6: 8000 | MM6: 8000 | MN6: 18000 | MO6: 0 | MP6: 18000 | MQ6: 18000 | MR6: 12000 | MS6: 6000 | MT6: 4000 | MU6: 0 | MV6: 0 | MW6: 14000 | MX6: 11000 | MY6: 7000 | MZ6: 5000 | NA6: 5000 | NB6: 5000 | NC6: 14000 | ND6: 7003 | NE6: 7004 | NF6: 7005 | NG6: 7006 | NH6: 7007 | NI6: 7008
A7: Shipped Units (PowerBi) | B7: 7700 | C7: 10524 | D7: 10799 | E7: 9520 | F7: 10470 | G7: 5668 | H7: 5929 | I7: 14944 | J7: 11440 | K7: 8989 | L7: 8111 | M7: 7313 | N7: 7107 | O7: 8732 | P7: 21935 | Q7: 26305 | R7: 18637 | S7: =S6 -> 0 | T7: 18837 | U7: 7944 | V7: 7973 | W7: 22771 | X7: 21362 | Y7: 9783 | Z7: 9890 | AA7: 9821 | AB7: 5028 | AC7: 7408 | AD7: 18288 | AE7: 22198 | AF7: 10631 | AG7: 9818 | AH7: 10160 | AI7: 5556 | AJ7: 8682 | AK7: 17677 | AL7: 12264 | AM7: 12070 | AN7: 12158 | AO7: 12139 | AP7: 11311 | AQ7: 13639 | AR7: 23854 | AS7: 28893 | AT7: 13864 | AU7: 12219 | AV7: 10122 | AW7: 7412 | AX7: 14291 | AY7: 20606 | AZ7: 26568 | BA7: 21812 | BB7: 20014 | BC7: 17377 | BD7: 6689 | BE7: 9642 | BF7: 14940 | BG7: 19060 | BH7: 13703 | BI7: 8438 | BJ7: 11835 | BK7: 8211 | BL7: 13864 | BM7: 19823 | BN7: 23922 | BO7: 15270 | BP7: 14109 | BQ7: 12371 | BR7: 5991 | BS7: 12307 | BT7: 16163 | BU7: 16444 | BV7: 10472 | BW7: 10624 | BX7: 9221 | BY7: 4799 | BZ7: 8979 | CA7: =CA6 -> 0 | CB7: 24191 | CC7: 10821 | CD7: 18882 | CE7: 27212 | CF7: 28131 | CG7: 13897 | CH7: 28284 | CI7: 37301 | CJ7: 21227 | CK7: 23434 | CL7: 35077 | CM7: 24513 | CN7: 13966 | CO7: 28310 | CP7: 37087 | CQ7: 30746 | CR7: 27300 | CS7: 24172 | CT7: 14813 | CU7: 15480 | CV7: =CV6 -> 0 | CW7: 26738 | CX7: 15489 | CY7: 11507 | CZ7: 11150 | DA7: 11527 | DB7: 15236 | DC7: 24244 | DD7: 26188 | DE7: 27656 | DF7: 22644 | DG7: 21907 | DH7: 20408 | DI7: 23185 | DJ7: 24258 | DK7: 39114 | DL7: 39399 | DM7: 39857 | DN7: 25906 | DO7: 18166 | DP7: 15307 | DQ7: 22323 | DR7: 14790 | DS7: 11588 | DT7: 9285 | DU7: 10532 | DV7: 6885 | DW7: 7183 | DX7: 16934 | DY7: 12488 | DZ7: 12080 | EA7: 10034 | EB7: 9585 | EC7: 6258 | ED7: 9392 | EE7: =EE6 -> 0 | EF7: 24748 | EG7: 19693 | EH7: 15511 | EI7: 10944 | EJ7: 6682 | EK7: 8178 | EL7: 33153 | EM7: 41129 | EN7: 26143 | EO7: 23676 | EP7: 24350 | EQ7: 19673 | ER7: 20061 | ES7: 36717 | ET7: 45095 | EU7: 42223 | EV7: 29692 | EW7: 36733 | EX7: 33327 | EY7: 23948 | EZ7: 35587 | FA7: 40966 | FB7: 36928 | FC7: 28608 | FD7: 27660 | FE7: 23343 | FF7: 22850 | FG7: 27055 | FH7: 26529 | FI7: 25645 | FJ7: 18034 | FK7: 16891 | FL7: 9098 | FM7: 9975 | FN7: 19622 | FO7: 12075 | FP7: 11835 | FQ7: 10000 | FR7: 9284 | FS7: 4688 | FT7: 7915 | FU7: 19584 | FV7: 16857 | FW7: 8621 | FX7: 10256 | FY7: 8948 | FZ7: 4802 | GA7: 8651 | GB7: 17949 | GC7: 11914 | GD7: 12448 | GE7: 10248 | GF7: 10078 | GG7: 6700 | GH7: 9518 | GI7: 26923 | GJ7: 22700 | GK7: 17358 | GL7: 11417 | GM7: 11578 | GN7: 6757 | GO7: 10148 | GP7: 19631 | GQ7: 15220 | GR7: 13038 | GS7: 15230 | GT7: 18978 | GU7: 16087 | GV7: 15569 | GW7: 31560 | GX7: 32648 | GY7: 29312 | GZ7: 30029 | HA7: 30148 | HB7: 36640 | HC7: 18650 | HD7: 38069 | HE7: 39475 | HF7: 37733 | HG7: 34449 | HH7: 31175 | HI7: 23845 | HJ7: 22241 | HK7: 38100 | HL7: 31301 | HM7: 19419 | HN7: 18673 | HO7: 15603 | HP7: 11367 | HQ7: 12467 | HR7: 18942 | HS7: 16385 | HT7: 10306 | HU7: 9831 | HV7: 14034 | HW7: 8009 | HX7: 13024 | HY7: 31464 | HZ7: 23752 | IA7: 22936 | IB7: 23713 | IC7: 24150 | ID7: 11446 | IE7: 14496 | IF7: 21195 | IG7: 17968 | IH7: 15163 | II7: 12974 | IJ7: 15447 | IK7: 6063 | IL7: 13125 | IM7: 15149 | IN7: 20061 | IO7: 27146 | IP7: 31066 | IQ7: 30998 | IR7: 57145 | IS7: 26540 | IT7: 39353 | IU7: 53107 | IV7: 43774 | IW7: 46603 | IX7: 49048 | IY7: 41855 | IZ7: 24756 | JA7: 54775 | JB7: 58868 | JC7: 57512 | JD7: 51429 | JE7: 59820 | JF7: 68109 | JG7: 39996 | JH7: 36962 | JI7: 24841 | JJ7: 19635 | JK7: 13887 | JL7: 25847 | JM7: 18303 | JN7: 21384 | JO7: 34285 | JP7: 49406 | JQ7: 46426 | JR7: 40538 | JS7: 32640 | JT7: 17380 | JU7: 20439 | JV7: 36014 | JW7: 48172 | JX7: 32728 | JY7: 28706 | JZ7: 28040 | KA7: 18649 | KB7: 16686 | KC7: 50225 | KD7: 73501 | KE7: 48278 | KF7: 56917 | KG7: 49584 | KH7: 32432 | KI7: 25469 | KJ7: 78828 | KK7: 71284 | KL7: 59828 | KM7: 51122 | KN7: =KN6 -> 0 | KO7: 90465 | KP7: 83936 | KQ7: 85314 | KR7: 80694 | KS7: 77116 | KT7: 72191 | KU7: 62800 | KV7: 48638 | KW7: 37530 | KX7: 46912 | KY7: 60510 | KZ7: 47829 | LA7: 42552 | LB7: 31857 | LC7: 13702 | LD7: 25226 | LE7: 36525 | LF7: 48897 | LG7: 49065 | LH7: 48939 | LI7: 17169 | LJ7: 15427 | LK7: 13284 | LL7: 18479 | LM7: 10524 | LN7: 8546 | LO7: =LO6 -> 0 | LP7: =LP6 -> 0 | LQ7: 33037 | LR7: 15224 | LS7: 36685 | LT7: 41476 | LU7: 36494 | LV7: =LV6 -> 0 | LW7: =LW6 -> 0 | LX7: 53458 | LY7: 17061 | LZ7: 41069 | MA7: 41573 | MB7: 43065 | MC7: 30308 | MD7: 24845 | ME7: 12934 | MF7: 11629 | MG7: 23480 | MH7: 29813 | MI7: 19942 | MJ7: 17352 | MK7: 14926 | ML7: 9552 | MM7: 9327 | MN7: 20119 | MO7: =MO6 -> 0 | MP7: 20450 | MQ7: 24157 | MR7: 15217 | MS7: 3896 | MT7: 5769 | MU7: =MU6 -> 0 | MV7: 12018 | MW7: 20189 | MX7: 15384 | MY7: 11787 | MZ7: 4704 | NA7: 10923 | NB7: =NB6 -> 5000 | NC7: =NC6 -> 14000 | ND7: =ND6 -> 7003 | NE7: =NE6 -> 7004 | NF7: =NF6 -> 7005 | NG7: =NG6 -> 7006 | NH7: =NH6 -> 7007 | NI7: =NI6 -> 7008
A8: Forecasted Demand (Units) (-10%, -5%) | B8: =VLOOKUP(B$3,'KPI DC Forecast link file'!$B:$C,2,FALSE) -> 9573.0005 | C8: =VLOOKUP(C$3,'KPI DC Forecast link file'!$B:$C,2,FALSE) -> 9053.9953 | D8: =VLOOKUP(D$3,'KPI DC Forecast link file'!$B:$C,2,FALSE) -> 10192.991 | E8: =VLOOKUP(E$3,'KPI DC Forecast link file'!$B:$C,2,FALSE) -> 9558.0108 | F8: =VLOOKUP(F$3,'KPI DC Forecast link file'!$B:$C,2,FALSE) -> 10013.012 | G8: =VLOOKUP(G$3,'KPI DC Forecast link file'!$B:$C,2,FALSE) -> 8281.005 | H8: =VLOOKUP(H$3,'KPI DC Forecast link file'!$B:$C,2,FALSE) -> 9525.9902 | I8: =VLOOKUP(I$3,'KPI DC Forecast link file'!$B:$C,2,FALSE) -> 10301.992 | ... DL8: =VLOOKUP(DL$3,'KPI DC Forecast link file'!$B:$C,2,FALSE) -> 11481.99 | DM8: 25807 | DN8: =VLOOKUP(DN$3,'KPI DC Forecast link file'!$B:$C,2,FALSE) -> 8736.0005 | DO8: =VLOOKUP(DO$3,'KPI DC Forecast link file'!$B:$C,2,FALSE) -> 8027.0051 | DP8: =VLOOKUP(DP$3,'KPI DC Forecast link file'!$B:$C,2,FALSE) -> 9552.9973 | DQ8: =VLOOKUP(DQ$3,'KPI DC Forecast link file'!$B:$C,2,FALSE) -> 11569.985 | DR8: =VLOOKUP(DR$3,'KPI DC Forecast link file'!$B:$C,2,FALSE) -> 9930.0064 | DS8: =VLOOKUP(DS$3,'KPI DC Forecast link file'!$B:$C,2,FALSE) -> 9603.0049 | DT8: =VLOOKUP(DT$3,'KPI DC Forecast link file'!$B:$C,2,FALSE) -> 10940.009 | DU8: =VLOOKUP(DU$3,'KPI DC Forecast link file'!$B:$C,2,FALSE) -> 9732.9915 | ... KD8: =VLOOKUP(KD$3,'KPI DC Forecast link file'!$B:$C,2,FALSE) -> 34725.004 | KE8: 70000 | KF8: =VLOOKUP(KF$3,'KPI DC Forecast link file'!$B:$C,2,FALSE) -> 45970.966 | KG8: =VLOOKUP(KG$3,'KPI DC Forecast link file'!$B:$C,2,FALSE) -> 45220.008 | KH8: =VLOOKUP(KH$3,'KPI DC Forecast link file'!$B:$C,2,FALSE) -> 45042.042 | KI8: =VLOOKUP(KI$3,'KPI DC Forecast link file'!$B:$C,2,FALSE) -> 54745.996 | KJ8: =VLOOKUP(KJ$3,'KPI DC Forecast link file'!$B:$C,2,FALSE) -> 60861.968 | KK8: =KK9*0.9 -> 55757.701 | KL8: =KL9*0.9 -> 46307.718 | KM8: =KM9*0.9 -> 43779.595 | KN8: =KN9*0.9 -> 46704.602 | KO8: =KO9*0.9 -> 120007.74 | KP8: =KP9*0.9 -> 89211.665 | KQ8: =KQ9*0.9 -> 91547.122 | KR8: =KR9*0.95 -> 114192 | KS8: =KS9*0.95 -> 58873.387 | KT8: =KT9*0.95 -> 27755.233 | KU8: =KU9*0.95 -> 22942.504 | KV8: =KV9*0.95 -> 24005.559 | KW8: =KW9*0.95 -> 41797.118 | KX8: =KX9*0.95 -> 53079.376 | KY8: =KY9*0.95 -> 37449.009 | ... MC8: =MC9*0.95 -> 18021.524
A9: OPS (8/18 and earlier) or IMF Plan Forecasted (Units) | KK9: =VLOOKUP(KK$3,'KPI DC Forecast link file'!$B:$C,2,FALSE) -> 61953.002 | KL9: =VLOOKUP(KL$3,'KPI DC Forecast link file'!$B:$C,2,FALSE) -> 51453.02 | KM9: =VLOOKUP(KM$3,'KPI DC Forecast link file'!$B:$C,2,FALSE) -> 48643.994 | KN9: =VLOOKUP(KN$3,'KPI DC Forecast link file'!$B:$C,2,FALSE) -> 51894.003 | KO9: =VLOOKUP(KO$3,'KPI DC Forecast link file'!$B:$C,2,FALSE) -> 133341.93 | KP9: =VLOOKUP(KP$3,'KPI DC Forecast link file'!$B:$C,2,FALSE) -> 99124.072 | KQ9: =VLOOKUP(KQ$3,'KPI DC Forecast link file'!$B:$C,2,FALSE) -> 101719.02 | KR9: =VLOOKUP(KR$3,'KPI DC Forecast link file'!$B:$C,2,FALSE) -> 120202.1 | ... MI9: =VLOOKUP(MI$3,'KPI DC Forecast link file'!$B:$C,2,FALSE) -> 17125.981 | MJ9: 8642 | MK9: 7340 | ML9: 6831 | MM9: 13570 | MN9: 11753 | MO9: 13975 | MP9: 6845 | MQ9: 6720 | MR9: 6583 | MS9: =VLOOKUP(MS$3,'KPI DC Forecast link file'!$B:$C,2,FALSE) -> 7160.0058 | MT9: =VLOOKUP(MT$3,'KPI DC Forecast link file'!$B:$C,2,FALSE) -> 14016.017 | MU9: =VLOOKUP(MU$3,'KPI DC Forecast link file'!$B:$C,2,FALSE) -> 12686.001 | MV9: =VLOOKUP(MV$3,'KPI DC Forecast link file'!$B:$C,2,FALSE) -> 11250.992 | MW9: =VLOOKUP(MW$3,'KPI DC Forecast link file'!$B:$C,2,FALSE) -> 7592.0025 | MX9: =VLOOKUP(MX$3,'KPI DC Forecast link file'!$B:$C,2,FALSE) -> 7901.9946 | MY9: =VLOOKUP(MY$3,'KPI DC Forecast link file'!$B:$C,2,FALSE) -> 7989.9952 | MZ9: =VLOOKUP(MZ$3,'KPI DC Forecast link file'!$B:$C,2,FALSE) -> 6806.0071 | NA9: =VLOOKUP(NA$3,'KPI DC Forecast link file'!$B:$C,2,FALSE) -> 9491.001 | NB9: 9142.8571 | NC9: 9626.1161 | ND9: 9296.0778 | NE9: 9523.8095 | NF9: 9237.1882 | NG9: 9237.1882 | NH9: 9484.6129 | NI9: 9877.2919 | NJ9: 9269.8413 | NK9: 8634.9206 | NL9: 8018.1406 | NM9: 15264.929 | NN9: 13890.037 | NO9: 15833.333 | NP9: 19695.122 | NQ9: 20561.314 | NR9: 10363.42 | NS9: 9881.4003 | NT9: 9640.3906 | NU9: 9640.3906 | NV9: 10242.915 | NW9: 9640.3906 | NX9: 9037.8662 | NY9: 10228.917 | NZ9: 9753.1537 | OA9: 9681.0683 | OB9: 8823.2522 | OC9: 16775.599 | OD9: 19125.957 | OE9: 8920.5674 | OF9: 9977.3036 | OG9: 9465.647 | OH9: 9612.372 | OI9: 9833.4566 | OJ9: 18521.429
A10: Actual Demand (units) | B10: 9573 | C10: 9054 | D10: 10193 | E10: 9558 | F10: 10013 | G10: 8281 | H10: 9526 | I10: 10302 | J10: 9291 | K10: 8513 | L10: 7877 | M10: 7469 | N10: 12470 | O10: 15830 | P10: 21238 | Q10: 22466 | R10: 15059 | S10: 8439 | T10: 8328 | U10: 8725 | V10: 19159 | W10: 20170 | X10: 9668 | Y10: 9719 | Z10: 9638 | AA10: 9134 | AB10: 7652 | AC10: 15823 | AD10: 19904 | AE10: 9775 | AF10: 9722 | AG10: 9936 | AH10: 9426 | AI10: 9403 | AJ10: 11350 | AK10: 13200 | AL10: 11296 | AM10: 11571 | AN10: 11008 | AO10: 21608 | AP10: 16514 | AQ10: 19503 | AR10: 27578 | AS10: 10118 | AT10: 10277 | AU10: 10048 | AV10: 10497 | AW10: 18495 | AX10: 20618 | AY10: 28099 | AZ10: 26271 | BA10: 12777 | BB10: 11293 | BC10: 10848 | BD10: 9986 | BE10: 13163 | BF10: 14994 | BG10: 13116 | BH10: 12155 | BI10: 10845 | BJ10: 10685 | BK10: 18359 | BL10: 19228 | BM10: 21169 | BN10: 12454 | BO10: 11429 | BP10: 10649 | BQ10: 10339 | BR10: 12854 | BS10: 13024 | BT10: 15063 | BU10: 9792 | BV10: 10666 | BW10: 8703 | BX10: 7855 | BY10: 8554 | BZ10: 8579 | CA10: 10772 | CB10: 12038 | CC10: 10899 | CD10: 31154 | CE10: 23844 | CF10: 23121 | CG10: 25643 | CH10: 37112 | CI10: 21535 | CJ10: 19742 | CK10: 51723 | CL10: 33240 | CM10: 29608 | CN10: 44080 | CO10: 23459 | CP10: 29841 | CQ10: 24430 | CR10: 8759 | CS10: 8461 | CT10: =CT8 -> 12120.991 | CU10: =CU8 -> 10334.006 | CV10: =CV8 -> 12744.986 | CW10: =CW8 -> 10368.005 | CX10: 9481 | CY10: 10411 | CZ10: 9270 | DA10: 28586 | DB10: 26675 | DC10: 31045 | DD10: 21813 | DE10: 26401 | DF10: 23308 | DG10: 21023 | DH10: 39337 | DI10: 35378 | DJ10: 55150 | DK10: 52176 | DL10: 11482 | DM10: 8879 | DN10: 8736 | DO10: 8027 | DP10: 9553 | DQ10: 11570 | DR10: 9930 | DS10: 9603 | DT10: 10940 | DU10: 9733 | DV10: 9299 | DW10: 10694 | DX10: 12834 | DY10: 11291 | DZ10: 10029 | EA10: 9840 | EB10: 8573 | EC10: 8472 | ED10: 15616 | EE10: 15449 | EF10: 17205 | EG10: 10125 | EH10: 9739 | EI10: 10462 | EJ10: 9241 | EK10: 40346 | EL10: 39574 | EM10: 35723 | EN10: 24400 | EO10: 38369 | EP10: 35769 | EQ10: 43610 | ER10: 35119 | ES10: 40736 | ET10: 39888 | EU10: 28413 | EV10: 21546 | EW10: 16594 | EX10: 41201 | EY10: 37101 | EZ10: 42292 | FA10: 34914 | FB10: 48860 | FC10: 21599 | FD10: 16029 | FE10: 18397 | FF10: 16843 | FG10: 14599 | FH10: 12209 | FI10: 11112 | FJ10: 10131 | FK10: 10698 | FL10: 9917 | FM10: 9973 | FN10: 12565 | FO10: 12686 | FP10: 8943 | FQ10: 9509 | FR10: 7968 | FS10: 8211 | FT10: 16150 | FU10: 17004 | FV10: 8702 | FW10: 8553 | FX10: 9200 | FY10: 8577 | FZ10: 10384 | GA10: 10950 | GB10: 12291 | GC10: 12309 | GD10: 10177 | GE10: 10417 | GF10: 10349 | GG10: 10263 | GH10: 20209 | GI10: 21660 | GJ10: 19742 | GK10: 11651 | GL10: 11311 | GM10: 10741 | GN10: 10758 | GO10: 12233 | GP10: 13284 | GQ10: 15400 | GR10: 12969 | GS10: 16912 | GT10: 30883 | GU10: 24183 | GV10: 27246 | GW10: 34492 | GX10: 31718 | GY10: 25306 | GZ10: 27197 | HA10: 48924 | HB10: 36650 | HC10: 40199 | HD10: 58004 | HE10: 59347 | HF10: 47544 | HG10: 13478 | HH10: 11237 | HI10: 11541 | HJ10: 11145 | HK10: 16847 | HL10: 14910 | HM10: 12061 | HN10: 10054 | HO10: 14378 | HP10: 11737 | HQ10: 12496 | HR10: 18008 | HS10: 10436 | HT10: 9346 | HU10: 9613 | HV10: 17088 | HW10: 16645 | HX10: 19425 | HY10: 30600 | HZ10: 25809 | IA10: 34619 | IB10: 14074 | IC10: 13814 | ID10: 10380 | IE10: 13865 | IF10: 15839 | IG10: 16258 | IH10: 10989 | II10: 14115 | IJ10: 13407 | IK10: 12182 | IL10: 14308 | IM10: 15924 | IN10: 14263 | IO10: 50085 | IP10: 50317 | IQ10: 61734 | IR10: 53823 | IS10: 45068 | IT10: 60172 | IU10: 54064 | IV10: 45972 | IW10: 40902 | IX10: 70239 | IY10: 54344 | IZ10: 50574 | JA10: 82303 | JB10: 45536 | JC10: 39390 | JD10: 19070 | JE10: 17670 | JF10: 17414 | JG10: 20690 | JH10: 22931 | JI10: 18367 | JJ10: 17689 | JK10: 18866 | JL10: 30946 | JM10: 20217 | JN10: 47670 | JO10: 69835 | JP10: 43692 | JQ10: 20636 | JR10: 19041 | JS10: 18527 | JT10: 17773 | JU10: 35046 | JV10: 48673 | JW10: 25085 | JX10: 24475 | JY10: 21447 | JZ10: 35712 | KA10: 30718 | KB10: 43709 | KC10: 51402 | KD10: 34725 | KE10: 60712 | KF10: 45971 | KG10: 45220 | KH10: 45042 | KI10: 54746 | KJ10: 60862 | KK10: 61953 | KL10: 51453 | KM10: 48644 | KN10: 51894 | KO10: 133342 | KP10: 99124 | KQ10: 101719 | KR10: 120202 | KS10: 61972 | KT10: 29216 | KU10: 24150 | KV10: 25268 | KW10: 43997 | KX10: 55873 | KY10: 39420 | KZ10: 35057 | LA10: 27275 | LB10: 25554 | LC10: 25315 | LD10: 35249 | LE10: 40610 | LF10: 31482 | LG10: 39464 | LH10: 20218 | LI10: 17530 | LJ10: 16483 | LK10: 12551 | LL10: 12492 | LM10: 9279 | LN10: 7040 | LO10: 6267 | LP10: 9414 | LQ10: 36275 | LR10: 26791 | LS10: 59685 | LT10: 39564 | LU10: 34935 | LV10: 23802 | LW10: 27085 | LX10: 27297 | LY10: 29387 | LZ10: 29609 | MA10: 27607 | MB10: 22560 | MC10: 18970 | MD10: 16746 | ME10: 19696 | MF10: 19173 | MG10: 22302 | MH10: 14931 | MI10: 17126 | MJ10: 10822 | MK10: 11141 | ML10: 9171 | MM10: 20170 | MN10: 20033 | MO10: 19521 | MP10: 7570 | MQ10: 7888 | MR10: 6678 | MS10: 7160 | MT10: 14016 | MU10: 12686 | MV10: 11251 | MW10: 7592 | MX10: 7902 | MY10: 7990 | MZ10: =MZ9 -> 6806.0071 | NA10: =NA9 -> 9491.001 | NB10: =NB9 -> 9142.8571 | NC10: =NC9 -> 9626.1161 | ND10: =ND9 -> 9296.0778 | NE10: =NE9 -> 9523.8095 | NF10: =NF9 -> 9237.1882 | NG10: =NG9 -> 9237.1882 | ... NI10: =NI9 -> 9877.2919
A11: Percentage demand vs. forecast | B11: =IFERROR(B10/B8,0) -> 0.99999994 | C11: =IFERROR(C10/C8,0) -> 1.0000005 | D11: =IFERROR(D10/D8,0) -> 1.0000009 | E11: =IFERROR(E10/E8,0) -> 0.99999887 | F11: =IFERROR(F10/F8,0) -> 0.99999879 | G11: =IFERROR(G10/G8,0) -> 0.9999994 | H11: =IFERROR(H10/H8,0) -> 1.000001 | I11: =IFERROR(I10/I8,0) -> 1.0000007 | ... KJ11: =IFERROR(KJ10/KJ8,0) -> 1.0000005 | KK11: =IFERROR(KK10/KK9,0) -> 0.99999998 | KL11: =IFERROR(KL10/KL9,0) -> 0.99999961 | KM11: =IFERROR(KM10/KM9,0) -> 1.0000001 | KN11: =IFERROR(KN10/KN9,0) -> 0.99999995 | KO11: =IFERROR(KO10/KO9,0) -> 1.0000005 | KP11: =IFERROR(KP10/KP9,0) -> 0.99999927 | KQ11: =IFERROR(KQ10/KQ9,0) -> 0.99999976 | KR11: =IFERROR(KR10/KR9,0) -> 0.99999915 | ... NI11: =IFERROR(NI10/NI9,0) -> 1
A12: Shipped Shipments | B12: 2092 | C12: 2448 | D12: 2924 | E12: 2527 | F12: 2656 | G12: 1452 | H12: 1677 | I12: 3704 | J12: 2869 | K12: 2220 | L12: 2194 | M12: 1721 | N12: 1832 | O12: 2195 | P12: 4875 | Q12: 6419 | R12: 4585 | S12: 0 | T12: 4600 | U12: 1999 | V12: 2165 | W12: 4806 | X12: 5019 | Y12: 2607 | Z12: 2572 | AA12: 2531 | AB12: 1309 | AC12: 1875 | AD12: 4298 | AE12: 5563 | AF12: 2727 | AG12: 2429 | AH12: 2653 | AI12: 1394 | AJ12: 2259 | AK12: 4418 | AL12: 3115 | AM12: 3044 | AN12: 3070 | AO12: 2937 | AP12: 2643 | AQ12: 3152 | AR12: 5570 | AS12: 6292 | AT12: 3305 | AU12: 3379 | AV12: 2567 | AW12: 1741 | AX12: 3563 | AY12: 4657 | AZ12: 6160 | BA12: 4529 | BB12: 4580 | BC12: 4283 | BD12: 1836 | BE12: 2557 | BF12: 3714 | BG12: 4889 | BH12: 3456 | BI12: 2245 | BJ12: 3262 | BK12: 2126 | BL12: 3436 | BM12: 4671 | BN12: 5626 | BO12: 4106 | BP12: 3825 | BQ12: 3165 | BR12: 1485 | BS12: 3100 | BT12: 3996 | BU12: 4107 | BV12: 2865 | BW12: 2628 | BX12: 2209 | BY12: 1077 | BZ12: 2200 | CA12: 0 | CB12: 5807 | CC12: 2680 | CD12: 3871 | CE12: 5505 | CF12: 5748 | CG12: 2839 | CH12: 5251 | CI12: 7214 | CJ12: 4666 | CK12: 4371 | CL12: 6397 | CM12: 4253 | CN12: 3094 | CO12: 5584 | CP12: 7247 | CQ12: 5974 | CR12: 5532 | CS12: 4483 | CT12: 3473 | CU12: 3841 | CW12: 6266 | CX12: 3568 | CY12: 3128 | CZ12: 2771 | DA12: 2584 | DB12: 3235 | DC12: 4283 | DD12: 5598 | DE12: 5270 | DF12: 4055 | DG12: 4760 | DH12: 3643 | DI12: 4205 | DJ12: 5105 | DK12: 7267 | DL12: 6500 | DM12: 6506 | DN12: 5281 | DO12: 3659 | DP12: 3624 | DQ12: 5398 | DR12: 3915 | DS12: 3149 | DT12: 2359 | DU12: 2536 | DV12: 1837 | DW12: 1887 | DX12: 4252 | DY12: 2959 | DZ12: 2900 | EA12: 2391 | EB12: 2570 | EC12: 1514 | ED12: 2328 | EF12: 5835 | EG12: 4114 | EH12: 3941 | EI12: 2750 | EJ12: 1588 | EK12: 2080 | EL12: 5757 | EM12: 7574 | EN12: 4659 | EO12: 5253 | EP12: 4722 | EQ12: 3970 | ER12: 3829 | ES12: 5813 | ET12: 8068 | EU12: 6807 | EV12: 5303 | EW12: 6232 | EX12: 6424 | EY12: 4776 | EZ12: 5769 | FA12: 7053 | FB12: 6181 | FC12: 5157 | FD12: 4443 | FE12: 3975 | FF12: 3895 | FG12: 5327 | FH12: 5645 | FI12: 5397 | FJ12: 4177 | FK12: 3769 | FL12: 1925 | FM12: 2443 | FN12: 4582 | FO12: 2791 | FP12: 2787 | FQ12: 2423 | FR12: 2323 | FS12: 1143 | FT12: 1964 | FU12: 4218 | FV12: 3683 | FW12: 2144 | FX12: 2692 | FY12: 2298 | FZ12: 1220 | GA12: 2091 | GB12: 4423 | GC12: 2803 | GD12: 2759 | GE12: 2442 | GF12: 2298 | GG12: 1694 | GH12: 2245 | GI12: 5629 | GJ12: 4773 | GK12: 3644 | GL12: 3072 | GM12: 2648 | GN12: 1960 | GO12: 2485 | GP12: 5004 | GQ12: 3520 | GR12: 3350 | GS12: 3523 | GT12: 4303 | GU12: 3193 | GV12: 3616 | GW12: 6409 | GX12: 6624 | GY12: 5887 | GZ12: 4787 | HA12: 6180 | HB12: 7386 | HC12: 2820 | HD12: 7960 | HE12: 7983 | HF12: 7457 | HG12: 6585 | HH12: 6450 | HI12: 5140 | HJ12: 4544 | HK12: 7611 | HL12: 7570 | HM12: 5026 | HN12: 4625 | HO12: 3851 | HP12: 2738 | HQ12: 3064 | HR12: 4842 | HS12: 4089 | HT12: 2798 | HU12: 2868 | HV12: 3629 | HW12: 1986 | HX12: 3210 | HY12: 7386 | HZ12: 5181 | IA12: 5332 | IB12: 5201 | IC12: 5378 | ID12: 3057 | IE12: 3915 | IF12: 5999 | IG12: 4882 | IH12: 4193 | II12: 3472 | IJ12: 4239 | IK12: 1792 | IL12: 3876 | IM12: 3961 | IN12: 5509 | IO12: 7017 | IP12: 7575 | IQ12: 7941 | IR12: 12736 | IS12: 5161 | IT12: 8876 | IU12: 13223 | IV12: 10427 | IW12: 10779 | IX12: 11724 | IY12: 9614 | IZ12: 5456 | JA12: 12884 | JB12: 13492 | JC12: 13891 | JD12: 11045 | JE12: 13612 | JF12: 16357 | JG12: 11133 | JH12: 10423 | JI12: 6812 | JJ12: 5182 | JK12: 3950 | JL12: 7045 | JM12: 5073 | JN12: 6056 | JO12: 8534 | JP12: 13176 | JQ12: 11093 | JR12: 10575 | JS12: 9002 | JT12: 5011 | JU12: 6174 | JV12: 9513 | JW12: 12318 | JX12: 8897 | JY12: 7968 | JZ12: 7704 | KA12: 5107 | KB12: 4525 | KC12: 13965 | KD12: 17923 | KE12: 12949 | KF12: 14832 | KG12: 13748 | KH12: 9253 | KI12: 6833 | KJ12: 20263 | KK12: 17061 | KL12: 14931 | KM12: 12488 | KN12: 0 | KO12: 21270 | KP12: 21804 | KQ12: 20543 | KR12: 18755 | KS12: 18836 | KT12: 17303 | KU12: 15581 | KV12: 13317 | KW12: 11753 | KX12: 14014 | KY12: 16593 | KZ12: 13094 | LA12: 12273 | LB12: 9238 | LC12: 4275 | LD12: 8526 | LE12: 11094 | LF12: 14811 | LG12: 14315 | LH12: 14225 | LI12: 5224 | LJ12: 4314 | LK12: 4162 | LL12: 5519 | LM12: 3339 | LN12: 2550 | LQ12: 8827 | LR12: 4072 | LS12: 7850 | LT12: 8176 | LU12: 6800 | LV12: 0 | LW12: 0 | LX12: 11515 | LY12: 3610 | LZ12: 8708 | MA12: 8568 | MB12: 9044 | MC12: 7085 | MD12: 5258 | ME12: 2530 | MF12: 2548 | MG12: 5701 | MH12: 6637 | MI12: 5472 | MJ12: 4080 | MK12: 3603 | ML12: 2604 | MM12: 2908 | MN12: 4710 | MO12: 0 | MP12: 4702 | MQ12: 5875 | MR12: 4357 | MS12: 1117 | MT12: 1743 | MU12: 0 | MV12: 3131 | MW12: 4947 | MX12: 3982 | MY12: 3462 | MZ12: 1313 | NA12: 3181
A13: UPT | B13: =IFERROR(B7/B12,0) -> 3.6806883 | C13: =IFERROR(C7/C12,0) -> 4.2990196 | D13: =IFERROR(D7/D12,0) -> 3.6932285 | E13: =IFERROR(E7/E12,0) -> 3.767313 | F13: =IFERROR(F7/F12,0) -> 3.9420181 | G13: =IFERROR(G7/G12,0) -> 3.9035813 | H13: =IFERROR(H7/H12,0) -> 3.53548 | I13: =IFERROR(I7/I12,0) -> 4.0345572 | ... NI13: =IFERROR(NI7/NI12,0) -> 0
A14: AB Utilization | B14: 0.8317 | C14: 0.8462 | D14: 0.8426 | E14: 0.7901 | F14: 0.8312 | G14: 0.8111 | H14: 0.8667 | I14: 0.8208 | J14: 0.8801 | K14: 0.8246 | L14: 0.8601 | M14: 0.8383 | N14: 0.84 | O14: 0.8063 | P14: 0.7739 | Q14: 0.8675 | R14: 0.8374 | S14: 0 | T14: 0.8227 | U14: 0.8433 | V14: 0.8689 | W14: 0.735 | X14: 0.8231 | Y14: 0.8754 | Z14: 0.8608 | AA14: 0.8557 | AB14: 0.8276 | AC14: 0.8434 | AD14: 0.8029 | AE14: 0.8916 | AF14: 0.8667 | AG14: 0.8661 | AH14: 0.7798 | AI14: 0.839 | AJ14: 0.9276 | AK14: 0.9328 | AL14: 0.887 | AM14: 0.8836 | AN14: 0.8613 | AO14: 0.8658 | AP14: 0.9196 | AQ14: 0.9145 | AR14: 0.8735 | AS14: 0.8836 | AT14: 0.8625 | AU14: 0.9125 | AV14: 0.9025 | AW14: 0.8958 | AX14: 0.8736 | AY14: 0.8825 | AZ14: 0.8725 | BA14: 0.9025 | BB14: 0.8836 | BC14: 0.8432 | BD14: 0.8825 | BE14: 0.8936 | BF14: 0.9015 | BG14: 0.9028 | BH14: 0.7958 | BI14: 0.8958 | BJ14: 0.8852 | BK14: 0.8752 | BL14: 0.8552 | BM14: 0.7798 | BN14: 0.839 | BO14: 0.9276 | BP14: 0.9328 | BQ14: 0.887 | BR14: 0.8836 | BS14: 0.8613 | BT14: 0.8658 | BU14: 0.9196 | BV14: 0.9145 | BW14: 0.8735 | BX14: 0.8908 | BY14: 0.8573 | BZ14: 0.884 | CA14: 0 | CB14: 0.8868 | CC14: 0.8905 | CD14: 0.864 | CE14: 0.85 | CF14: 0.8887 | CG14: 0.8405 | CH14: 0.7734 | CI14: 0.8546 | CJ14: 0.8941 | CK14: 0.8314 | CL14: 0.8271 | CM14: 0.7253 | CN14: 0.8866 | CO14: 0.878 | CP14: 0.8337 | CQ14: 0.8738 | CR14: 0.8598 | CS14: 0.7949 | CT14: 0.9461 | CU14: 0.8149 | CV14: 0 | CW14: 0.8756 | CX14: 0.8933 | CY14: 0.9398 | CZ14: 0.9013 | DA14: 0.8551 | DB14: 0.8632 | DC14: 0.774 | DD14: 0.9047 | DE14: 0.8744 | DF14: 0.782 | DG14: 0.8968 | DH14: 0.7995 | DI14: 0.7579 | DJ14: 0.8639 | DK14: 0.826 | DL14: 0.8791 | DM14: 0.7922 | DN14: 0.9079 | DO14: 0.8885 | DP14: 0.9201 | DQ14: 0.8519 | DR14: 0.7898 | DS14: 0.9216 | DT14: 0.9126 | DU14: 0.9129 | DV14: 0.8756 | DW14: 0.8799 | DX14: 0.8865 | DY14: 0.8797 | DZ14: 0.722 | EA14: 0.8909 | EB14: 0.9441 | EC14: 0.8978 | ED14: 0.8963 | EF14: 0.896 | EG14: 0.8521 | EH14: 0.9545 | EI14: 0.9069 | EJ14: 0.7468 | EK14: 0.8963 | EL14: 0.7817 | EM14: 0.8513 | EN14: 0.7725 | EO14: 0.9134 | EP14: 0.805 | EQ14: 0.8161 | ER14: 0.7824 | ES14: 0.6963 | ET14: 0.7597 | EU14: 0.7427 | EV14: 0.757 | EW14: 0.6809 | EX14: 0.7508 | EY14: 0.788 | EZ14: 0.581 | FA14: 0.6327 | FB14: 0.713 | FC14: 0.7814 | FD14: 0.7167 | FE14: 0.6817 | FF14: 0.7608 | FG14: 0.7652 | FH14: 0.8696 | FI14: 0.9012 | FJ14: 0.9188 | FK14: 0.885 | FL14: 0.8357 | FM14: 0.8728 | FN14: 0.8837 | FO14: 0.8805 | FP14: 0.8623 | FQ14: 0.8835 | FR14: 0.8929 | FS14: 0.8601 | FT14: 0.8486 | FU14: 0.8414 | FV14: 0.8663 | FW14: 0.863 | FX14: 0.8539 | FY14: 0.8405 | FZ14: 0.7946 | GA14: 0.6544 | GB14: 0.7784 | GC14: 0.8059 | GD14: 0.8407 | GE14: 0.8447 | GF14: 0.8495 | GG14: 0.8711 | GH14: 0.8492 | GI14: 0.7734 | GJ14: 0.8416 | GK14: 0.7921 | GL14: 0.8898 | GM14: 0.857 | GN14: 0.8774 | GO14: 0.6969 | GP14: 0.828 | GQ14: 0.8494 | GR14: 0.8666 | GS14: 0.8402 | GT14: 0.8208 | GU14: 0.8094 | GV14: 0.8766 | GW14: 0.7295 | GX14: 0.8162 | GY14: 0.795 | GZ14: 0.7748 | HA14: 0.8203 | HB14: 0.8391 | HC14: 0.58 | HD14: 0.8452 | HE14: 0.7913 | HF14: 0.7642 | HG14: 0.7743 | HH14: 0.7944 | HI14: 0.7487 | HJ14: 0.8774 | HK14: 0.7438 | HL14: 0.8711 | HM14: 0.8434 | HN14: 0.8332 | HO14: 0.8109 | HP14: 0.8518 | HQ14: 0.8097 | HR14: 0.8496 | HS14: 0.8249 | HT14: 0.8441 | HU14: 0.8191 | HV14: 0.8613 | HW14: 0.8053 | HX14: 0.789 | HY14: 0.8416 | HZ14: 0.8104 | IA14: 0.8302 | IB14: 0.7887 | IC14: 0.7645 | ID14: 0.7622 | IE14: 0.7828 | IF14: 0.8319 | IG14: 0.787 | IH14: 0.8232 | II14: 0.8095 | IJ14: 0.7899 | IK14: 0.7419 | IL14: 0.8347 | IM14: 0.7524 | IN14: 0.7862 | IO14: 0.7523 | IP14: 0.7286 | IQ14: 0.7329 | IR14: 0.662 | IS14: 0.6057 | IT14: 0.7119 | IU14: 0.7423 | IV14: 0.7319 | IW14: 0.6606 | IX14: 0.6826 | IY14: 0.6792 | IZ14: 0.6067 | JA14: 0.739 | JB14: 0.6795 | JC14: 0.67 | JD14: 0.6236 | JE14: 0.666 | JF14: 0.6538 | JG14: 0.7384 | JH14: 0.7975 | JI14: 0.7077 | JJ14: 0.6682 | JK14: 0.7231 | JL14: 0.7638 | JM14: 0.6579 | JN14: 0.7472 | JO14: 0.7075 | JP14: 0.6365 | JQ14: 0.689 | JR14: 0.675 | JS14: 0.692 | JT14: 0.6885 | JU14: 0.5959 | JV14: 0.5247 | JW14: 0.6839 | JX14: 0.7081 | JY14: 0.5486 | JZ14: 0.6541 | KA14: 0.6121 | KB14: 0.638 | KC14: 0.747 | KD14: 0.5118 | KE14: 0.5552 | KF14: 0.5741 | KG14: 0.6239 | KH14: 0.6317 | KI14: 0.5798 | KJ14: 0.6484 | KK14: 0.5833 | KL14: 0.7231 | KM14: 0.7528 | KN14: 0.9535 | KO14: 0.6226 | KP14: 0.7122 | KQ14: 0.7015 | KR14: 0.619 | KS14: 0.6726 | KT14: 0.6512 | KU14: 0.609 | KV14: 0.7413 | KW14: 0.6686 | KX14: 0.7318 | KY14: 0.6267 | KZ14: 0.5743 | LA14: 0.6314 | LB14: 0.592 | LC14: 0.7577 | LD14: 0.7408 | LE14: 0.7088 | LF14: 0.6539 | LG14: 0.6901 | LH14: 0.6681 | LI14: 0.6311 | LJ14: 0.605 | LK14: 0.7823 | LL14: 0.7573 | LM14: 0.7894 | LN14: 0.814 | LQ14: 0.7375 | LR14: 0.6862 | LS14: 0.8325 | LT14: 0.7025 | LU14: 0.3437 | LX14: 0.6877 | LY14: 0.6874 | LZ14: 0.7278 | MA14: 0.7076 | MB14: 0.7918 | MC14: 0.8338 | MD14: 0.7539 | ME14: 0.6613 | MF14: 0.8407 | MG14: 0.71 | MH14: 0.663 | MI14: 0.8615 | MJ14: 0.8317 | MK14: 0.8277 | ML14: 0.8492 | MM14: 0.6981 | MN14: 0.7891 | MO14: 0.9444 | MP14: 0.8377 | MQ14: 0.8422 | MR14: 0.8916 | MS14: 0.8725 | MT14: 0.8022 | MW14: 0.8055 | MX14: 0.8515 | MY14: 0.9098 | MZ14: 0.8298 | NA14: 0.8749 | NB14: 0.8926 | NC14: 0.8862 | ND14: 0.8909 | NE14: 0.8964 | NF14: 0.8184 | NG14: 0.8767 | NH14: 0.8462 | NI14: 0.8979
A15: Out of 48 | B15: 0 | C15: 0 | D15: =MAX(0,D5-C10-B10) -> 0 | E15: =MAX(0,E5-D10-C10) -> 0 | F15: =MAX(0,F5-E10-D10) -> 0 | G15: =MAX(0,G5-F10-E10) -> 0 | H15: =MAX(0,H5-G10-F10) -> 0 | I15: =MAX(0,I5-H10-G10) -> 0 | J15: =MAX(0,J5-I10-H10) -> 0 | K15: =MAX(0,K5-J10-I10) -> 0 | ... NI15: =MAX(0,NI5-NH10-NG10) -> 0
A16: Out of 72 | B16: 0 | C16: 0 | D16: 0 | E16: =MAX(0,E5-D10-C10-B10) -> 0 | F16: =MAX(0,F5-E10-D10-C10) -> 0 | G16: =MAX(0,G5-F10-E10-D10) -> 0 | H16: =MAX(0,H5-G10-F10-E10) -> 0 | I16: =MAX(0,I5-H10-G10-F10) -> 0 | J16: =MAX(0,J5-I10-H10-G10) -> 0 | K16: =MAX(0,K5-J10-I10-H10) -> 0 | L16: =MAX(0,L5-K10-J10-I10) -> 0 | ... NI16: =MAX(0,NI5-NH10-NG10-NF10) -> 0
A17: Out of 96 | B17: 0 | C17: 0 | D17: 0 | E17: 0 | F17: =MAX(0,F5-E10-D10-C10-B10) -> 0 | G17: =MAX(0,G5-F10-E10-D10-C10) -> 0 | H17: =MAX(0,H5-G10-F10-E10-D10) -> 0 | I17: =MAX(0,I5-H10-G10-F10-E10) -> 0 | J17: =MAX(0,J5-I10-H10-G10-F10) -> 0 | K17: =MAX(0,K5-J10-I10-H10-G10) -> 0 | L17: =MAX(0,L5-K10-J10-I10-H10) -> 0 | M17: =MAX(0,M5-L10-K10-J10-I10) -> 0 | ... NI17: =MAX(0,NI5-NH10-NG10-NF10-NE10) -> 0
A18: Out of 120 | B18: 0 | C18: 0 | D18: 0 | E18: 0 | F18: 0 | G18: =MAX(0,G5-F10-E10-D10-C10-B10) -> 0 | H18: =MAX(0,H5-G10-F10-E10-D10-C10) -> 0 | I18: =MAX(0,I5-H10-G10-F10-E10-D10) -> 0 | J18: =MAX(0,J5-I10-H10-G10-F10-E10) -> 0 | K18: =MAX(0,K5-J10-I10-H10-G10-F10) -> 0 | L18: =MAX(0,L5-K10-J10-I10-H10-G10) -> 0 | M18: =MAX(0,M5-L10-K10-J10-I10-H10) -> 0 | N18: =MAX(0,N5-M10-L10-K10-J10-I10) -> 0 | ... NI18: =MAX(0,NI5-NH10-NG10-NF10-NE10-ND10) -> 0
A19: Out of 144 | B19: 0 | C19: 0 | D19: 0 | E19: 0 | F19: 0 | G19: 0 | H19: =MAX(0,H5-G10-F10-E10-D10-C10-B10) -> 0 | I19: =MAX(0,I5-H10-G10-F10-E10-D10-C10) -> 0 | J19: =MAX(0,J5-I10-H10-G10-F10-E10-D10) -> 0 | K19: =MAX(0,K5-J10-I10-H10-G10-F10-E10) -> 0 | L19: =MAX(0,L5-K10-J10-I10-H10-G10-F10) -> 0 | M19: =MAX(0,M5-L10-K10-J10-I10-H10-G10) -> 0 | N19: =MAX(0,N5-M10-L10-K10-J10-I10-H10) -> 0 | O19: =MAX(0,O5-N10-M10-L10-K10-J10-I10) -> 0 | ... NI19: =MAX(0,NI5-NH10-NG10-NF10-NE10-ND10-NC10) -> 0
A21: Labor Planning
A22: FTE Needed | B22: ='Deployment needs'!C3 -> 22.044208 | C22: ='Deployment needs'!D3 -> 26.831822 | D22: ='Deployment needs'!E3 -> 27.069882 | E22: ='Deployment needs'!F3 -> 28.5286 | F22: ='Deployment needs'!G3 -> 27.04792 | G22: ='Deployment needs'!H3 -> 19.707296 | H22: ='Deployment needs'!I3 -> 22.676197 | I22: ='Deployment needs'!J3 -> 40.382362 | ... NI22: ='Deployment needs'!NJ3 -> 0
A23: Base FTE | B23: 39.25 | C23: 52.75 | D23: 42.75 | E23: 42.75 | F23: 42.75 | G23: 16.75 | H23: 17.25 | I23: 39.25 | J23: 52.75 | K23: 42.75 | L23: 42.75 | M23: 42.75 | N23: 16.75 | O23: 17.25 | P23: 39.25 | Q23: 52.75 | R23: 42.75 | S23: 42.75 | T23: 42.75 | U23: 16.75 | V23: 17.25 | DA23: 16.75 | DB23: 17.25 | DC23: 39.25 | DD23: 52.75 | DE23: 42.75 | DF23: 42.75 | DG23: 42.75 | DH23: 17.5 | DI23: 18 | DJ23: 40 | DK23: 52.75 | DL23: 42.75 | DM23: 42.75 | DN23: 42.75 | DO23: 17.5 | DP23: 18 | DQ23: 40 | DR23: 52.75 | DS23: 42.75 | DT23: 42.75 | DU23: 42.75 | DV23: 17.5 | DW23: 18 | DX23: 40 | DY23: 52.75 | DZ23: 42.75 | EA23: 42.75 | EB23: 42.75 | EC23: 17.5 | ED23: 18 | EE23: 40 | EF23: 52.75 | EG23: 42.75 | EH23: 42.75 | EI23: 42.75 | EJ23: 17.5 | EK23: 18 | EL23: 40 | EM23: 52.75 | EN23: 42.75 | EO23: 42.75 | EP23: 42.75 | EQ23: 17.5 | ER23: 18 | ES23: 40 | ET23: 52.75 | EU23: 42.75 | EV23: 42.75 | EW23: 42.75 | EX23: 17.5 | EY23: 18 | EZ23: 40 | FA23: 52.75 | FB23: 42.75 | FC23: 42.75 | FD23: 42.75 | FE23: 17.5 | FF23: 18 | FG23: 40 | FH23: 52.75 | FI23: 42.75 | FJ23: 42.75 | FK23: 42.75 | FL23: 17.5 | FM23: 18 | FN23: 40 | FO23: 52.75 | FP23: 42.75 | FQ23: 42.75 | FR23: 42.75 | FS23: 20.5 | FT23: 21 | FU23: 49 | FV23: 58.75 | FW23: 48.75 | FX23: 48.75 | FY23: 48.75 | FZ23: 20.5 | GA23: 21 | GB23: 49 | GC23: 58.75 | GD23: 48.75 | GE23: 48.75 | GF23: 48.75 | GG23: 24.25 | GH23: 24.75 | GI23: 56.75 | GJ23: 61.75 | GK23: 51.75 | GL23: 51.75 | GM23: 51.75 | GN23: 24 | GO23: 24.5 | GP23: 54.5 | GQ23: 62.75 | GR23: 53.75 | GS23: 53.75 | GT23: 53.75 | GU23: 23.25 | GV23: 23.75 | GW23: 56.75 | GX23: 62.75 | GY23: 55.75 | GZ23: 55.75 | HA23: 54.75 | HB23: 26.25 | HC23: 26.75 | HD23: 56.75 | HE23: 62.75 | HF23: 55.75 | HG23: 55.75 | HH23: 54.75 | HI23: 26.25 | HJ23: 26.75 | HK23: 62.25 | HL23: 90 | HM23: 59.75 | HN23: 59.75 | HO23: 59.75 | HP23: 30.25 | HQ23: 30.25 | HR23: 66.25 | HS23: 95 | HT23: 61.75 | HU23: 61.75 | HV23: 61.75 | HW23: 33.25 | HX23: 33.25 | HY23: 73.25 | HZ23: 105 | IA23: 68.75 | IB23: 68.75 | IC23: 68.75 | ID23: 36.25 | IE23: 36.25 | IF23: 79.25 | IG23: 115 | IH23: 75.75 | II23: 75.75 | IJ23: 75.75 | IK23: 39.25 | IL23: 39.25 | IM23: 42.25 | IN23: 87.25 | IO23: 88.75 | IP23: 88.75 | IQ23: 88.75 | IR23: 128.5 | IS23: 40.25 | IT23: 82.25 | IU23: 113 | IV23: 101.75 | IW23: 97 | IX23: 97 | IY23: 40.25 | IZ23: 40.25 | JA23: 81.25 | JB23: 116.75 | JC23: 97.75 | JD23: 97.75 | JE23: 97.75 | JF23: 40.25 | JG23: 40.25 | JH23: 82.25 | JI23: 110 | JJ23: 122.75 | JK23: 122.75 | JL23: 122.75 | JM23: 42.25 | JN23: 42.25 | JO23: 109.25 | JP23: 155 | JQ23: 132.75 | JR23: 132.75 | JS23: 132.75 | JT23: 42.25 | JU23: 42.25 | JV23: 112.25 | JW23: 180 | JX23: 137.75 | JY23: 137.75 | JZ23: 137.75 | KA23: 42.25 | KB23: 42.25 | KC23: 112.25 | KD23: 145 | KE23: 137.75 | KF23: 137.75 | KG23: 137.75 | KH23: 42.25 | KI23: 42.25 | KJ23: 112.25 | KK23: 145 | KL23: 145 | KM23: 145 | KN23: 0 | KO23: 170 | KP23: 170 | KQ23: 180 | KR23: 164 | KS23: 164 | KT23: 164 | KU23: 129 | KV23: 109 | KW23: 102 | KX23: 120 | KY23: 142 | KZ23: 132 | LA23: 132 | LB23: 132 | LC23: 50 | LD23: 51 | LE23: 94.75 | LF23: 115 | LG23: 105 | LH23: 105 | LI23: 125 | LJ23: 47 | LK23: 48 | LL23: 109 | LM23: 130 | LN23: 123 | LO23: 123 | LP23: 123 | LQ23: 44 | LR23: 41 | LS23: 104 | LT23: 120 | LU23: 113 | LV23: 113 | LW23: 113 | LX23: 131 | LY23: 60 | LZ23: 82.75 | MA23: 110 | MB23: 113 | MC23: 113 | MD23: 113 | ME23: 29 | MF23: 29 | MG23: 61.75 | MH23: 75 | MI23: 52 | MJ23: 52 | MK23: 52 | ML23: 23 | MM23: 23 | MN23: 47 | MO23: 70 | MP23: 47 | MQ23: 47 | MR23: 47 | MS23: 23 | MT23: 23 | MU23: 43 | MV23: 65 | MW23: 45 | MX23: 45 | MY23: 45 | MZ23: 20 | NA23: 20 | NB23: 21 | NC23: 22 | ND23: 23 | NE23: 24 | NF23: 25 | NG23: 26 | NH23: 27 | NI23: 28
A24: FTE w/ full OT | IU24: 0 | IV24: 0 | IW24: 0 | IX24: 16 | IY24: 55.75 | IZ24: 0 | JA24: 0 | JB24: 0 | JC24: 16 | JD24: 0 | JE24: 20 | JF24: 97.75 | JG24: 55.75 | JH24: 0 | JI24: 0 | JJ24: 0 | JK24: 0 | JL24: 0 | JM24: 0 | JN24: 0 | JO24: 0 | KH24: 40 | KJ24: 55 | KK24: 10 | KL24: 10 | KM24: 10 | KX24: 0 | KY24: 0 | KZ24: 0 | LA24: 0 | LB24: 0 | LC24: 0 | LD24: 0 | LE24: 0 | LF24: 7 | LG24: 0 | LH24: 0 | LI24: 0 | LJ24: 0 | LK24: 0 | LL24: 0 | LM24: 0 | LN24: 0 | LO24: 0 | LP24: 0 | LQ24: 0 | LR24: 0
A25: Sum | IP25: =SUM(IP23:IP28) -> 99.75 | IQ25: =SUM(IQ23:IQ28) -> 99.75 | IR25: =SUM(IR23:IR28) -> 139.5 | IS25: =SUM(IS23:IS28) -> 44.25 | IT25: =SUM(IT23:IT28) -> 90.25 | IU25: =SUM(IU23:IU28) -> 128 | IV25: =SUM(IV23:IV28) -> 112.75 | IW25: =SUM(IW23:IW28) -> 108 | ... KG25: =SUM(KG23:KG28) -> 137.75 | KH25: =SUM(KH23:KH24) -> 82.25 | KI25: =SUM(KI23:KI24) -> 42.25 | KJ25: =SUM(KJ23:KJ24) -> 167.25 | KK25: =SUM(KK23:KK24) -> 155 | KL25: =SUM(KL23:KL24) -> 155 | KM25: =SUM(KM23:KM24) -> 155 | KN25: =SUM(KN23:KN24) -> 0 | KO25: =SUM(KO23:KO24) -> 170 | ... NI25: =SUM(NI23:NI24) -> 28
A26: Sum - 5% attendance | KK26: =KK25*0.9 -> 139.5 | KL26: =KL25*0.9 -> 139.5 | KM26: =KM25*0.9 -> 139.5 | KN26: =KN25*0.9 -> 0 | KO26: =KO25*0.9 -> 153 | KP26: =KP25*0.9 -> 153 | KQ26: =KQ25*0.9 -> 162 | KR26: =KR25*0.9 -> 147.6 | KS26: =KS25*0.9 -> 147.6 | KT26: =KT25*0.95 -> 155.8 | KU26: =KU25*0.95 -> 122.55 | KV26: =KV25*0.95 -> 103.55 | KW26: =KW25*0.95 -> 96.9 | KX26: =KX25*0.95 -> 114 | KY26: =KY25*0.95 -> 134.9 | KZ26: =KZ25*0.95 -> 125.4 | LA26: =LA25*0.95 -> 125.4 | ... NI26: =NI25*0.95 -> 26.6
A27: Difference | B27: =B23-B22 -> 17.205792 | C27: =C23-C22 -> 25.918178 | D27: =D23-D22 -> 15.680118 | E27: =E23-E22 -> 14.2214 | F27: =F23-F22 -> 15.70208 | G27: =G23-G22 -> -2.9572956 | H27: =H23-H22 -> -5.4261966 | I27: =I23-I22 -> -1.132362 | ... IO27: =IO23-IO22 -> 11.334084 | IP27: =IP25-IP22 -> 8.2552017 | IQ27: =IQ23-IQ22 -> -4.8426101 | IR27: =IR23-IR22 -> 1.6306088 | IS27: =IS23-IS22 -> -0.39252844 | IT27: =IT23-IT22 -> -13.037332 | IU27: =IU23-IU22 -> -19.387057 | IV27: =IV23-IV22 -> -9.2571744 | IW27: =IW23-IW22 -> -14.862307 | IX27: =IX23-IX22 -> -30.297484 | ... JB27: =JB23-JB22 -> -8.6611571 | JC27: =JC23+JC24-JC22 -> -15.510266 | JD27: =JD23+JD24-JD22 -> -23.705523 | JE27: =JE23+JE24-JE22 -> -11.207872 | JF27: =JF23+JF24-JF22 -> 7.8605921 | JG27: =JG23+JG24-JG22 -> 27.428448 | JH27: =JH23+JH24-JH22 -> -3.1715358 | JI27: =JI23+JI24-JI22 -> 32.654926 | JJ27: =JJ23+JJ24-JJ22 -> 60.796828 | ... KJ27: =KJ23+KJ24-KJ22 -> 11.971192 | KK27: =KK26-KK22 -> 4.5365341 | KL27: =KL26-KL22 -> 19.849512 | KM27: =KM26-KM22 -> 32.098442 | KN27: =KN26-KN22 -> -92.937652 | KO27: =KO26-KO22 -> -3.592798 | KP27: =KP26-KP22 -> 2.2543589 | KQ27: =KQ26-KQ22 -> -14.108055 | KR27: =KR26-KR22 -> -9.9638686 | ... NI27: =NI26-NI22 -> 26.6
A28: Temps Scheduled | IP28: 11 | IQ28: 11 | IR28: 11 | IS28: 4 | IT28: 8 | IU28: 15 | IV28: 11 | IW28: 11 | IX28: 11 | IY28: 11 | IZ28: 7 | JA28: 17 | JB28: 14 | JC28: 11 | JD28: 17 | JE28: 11 | JF28: 6
