Workbook
Name _1st_shift_percentage: Data!$B$60
Name _2nd_shift_percentage: Data!$B$59
Name Amazon_Replen: Data!$B$58
Name Autobagger_Bander: [1]Data!$B$28
Name Autobagger_Bander: [2]Data!$B$28
Name Autobagger_Bander: [2]Data!$B$28
Name Autobagger_Bander: Data!$B$28
Name Autobagger_Operator: [1]Data!$B$27
Name Autobagger_Operator: [2]Data!$B$27
Name Autobagger_Operator: [2]Data!$B$27
Name Autobagger_Operator: Data!$B$27
Name Average_units_per_bin: Data!$B$52
Name Cartbuilding: Data!$B$18
Name Cartons_per_hour_Cubiscan: Data!$B$38
Name Cubiscan: Data!$B$36
Name DD: #REF!
Name DTC: Data!$B$9
Name DTC_to_replen: Data!$B$35
Name Exceptions: [1]Data!$B$42
Name Exceptions: [2]Data!$B$42
Name Exceptions: [2]Data!$B$42
Name Exceptions: Data!$B$42
Name Gift_cards: Data!$B$21
Name Gift_cards_per_hour: Data!$B$26
Name Hours_1st: Data!$B$3
Name Hours_2nd: Data!$B$4
Name Inventory: Data!$B$50
Name Narvar: [1]Data!$B$41
Name Narvar: [2]Data!$B$41
Name Narvar: [2]Data!$B$41
Name Narvar: Data!$B$41
Name Open_orders: Data!$B$54
Name Overstock: [1]Data!$B$33
Name Overstock: [2]Data!$B$33
Name Overstock: [2]Data!$B$33
Name Overstock: Data!$B$33
Name Overstock_cycle_count: Data!$B$53
Name Pecentage_of_goal_2nd: Data!$B$6
Name Percentage_1st_Goal: Data!$B$43
Name Percentage_2nd_Goal: Data!$B$44
Name Percentage_Exceptions: Data!$B$47
Name Percentage_Narvar: Data!$B$45
Name Percentage_Non_Narvar: Data!$B$46
Name Percentage_of_goal_1st: Data!$B$5
Name Percentage_regular: Data!$B$14
Name Percentage_singles: Data!$B$15
Name Picking_cycle_count: Data!$B$51
Name Pieces_per_package: Data!$B$48
Name Planning: Data!$B$2
Name Receiving: [1]Data!$B$34
Name Receiving: [2]Data!$B$34
Name Receiving: [2]Data!$B$34
Name Receiving: Data!$B$34
Name Receiving_DD: #REF!
Name Region_1: Data!$B$10
Name Region_2: Data!$B$11
Name Region_7: Data!$B$12
Name Repack: Data!$B$22
Name Repack_goal: Data!$B$23
Name Replenishment_pull: [1]Data!$B$31

Sheet SOS Topics & Reminders
A1: Date Added | B1: Topic | C1: Notes | D1: Inital and Date Covered on 1st Shift | E1: Inital and Date Covered on 2nd Shift | F1: Inital and Date Covered on Wknd Shift
A2: 46086 | B2: Cell Phone Policy | C2: Issue reminder that all cell phones must be set to silent, vibrate mode or turned off during work hours, Employees are permitted to use cell phones only during designated breaks and lunch periods, and such use must occur off the warehouse floor. Use of your cell phone is strictly prohibited while operating an industrial vehicle, this is a serious safety violation. Please inform your supervisor and step off the floor if you must use your phone. | D2: 3/5/2026 - SC | E2: 03/08/2026-AG | F2: 3/6/26-sjn
A3: 45721 | B3: Weekly Production Review and Monthly TB Review | C3: Remind the team we review production weekly and conduct monthly TB with the team. Ensure they understand these metrics are being monitored and will be reviewed. | D3: 3/5/2026 - SC | E3: 03/08/2026-AG | F3: 3/6/26--sjn
A4: 46090 | B4: Counting errors | C4: Let people know that we are going to start adding cycle count errors to the rollup and will be tracking people's accuracy in counting going forward. | E4: 3/9/2026-MR | F4: 3/13/2026-sjn
A5: 46090 | B5: Vacation requests | C5: Please put in your vacation requests as early as you can. The time off calendar fills up quickly and we approve requests on a first come/first served basis. | D5: 3/10/2026 SC-CG | E5: 3/9/2026-MR | F5: 3/13/2026-sjn
A6: 45725 | B6: LMS scanning | C6: We discussed the importance of LMS and its impact on production and labor coding. | D6: 03/09/26 -SC-CG | E6: 03/15/2026 AG | F6: 3/13/2026 EP
A7: 46091 | B7: Update in PTO in Paylocity | C7: HR is working on this. We know it's not correct. We need to let the system resolve itself. Manually entering in hours is not working. | D7: 3/10/26 - CG/SC | E7: 03/15/2026 AG | F7: 46094
A8: 46091 | B8: Position Update | C8: O&T role is officially posted! If you wish to apply there is a QR code on the postings in the breakroom! | D8: 3/11/26 - CG/SC | E8: 3/15/2026 AG | F8: 3/13/2026-EP
A9: 46092 | B9: 401K Meeting | C9: Spanish Session for Monday 3/16 | D9: 3/12/26 - CG/SC | E9: 03/15/2026 AG | F9: 3/15/26 ep
A10: 46094 | B10: Food on the floor | C10: Remind folks that they can only have water on the floor. No candy, sodas, chips etc. | D10: 3/16/26 -CG | E10: 3/15/2026 AG | F10: 3/14/2026- sjn
A11: 46096 | B11: PTO request time frame | C11: All Paid Time Off (PTO) requests must be submitted before the weekly report closes for the applicable work week | E11: 03/15/2026 AG | F11: 3/15/2026 EP
A12: 46098 | B12: Coffe reminder | C12: Employees can only make ccoffee durning their break times. | D12: 03/17/2026- CG/SC | E12: 03/15/2026 AG | F12: 3/20/2026--sjn
A13: 46099 | B13: Incoming Volume and sale | C13: We discussed the upcoming incoming volume and sale, and reminded the team that there will be a PTO blackout. The team was also advised to be prepared for the increased workload. | D13: 03/18/26 CG-SC | E13: 03/18/2026 AG | F13: 3/20/2026 EP
A14: 46104 | B14: No cellphones after they clock in. | C14: Today, we communicated that team members are not permitted to use their cell phones once they are clocked in. All employees must be prepared for the SOS meeting with their phones turned off. | D14: 03/23/26 SC/CG | E14: 03/24/2026 AG | F14: 03/23/26 EP
A15: 46105 | B15: O&T Postion FINAL reminder | C15: The posting for the O&T position will be taken down tomorrow at noon. This is your final reminder to apply if you're interested! | D15: 3/25/26 - CG | E15: 03/24/2026 AG | F15: 3/27/26 EP
A16: 46111 | B16: Cell phones | C16: Reminder that cell phones left in the breakroom should please be put on silent. Please be mindful that this is shared space and sometimes people's notifications, ringtones and alarms are so loud they can be heard in offices and sometimes people are in meetings. | D16: 04/02/26 - SC | E16: 04/06/2026 ag | F16: 4/10/2026 sjn
A17: 46118 | B17: Cell phones, scanning, cherry picking | C17: Reminder that cell phones left in the breakroom should please be put on silent. Please be mindful that this is shared space, No cherry picking carts in picking, make sure to scan to the correct functions. | D17: 04/06/2026 -CG / SC | E17: 04/06/2026 ag | F17: 04/06/26 --SJ
A18: 46118 | B18: Washed but wanted Sale! | C18: We will be having a washed but wanted sale from Friday 4/10 to Thursday 4/16! We are looking for volunteers to sign up to work the sale, these people will get the first peak at the inventory for the day. Each employee will also receive $50 in Hanna Bucks to shop the sale. Please keep an eye out to sign up for the shopping slots and see your supervisor if you would like to sign up for working the sale! | D18: 04/07/2026 - CG/SC | E18: 04/07/2026 ag | F18: 4/10/26 sjn
A19: 46118 | B19: Use of chairs | C19: We found a chair in receiving at the vendor compliance station, this is a gentle reminder that the use of chairs in the warehouse in prohibited. Next time a chair is oberved it could result in disciplinary action. | D19: 04/07/2026 - CG/SC | E19: 04/07/2026 ag | F19: 4/10/26 sjn
A20: 04/072026 | B20: Housekeeping | C20: Return ladders, brooms, and dustbins to their designated aisles and rack locations. All carts and totes must also be returned to their assigned areas. Restock and clean shipping areas. | D20: 04/07/2026 - CG/SC | E20: 04/07/2026 ag | F20: 4/10/26 sjn
A21: 04/072026 | B21: DC Connect April-May | C21: The DC Connect team covered the activities for the months of April and May. | D21: 0407/2026 - MC/SA | E21: 04/07/2026 ag | F21: 4/10/26 sjn
A22: 46120 | B22: Washed but wanted | C22: We have recently found boxes of WBW where it appears someone has put their washed but wanted for the day in a box instead of sorting it down and just wrote WBW on it. This is a gentle reminder that all units must be sorted by size. The size must be written on all 4 sides of the carton. When a box is full you must seal it up and replace it. If someone is found to not be following proper proceedure they will receive corrective action. | F22: 4/10/26 sjn
A23: 46122 | B23: 401K meeting for English speakers | C23: 401K meeting for English speakers is on Monday, 4/13 at 3 pm. | D23: 04/13/26 - SJN-MC-SC | E23: 4/13/2026 ag
A24: 46122 | B24: Food in lockers | C24: The safety committee's EHS checklist modules have had noted that we have open food containers in lockers. Reminder that food left in lockers must be non-perishable and be completely sealed to avoid attracking bugs and rodents. Additionally, the same rules apply for the refridgerator, there should be no open food or drink containers. | D24: 04/13/26 - SJN-MC-SC | E24: 04/13/2026 ag | F24: 4/11/2026-sjn
A25: 46122 | B25: Friends and Family Sale | C25: The Friends and Family sale starts Tuesday April 21st and runs through Monday May 4th. We are currently working on a schedule and will release it as soon as it's complete but wanted to give everyone a head's up that there will be scheduled overtime. | D25: 04/13/26 - SJN-MC-SC | E25: 04/19/2026 ag | F25: 4/11/2026-sjn
A26: 46129 | B26: Reporting Accidents and Safety issues | C26: Remind people that they need to report Safety issues and Accidents and near misses right away. | E26: 04/19/2026 ag | F26: 4/18/26-sjn
A27: 46130 | B27: Cycle count errors being recorded | C27: Remind people that we are recording cycle count errors and these will turn up on their TB each month. | E27: 04/19/2026 ag | F27: 4/19/26-sjn
A28: 46131 | B28: Earth Day celebration on Friday | C28: Friday we will have a small celebration of Earth Day with plant give aways and snacks | E28: 04/19/2026 ag | F28: 4/19/26-sjn
A29: 46133 | B29: Safety Committee | C29: We are opening up positions on the Safety Committee and moving to an annual refresh cycle to give more team members the opportunity to participate and build valuable experience. Serving on the committee is a great way to contribute to a safer workplace, share ideas, collaborate across teams, and develop leadership and problem-solving skills. If you’re interested in joining, please speak with your supervisor to express your interest. You are able to apply if you are currently on the safety committee and would like to continue involvement. In the event that there are not enough volunteers, supervisors will select team members to ensure all areas are represented. We encourage everyone to consider getting involved and helping us continue to strengthen our safety culture | D29: 4/22/2026 - CG/SC/MC | E29: 04/19/2026 ag | F29: 4/24/26--sjn
A30: 46133 | B30: Safety Reminder | C30: Never open doors or entry gates for strangers, alert your supervisor immediately and direct anyone not currently employeed at Hanna to the reception area. Report any suspicious behavior or non-Hanna employee if seen in the parking lot. Do not let anyone "piggy back" entering the building. Safety should be priority for all associates. | D30: 4/24/26-sjn | E30: 04/26/2026 ag | F30: 4/24/26--sjn
A31: 46136 | B31: Safety Meeting | C31: There will be a safety meeting Monday 4/27 with Jackie, Vega, Rolexis, Richard and Jonat | D31: 4/27/26 -sjn | F31: 4/25/2026 EP
A32: 46136 | B32: Don't override when putting away overstock. | C32: Remind stockers not to use override when putting away overstock. We have been mistakenly putting boxes into Invalid locations. | D32: 4/27/26 -sjn | E32: 04/26/2026 ag | F32: 4/27/26--sjn
A33: 46144 | B33: Incorrect lift scans | C33: Do not use Inbound indirect scans for long periods of time. You should not be using 509 if you are pulling replenishment all day for instance. | D33: 5/11/2026 -cjg | E33: 05/17/2026 ag | F33: 5/2/2026 EP
A34: 46150 | B34: Mother's day | C34: DC will be close on 5/10/2026, to allow employee to celebrate Mother's day | D34: na | E34: na | F34: 5/8/2026-sjn
A35: 46150 | B35: Incorrect lift scans | C35: Reminder. Do not use Inbound indirect scans for long periods of time. You should not be using 509 if you are pulling replenishment all day for instance. | D35: 5/11/2026 -cjg | E35: 05/11/2026 AG | F35: 5/9/2026-sjn
A36: 46151 | B36: Empty boxes not empty | C36: When pulling empty boxes from picking, make sure the box is really empty. | D36: 5/11/2026 -cjg | E36: 05/11/2026 AG | F36: 5/9/2026-sjn
A37: 46153 | B37: Safety Reminder | C37: With it starting to get warmer, please remember to drink plenty of water! With this, please make sure it's in a plastic or metal sealable/spill proof bottle. A bottle that does not have a closable lid can lead to spills that can cause a slip and fall, glass bottles can fall and bust which lead to slip and fall as well as pose a cut risk | E37: 05/17/2026 ag | F37: 5/15/26-EP
A38: 46153 | B38: Memorial Day Sale | C38: Please let everyone know that the Memorial Day Sale starts this Thursday 5/14, please prepare for working scheduled overtime next week! | D38: 05/13 - SC-CG-MC | E38: 05/17/2026 ag | F38: 5/15/26-EP
A39: 46155 | B39: Safety Reminder | C39: Reminder for anyone driving industrial vehicles, you are responsible for reporting any observed vehicle issues or safety concerns to your supervisor immediately upon discovery. Do not continue operating a vehicle with an issue, no matter how small or insignificant you think it is. Safety comes first, we would much rather lock and tag out a vehicle, have it inspected and cleared by maintenance than someone get hurt or be involved in an accident. | D39: 05/14/2026- SC-DG-MC | E39: 05/17/2026 ag | F39: 5/15/26-EP
A40: 46155 | B40: Memorial Day Schedule | C40: Pay attention to posting in breakroom! | D40: 05/14/2026- SC-DG-MC | E40: 05/17/2026 ag | F40: 5/15/26-EP
...

Sheet Sheet1
A1: DC Links
A2: Outbound | B2: Inbound | C2: Supervisor Links | D2: Training/Crosstraining | E2: Test Password
A3: Outbound WIP | B3: Inbound Dashboard | C3: FC_Rollup | D3: Advanced Stocking Functions | E3: hannast
A4: Voice Console | B4: Receiving Dashboard | C4: IT Ticket Entry | D4: Advanced Stocking Functions - SP | E4: hannast
A5: Voicelink | D5: Throw Assessment | E5: hannas1
D6: Throw Assessment - SP | E6: hannat
D7: Picking Region 1 | E7: hannap
D8: Picking Region 1 - SP | E8: hannap

Sheet Monday Deployment
B1: {=IFERROR(_xlfn.IFS(E5=0,"",E5>0,E5),"")} -> Maria Carrasco | C1: {=IFERROR(_xlfn.IFS(F5=0,"",F5>0,F5),"")} -> SL | E1: Monday SHIFT DEPLOYMENT | O1: 1st shift | U1: =TODAY() -> 46189 | Z1: Outbound | AA1: Cart Building | AB1: AB Super User | AC1: AB Bander | AE1: Shipping | AF1: Taper | AG1: Special Projects | AH1: Training | AI1: ="Picking"&" "&COUNTA(AI2:AI38)-COUNTBLANK(AI2:AI38) -> Picking 1 | AJ1: ="Picking"&" "&COUNTA(AJ2:AJ38)-COUNTBLANK(AJ2:AJ38) -> Picking 0
B2: {=IFERROR(_xlfn.IFS(E6=0,"",E6>0,E6),"")} -> Brandee Foster- IL | C2: {=IFERROR(_xlfn.IFS(F6=0,"",F6>0,F6),"")} -> i | O2: Key | P2: Function | Q2: =TODAY() -> 46189 | R2: Work | S2: GM Plan | AA2: {=IFERROR(INDEX($B$1:$B$272,SMALL(IF($O$3=$C$1:$C$272,ROW($C$1:$C$272)-MIN(ROW($B$1:$B$272))+1,""), ROW()-1)),"")} | AB2: {=IFERROR(INDEX($B$1:$B$272,SMALL(IF($O$10=$C$1:$C$272,ROW($C$1:$C$272)-MIN(ROW($B$1:$B$272))+1,""), ROW()-1)),"")} | AC2: {=IFERROR(INDEX($B$1:$B$272,SMALL(IF($O$9=$C$1:$C$272,ROW($C$1:$C$272)-MIN(ROW($B$1:$B$272))+1,""), ROW()-1)),"")} | AE2: {=IFERROR(INDEX($B$1:$B$272,SMALL(IF($O$6=$C$1:$C$272,ROW($C$1:$C$272)-MIN(ROW($B$1:$B$272))+1,""), ROW()-1)),"")} | AF2: {=IFERROR(INDEX($B$1:$B$272,SMALL(IF($O$8=$C$1:$C$272,ROW($C$1:$C$272)-MIN(ROW($B$1:$B$272))+1,""), ROW()-1)),"")} | AG2: {=IFERROR(INDEX($B$1:$B$272,SMALL(IF($O$31=$C$1:$C$272,ROW($C$1:$C$272)-MIN(ROW($B$1:$B$272))+1,""), ROW()-1)),"")} | AH2: {=IFERROR(INDEX($B$1:$B$272,SMALL(IF($O$21=$C$1:$C$272,ROW($C$1:$C$272)-MIN(ROW($B$1:$B$272))+1,""), ROW()-1)),"")} | AI2: {=IFERROR(INDEX($B$1:$B$31,SMALL(IF($O$4=$C$1:$C$31,ROW($C$1:$C$31)-MIN(ROW($B$1:$B$31))+1,""), ROW()-1)),"")} -> Dania Curbelo | AJ2: {=IFERROR(INDEX($B$32:$B$646,SMALL(IF($O$4=$C$32:$C$646,ROW($C$32:$C$646)-MIN(ROW($B$32:$B$646))+1,""), ROW()-1)),"")} | AL2: Bander
B3: {=IFERROR(_xlfn.IFS(E7=0,"",E7>0,E7),"")} -> Ailin Reynaldo | C3: {=IFERROR(_xlfn.IFS(F7=0,"",F7>0,F7),"")} -> I | E3: Hanna employees | J3: GIG employees | O3: CB | P3: Cartbuilding | Q3: =COUNTIFS($F$5:$F$33,O3)+COUNTIFS($I$5:$I$33,O3) -> 0 | R3: =V7 -> 3677 | S3: =LOOKUP(U1,'Deployment needs'!$2:$2,'Deployment needs'!58:58) -> 0.4837963 | U3: DC Daily Goal | V3: =LOOKUP(U1,'Deployment needs'!2:2,'Deployment needs'!5:5) -> 13000 | AA3: {=IFERROR(INDEX($B$1:$B$272,SMALL(IF($O$3=$C$1:$C$272,ROW($C$1:$C$272)-MIN(ROW($B$1:$B$272))+1,""), ROW()-1)),"")} | AB3: {=IFERROR(INDEX($B$1:$B$272,SMALL(IF($O$10=$C$1:$C$272,ROW($C$1:$C$272)-MIN(ROW($B$1:$B$272))+1,""), ROW()-1)),"")} | AC3: {=IFERROR(INDEX($B$1:$B$272,SMALL(IF($O$9=$C$1:$C$272,ROW($C$1:$C$272)-MIN(ROW($B$1:$B$272))+1,""), ROW()-1)),"")} | AE3: {=IFERROR(INDEX($B$1:$B$272,SMALL(IF($O$6=$C$1:$C$272,ROW($C$1:$C$272)-MIN(ROW($B$1:$B$272))+1,""), ROW()-1)),"")} | AF3: {=IFERROR(INDEX($B$1:$B$272,SMALL(IF($O$8=$C$1:$C$272,ROW($C$1:$C$272)-MIN(ROW($B$1:$B$272))+1,""), ROW()-1)),"")} | AG3: {=IFERROR(INDEX($B$1:$B$272,SMALL(IF($O$31=$C$1:$C$272,ROW($C$1:$C$272)-MIN(ROW($B$1:$B$272))+1,""), ROW()-1)),"")} | AH3: {=IFERROR(INDEX($B$1:$B$272,SMALL(IF($O$21=$C$1:$C$272,ROW($C$1:$C$272)-MIN(ROW($B$1:$B$272))+1,""), ROW()-1)),"")} | AI3: {=IFERROR(INDEX($B$1:$B$31,SMALL(IF($O$4=$C$1:$C$31,ROW($C$1:$C$31)-MIN(ROW($B$1:$B$31))+1,""), ROW()-1)),"")} -> Hector Rocha | AJ3: {=IFERROR(INDEX($B$32:$B$646,SMALL(IF($O$4=$C$32:$C$646,ROW($C$32:$C$646)-MIN(ROW($B$32:$B$646))+1,""), ROW()-1)),"")} | AL3: Groups | AM3: Sunday | AN3: Monday | AO3: Tuesday | AP3: Wednesday | AQ3: Thursday | AR3: Friday | AS3: Saturday
B4: {=IFERROR(_xlfn.IFS(E8=0,"",E8>0,E8),"")} -> Chrissy Parisek | C4: {=IFERROR(_xlfn.IFS(F8=0,"",F8>0,F8),"")} -> x | E4: 1st SHIFT DEPLOYMENT | F4: area | G4: Weekend Deployment | I4: area | J4: Names | L4: area | O4: P | P4: Picking- Bulk | Q4: =COUNTIFS($F$5:$F$33,O4)+COUNTIFS($I$5:$I$33,O4) -> 0 | R4: =V9 -> 2718 | S4: =LOOKUP(U1,'Deployment needs'!$2:$2,'Deployment needs'!54:54)+LOOKUP(U1,'Deployment needs'!$2:$2,'Deployment needs'!55:55) -> 4.0689815 | U4: 1st Shift Goal | V4: =LOOKUP(U1,'Deployment needs'!$2:$2,'Deployment needs'!$53:$53) -> 7150 | AA4: {=IFERROR(INDEX($B$1:$B$272,SMALL(IF($O$3=$C$1:$C$272,ROW($C$1:$C$272)-MIN(ROW($B$1:$B$272))+1,""), ROW()-1)),"")} | AB4: {=IFERROR(INDEX($B$1:$B$272,SMALL(IF($O$10=$C$1:$C$272,ROW($C$1:$C$272)-MIN(ROW($B$1:$B$272))+1,""), ROW()-1)),"")} | AC4: {=IFERROR(INDEX($B$1:$B$272,SMALL(IF($O$9=$C$1:$C$272,ROW($C$1:$C$272)-MIN(ROW($B$1:$B$272))+1,""), ROW()-1)),"")} | AE4: {=IFERROR(INDEX($B$1:$B$272,SMALL(IF($O$6=$C$1:$C$272,ROW($C$1:$C$272)-MIN(ROW($B$1:$B$272))+1,""), ROW()-1)),"")} | AF4: {=IFERROR(INDEX($B$1:$B$272,SMALL(IF($O$8=$C$1:$C$272,ROW($C$1:$C$272)-MIN(ROW($B$1:$B$272))+1,""), ROW()-1)),"")} | AG4: {=IFERROR(INDEX($B$1:$B$272,SMALL(IF($O$31=$C$1:$C$272,ROW($C$1:$C$272)-MIN(ROW($B$1:$B$272))+1,""), ROW()-1)),"")} | AH4: {=IFERROR(INDEX($B$1:$B$272,SMALL(IF($O$21=$C$1:$C$272,ROW($C$1:$C$272)-MIN(ROW($B$1:$B$272))+1,""), ROW()-1)),"")} | AI4: {=IFERROR(INDEX($B$1:$B$31,SMALL(IF($O$4=$C$1:$C$31,ROW($C$1:$C$31)-MIN(ROW($B$1:$B$31))+1,""), ROW()-1)),"")} | AJ4: {=IFERROR(INDEX($B$32:$B$646,SMALL(IF($O$4=$C$32:$C$646,ROW($C$32:$C$646)-MIN(ROW($B$32:$B$646))+1,""), ROW()-1)),"")} | AL4: 1st | AN4: {=IFERROR(INDEX($B$1:$B$675,SMALL(IF($O$15=$C$1:$C$675,ROW($C$1:$C$675)-MIN(ROW($B$1:$B$675))+1,""), ROW()-12)),"")}
B5: {=IFERROR(_xlfn.IFS(E9=0,"",E9>0,E9),"")} -> Yasmin Montero | C5: {=IFERROR(_xlfn.IFS(F9=0,"",F9>0,F9),"")} -> x | E5: Maria Carrasco | F5: SL | G5: Deja Andersson | I5: SL | J5: 7:30 AM-11:30 AM Crew | O5: SN | P5: Picking- Singles | Q5: =COUNTIFS($F$5:$F$33,O5)+COUNTIFS($I$5:$I$33,O5) -> 0 | U5: Projected Goal | V5: 10000 | AA5: {=IFERROR(INDEX($B$1:$B$272,SMALL(IF($O$3=$C$1:$C$272,ROW($C$1:$C$272)-MIN(ROW($B$1:$B$272))+1,""), ROW()-1)),"")} | AB5: {=IFERROR(INDEX($B$1:$B$272,SMALL(IF($O$10=$C$1:$C$272,ROW($C$1:$C$272)-MIN(ROW($B$1:$B$272))+1,""), ROW()-1)),"")} | AC5: {=IFERROR(INDEX($B$1:$B$272,SMALL(IF($O$9=$C$1:$C$272,ROW($C$1:$C$272)-MIN(ROW($B$1:$B$272))+1,""), ROW()-1)),"")} | AE5: {=IFERROR(INDEX($B$1:$B$272,SMALL(IF($O$6=$C$1:$C$272,ROW($C$1:$C$272)-MIN(ROW($B$1:$B$272))+1,""), ROW()-1)),"")} | AF5: {=IFERROR(INDEX($B$1:$B$272,SMALL(IF($O$8=$C$1:$C$272,ROW($C$1:$C$272)-MIN(ROW($B$1:$B$272))+1,""), ROW()-1)),"")} | AG5: {=IFERROR(INDEX($B$1:$B$272,SMALL(IF($O$31=$C$1:$C$272,ROW($C$1:$C$272)-MIN(ROW($B$1:$B$272))+1,""), ROW()-1)),"")} | AH5: {=IFERROR(INDEX($B$1:$B$272,SMALL(IF($O$21=$C$1:$C$272,ROW($C$1:$C$272)-MIN(ROW($B$1:$B$272))+1,""), ROW()-1)),"")} | AI5: {=IFERROR(INDEX($B$1:$B$31,SMALL(IF($O$4=$C$1:$C$31,ROW($C$1:$C$31)-MIN(ROW($B$1:$B$31))+1,""), ROW()-1)),"")} | AJ5: {=IFERROR(INDEX($B$32:$B$646,SMALL(IF($O$4=$C$32:$C$646,ROW($C$32:$C$646)-MIN(ROW($B$32:$B$646))+1,""), ROW()-1)),"")}
B6: {=IFERROR(_xlfn.IFS(E10=0,"",E10>0,E10),"")} -> Annaliet Rodriguez Perez | C6: {=IFERROR(_xlfn.IFS(F10=0,"",F10>0,F10),"")} -> x | E6: Brandee Foster- IL | F6: i | G6: Eumary Quinones | I6: I | O6: S | P6: Shipping | Q6: =COUNTIFS($F$5:$F$33,O6)+COUNTIFS($I$5:$I$33,O6) -> 0 | S6: {=LOOKUP(U1,'Deployment needs'!$2:$2,('Deployment needs'!56:56+'Deployment needs'!57:57))} -> 1.0857407 | U6: Total Units | V6: 28542 | AA6: {=IFERROR(INDEX($B$1:$B$272,SMALL(IF($O$3=$C$1:$C$272,ROW($C$1:$C$272)-MIN(ROW($B$1:$B$272))+1,""), ROW()-1)),"")} | AB6: {=IFERROR(INDEX($B$1:$B$272,SMALL(IF($O$10=$C$1:$C$272,ROW($C$1:$C$272)-MIN(ROW($B$1:$B$272))+1,""), ROW()-1)),"")} | AC6: {=IFERROR(INDEX($B$1:$B$272,SMALL(IF($O$9=$C$1:$C$272,ROW($C$1:$C$272)-MIN(ROW($B$1:$B$272))+1,""), ROW()-1)),"")} | AE6: {=IFERROR(INDEX($B$1:$B$272,SMALL(IF($O$6=$C$1:$C$272,ROW($C$1:$C$272)-MIN(ROW($B$1:$B$272))+1,""), ROW()-1)),"")} | AF6: Truck | AG6: Baby Bundle Project | AH6: {=IFERROR(INDEX($B$1:$B$272,SMALL(IF($O$21=$C$1:$C$272,ROW($C$1:$C$272)-MIN(ROW($B$1:$B$272))+1,""), ROW()-1)),"")} | AI6: {=IFERROR(INDEX($B$1:$B$31,SMALL(IF($O$4=$C$1:$C$31,ROW($C$1:$C$31)-MIN(ROW($B$1:$B$31))+1,""), ROW()-1)),"")} | AJ6: {=IFERROR(INDEX($B$32:$B$646,SMALL(IF($O$4=$C$32:$C$646,ROW($C$32:$C$646)-MIN(ROW($B$32:$B$646))+1,""), ROW()-1)),"")}
B7: {=IFERROR(_xlfn.IFS(E11=0,"",E11>0,E11),"")} -> Damaris Curbelo | C7: {=IFERROR(_xlfn.IFS(F11=0,"",F11>0,F11),"")} -> x | E7: Ailin Reynaldo | F7: I | G7: Sunia Hernandez | I7: x | O7: TR | P7: Truck loading | Q7: =COUNTIFS($F$5:$F$33,O7)+COUNTIFS($I$5:$I$33,O7) -> 0 | S7: =LOOKUP(U1,'Deployment needs'!$2:$2,'Deployment needs'!60:60) -> 0.18868056 | U7: Created Wave Units | V7: 3677 | AA7: {=IFERROR(INDEX($B$1:$B$272,SMALL(IF($O$3=$C$1:$C$272,ROW($C$1:$C$272)-MIN(ROW($B$1:$B$272))+1,""), ROW()-1)),"")} | AB7: Pick Singles | AC7: {=IFERROR(INDEX($B$1:$B$272,SMALL(IF($O$9=$C$1:$C$272,ROW($C$1:$C$272)-MIN(ROW($B$1:$B$272))+1,""), ROW()-1)),"")} | AE7: {=IFERROR(INDEX($B$1:$B$272,SMALL(IF($O$6=$C$1:$C$272,ROW($C$1:$C$272)-MIN(ROW($B$1:$B$272))+1,""), ROW()-1)),"")} | AF7: {=IFERROR(INDEX($B$1:$B$272,SMALL(IF($O$7=$C$1:$C$272,ROW($C$1:$C$272)-MIN(ROW($B$1:$B$272))+1,""), ROW()-6)),"")} | AG7: {=IFERROR(INDEX($B$1:$B$272,SMALL(IF($O$28=$C$1:$C$272,ROW($C$1:$C$272)-MIN(ROW($B$1:$B$272))+1,""), ROW()-6)),"")} | AH7: {=IFERROR(INDEX($B$1:$B$272,SMALL(IF($O$21=$C$1:$C$272,ROW($C$1:$C$272)-MIN(ROW($B$1:$B$272))+1,""), ROW()-1)),"")} | AI7: {=IFERROR(INDEX($B$1:$B$31,SMALL(IF($O$4=$C$1:$C$31,ROW($C$1:$C$31)-MIN(ROW($B$1:$B$31))+1,""), ROW()-1)),"")} | AJ7: {=IFERROR(INDEX($B$32:$B$646,SMALL(IF($O$4=$C$32:$C$646,ROW($C$32:$C$646)-MIN(ROW($B$32:$B$646))+1,""), ROW()-1)),"")}
B8: {=IFERROR(_xlfn.IFS(E12=0,"",E12>0,E12),"")} -> Dania Curbelo | C8: P | E8: Chrissy Parisek | F8: x | G8: Orlis Daniel Zaldivar | I8: x | O8: TP | P8: Taper/Downsize | Q8: =COUNTIFS($F$5:$F$33,O8)+COUNTIFS($I$5:$I$33,O8) -> 0 | S8: {=LOOKUP(U1,'Deployment needs'!$2:$2,('Deployment needs'!59:59+'Deployment needs'!62:62))} -> 0.27547222 | U8: Available Units | V8: 19216 | AA8: Lead - Support/Trainer | AB8: {=IFERROR(INDEX($B$1:$B$272,SMALL(IF($O$5=$C$1:$C$272,ROW($C$1:$C$272)-MIN(ROW($B$1:$B$272))+1,""), ROW()-7)),"")} | AC8: {=IFERROR(INDEX($B$1:$B$272,SMALL(IF($O$9=$C$1:$C$272,ROW($C$1:$C$272)-MIN(ROW($B$1:$B$272))+1,""), ROW()-1)),"")} | AE8: {=IFERROR(INDEX($B$1:$B$272,SMALL(IF($O$6=$C$1:$C$272,ROW($C$1:$C$272)-MIN(ROW($B$1:$B$272))+1,""), ROW()-1)),"")} | AF8: {=IFERROR(INDEX($B$1:$B$272,SMALL(IF($O$7=$C$1:$C$10,ROW($C$1:$C$272)-MIN(ROW($B$1:$B$272))+1,""), ROW()-6)),"")} | AG8: {=IFERROR(INDEX($B$1:$B$272,SMALL(IF($O$28=$C$1:$C$272,ROW($C$1:$C$272)-MIN(ROW($B$1:$B$272))+1,""), ROW()-6)),"")} | AH8: {=IFERROR(INDEX($B$1:$B$272,SMALL(IF($O$21=$C$1:$C$272,ROW($C$1:$C$272)-MIN(ROW($B$1:$B$272))+1,""), ROW()-1)),"")} | AI8: {=IFERROR(INDEX($B$1:$B$31,SMALL(IF($O$4=$C$1:$C$31,ROW($C$1:$C$31)-MIN(ROW($B$1:$B$31))+1,""), ROW()-1)),"")} | AJ8: {=IFERROR(INDEX($B$32:$B$646,SMALL(IF($O$4=$C$32:$C$646,ROW($C$32:$C$646)-MIN(ROW($B$32:$B$646))+1,""), ROW()-1)),"")}
B9: {=IFERROR(_xlfn.IFS(E13=0,"",E13>0,E13),"")} -> Esther Fonseca | C9: {=IFERROR(_xlfn.IFS(F13=0,"",F13>0,F13),"")} -> x | E9: Yasmin Montero | F9: x | G9: Rolexis Lopez Diaz | I9: x | O9: B | P9: Bander | Q9: =COUNTIFS($F$5:$F$33,O9)+COUNTIFS($I$5:$I$33,O9) -> 0 | S9: =LOOKUP(U1,'Deployment needs'!$2:$2,'Deployment needs'!63:63) -> 1.1585648 | U9: Units at Bander | V9: 2718 | AA9: {=IFERROR(INDEX($B$1:$B$272,SMALL(IF($O$30=$C$1:$C$272,ROW($C$1:$C$272)-MIN(ROW($B$1:$B$272))+1,""),ROW()-8)),"")} -> Maria Carrasco | AB9: {=IFERROR(INDEX($B$1:$B$272,SMALL(IF($O$5=$C$1:$C$272,ROW($C$1:$C$272)-MIN(ROW($B$1:$B$272))+1,""), ROW()-7)),"")} | AC9: {=IFERROR(INDEX($B$1:$B$272,SMALL(IF($O$9=$C$1:$C$272,ROW($C$1:$C$272)-MIN(ROW($B$1:$B$272))+1,""), ROW()-1)),"")} | AE9: {=IFERROR(INDEX($B$1:$B$272,SMALL(IF($O$6=$C$1:$C$272,ROW($C$1:$C$272)-MIN(ROW($B$1:$B$272))+1,""), ROW()-1)),"")} | AF9: {=IFERROR(INDEX($B$1:$B$272,SMALL(IF($O$7=$C$1:$C$10,ROW($C$1:$C$272)-MIN(ROW($B$1:$B$272))+1,""), ROW()-6)),"")} | AG9: {=IFERROR(INDEX($B$1:$B$272,SMALL(IF($O$28=$C$1:$C$272,ROW($C$1:$C$272)-MIN(ROW($B$1:$B$272))+1,""), ROW()-6)),"")} | AH9: {=IFERROR(INDEX($B$1:$B$272,SMALL(IF($O$21=$C$1:$C$272,ROW($C$1:$C$272)-MIN(ROW($B$1:$B$272))+1,""), ROW()-1)),"")} | AI9: {=IFERROR(INDEX($B$1:$B$31,SMALL(IF($O$4=$C$1:$C$31,ROW($C$1:$C$31)-MIN(ROW($B$1:$B$31))+1,""), ROW()-1)),"")} | AJ9: {=IFERROR(INDEX($B$32:$B$646,SMALL(IF($O$4=$C$32:$C$646,ROW($C$32:$C$646)-MIN(ROW($B$32:$B$646))+1,""), ROW()-1)),"")}
B10: {=IFERROR(_xlfn.IFS(E14=0,"",E14>0,E14),"")} -> Yordanka Manzanares | C10: {=IFERROR(_xlfn.IFS(F14=0,"",F14>0,F14),"")} -> x | E10: Annaliet Rodriguez Perez | F10: x | G10: Joaquin Lopez Enrique | I10: x | O10: AB | P10: Autobagger | Q10: =COUNTIFS($F$5:$F$33,O10)+COUNTIFS($I$5:$I$33,O10) -> 0 | S10: =LOOKUP(U1,'Deployment needs'!$2:$2,'Deployment needs'!64:64) -> 1 | U10: Held by Replen | V10: 868 | AA10: {=IFERROR(INDEX($B$1:$B$272,SMALL(IF($O$30=$C$1:$C$272,ROW($C$1:$C$272)-MIN(ROW($B$1:$B$272))+1,""),ROW()-8)),"")} -> Deja Andersson | AB10: {=IFERROR(INDEX($B$1:$B$272,SMALL(IF($O$5=$C$1:$C$272,ROW($C$1:$C$272)-MIN(ROW($B$1:$B$272))+1,""), ROW()-7)),"")} | AC10: {=IFERROR(INDEX($B$1:$B$272,SMALL(IF($O$9=$C$1:$C$272,ROW($C$1:$C$272)-MIN(ROW($B$1:$B$272))+1,""), ROW()-1)),"")} | AE10: {=IFERROR(INDEX($B$1:$B$272,SMALL(IF($O$6=$C$1:$C$272,ROW($C$1:$C$272)-MIN(ROW($B$1:$B$272))+1,""), ROW()-1)),"")} | AF10: {=IFERROR(INDEX($B$1:$B$272,SMALL(IF($O$7=$C$1:$C$10,ROW($C$1:$C$272)-MIN(ROW($B$1:$B$272))+1,""), ROW()-6)),"")} | AG10: {=IFERROR(INDEX($B$1:$B$272,SMALL(IF($O$28=$C$1:$C$272,ROW($C$1:$C$272)-MIN(ROW($B$1:$B$272))+1,""), ROW()-6)),"")} | AH10: {=IFERROR(INDEX($B$1:$B$272,SMALL(IF($O$21=$C$1:$C$272,ROW($C$1:$C$272)-MIN(ROW($B$1:$B$272))+1,""), ROW()-1)),"")} | AI10: {=IFERROR(INDEX($B$1:$B$31,SMALL(IF($O$4=$C$1:$C$31,ROW($C$1:$C$31)-MIN(ROW($B$1:$B$31))+1,""), ROW()-1)),"")} | AJ10: {=IFERROR(INDEX($B$32:$B$646,SMALL(IF($O$4=$C$32:$C$646,ROW($C$32:$C$646)-MIN(ROW($B$32:$B$646))+1,""), ROW()-1)),"")} | AL10: 2nd
B11: {=IFERROR(_xlfn.IFS(E15=0,"",E15>0,E15),"")} -> Jackie Gomez | C11: {=IFERROR(_xlfn.IFS(F15=0,"",F15>0,F15),"")} -> x | E11: Damaris Curbelo | F11: x | G11: Dora Lopez (Alicia) | I11: x | O11: R | P11: Resets | Q11: =COUNTIFS($F$5:$F$33,O11)+COUNTIFS($I$5:$I$33,O11) -> 0 | S11: =LOOKUP(U1,'Deployment needs'!$2:$2,'Deployment needs'!93:93) -> 0.18055556 | U11: Actual Picked | V11: TBD | AA11: {=IFERROR(INDEX($B$1:$B$272,SMALL(IF($O$30=$C$1:$C$272,ROW($C$1:$C$272)-MIN(ROW($B$1:$B$272))+1,""),ROW()-8)),"")} | AB11: {=IFERROR(INDEX($B$1:$B$272,SMALL(IF($O$5=$C$1:$C$272,ROW($C$1:$C$272)-MIN(ROW($B$1:$B$272))+1,""), ROW()-7)),"")} | AC11: {=IFERROR(INDEX($B$1:$B$272,SMALL(IF($O$9=$C$1:$C$272,ROW($C$1:$C$272)-MIN(ROW($B$1:$B$272))+1,""), ROW()-1)),"")} | AE11: {=IFERROR(INDEX($B$1:$B$272,SMALL(IF($O$6=$C$1:$C$272,ROW($C$1:$C$272)-MIN(ROW($B$1:$B$272))+1,""), ROW()-1)),"")} | AF11: ="Returns"&" "&R22&" "&"orders"&" "&COUNTA(AF12:AF27)-COUNTBLANK(AF12:AF27) -> Returns 535 orders -1 | AG11: {=IFERROR(INDEX($B$1:$B$272,SMALL(IF($O$28=$C$1:$C$272,ROW($C$1:$C$272)-MIN(ROW($B$1:$B$272))+1,""), ROW()-6)),"")} | AH11: {=IFERROR(INDEX($B$1:$B$272,SMALL(IF($O$21=$C$1:$C$272,ROW($C$1:$C$272)-MIN(ROW($B$1:$B$272))+1,""), ROW()-1)),"")} | AI11: {=IFERROR(INDEX($B$1:$B$31,SMALL(IF($O$4=$C$1:$C$31,ROW($C$1:$C$31)-MIN(ROW($B$1:$B$31))+1,""), ROW()-1)),"")} | AJ11: {=IFERROR(INDEX($B$32:$B$646,SMALL(IF($O$4=$C$32:$C$646,ROW($C$32:$C$646)-MIN(ROW($B$32:$B$646))+1,""), ROW()-1)),"")}
B12: {=IFERROR(_xlfn.IFS(E16=0,"",E16>0,E16),"")} -> Madelayne Oduardo | C12: {=IFERROR(_xlfn.IFS(F16=0,"",F16>0,F16),"")} -> x | E12: Dania Curbelo | F12: x | G12: Sonia Lopez Medina | I12: x | O12: E | P12: Resets Exeptions | Q12: =COUNTIFS($F$5:$F$33,O12)+COUNTIFS($I$5:$I$33,O12) -> 0 | U12: BI Shift Shipped | V12: TBD | Z12: Inventory | AA12: Resets | AB12: Picking Cycle Counts / Spot Count | AC12: Outbound Exception | AE12: Tasks | AF12: {=IFERROR(INDEX($B$1:$B$272,SMALL(IF($C$1:$C$272=$O$22, ROW($B$1:$B$272)-ROW($B$1)+1),ROWS($AF$12:AF12) ) ), "")} | AG12: Sort Returns Putaway | AH12: Inventory & CC Reconcile | AI12: {=IFERROR(INDEX($B$1:$B$31,SMALL(IF($O$4=$C$1:$C$31,ROW($C$1:$C$31)-MIN(ROW($B$1:$B$31))+1,""), ROW()-1)),"")} | AJ12: {=IFERROR(INDEX($B$32:$B$646,SMALL(IF($O$4=$C$32:$C$646,ROW($C$32:$C$646)-MIN(ROW($B$32:$B$646))+1,""), ROW()-1)),"")}
B13: {=IFERROR(_xlfn.IFS(E17=0,"",E17>0,E17),"")} -> Roxana Lloret | C13: {=IFERROR(_xlfn.IFS(F17=0,"",F17>0,F17),"")} -> x | E13: Esther Fonseca | F13: x | G13: Josefa Martinez | I13: x | J13: 12 pm- 4 pm crew | O13: IP | P13: Ipads | Q13: =COUNTIFS($F$5:$F$33,O13)+COUNTIFS($I$5:$I$33,O13) -> 0 | U13: % to Plan Shipped | V13: =V12/V4 -> #VALUE! | AA13: {=IFERROR(INDEX($B$1:$B$272,SMALL(IF($O$11=$C$1:$C$272,ROW($C$1:$C$272)-MIN(ROW($B$1:$B$272))+1,""), ROW()-12)),"")} | AB13: {=IFERROR(INDEX($B$1:$B$272,SMALL(IF($O$16=$C$1:$C$272,ROW($C$1:$C$272)-MIN(ROW($B$1:$B$272))+1,""), ROW()-12)),"")} | AC13: {=IFERROR(INDEX($B$1:$B$272,SMALL(IF($O$14=$C$1:$C$272,ROW($C$1:$C$272)-MIN(ROW($B$1:$B$272))+1,""), ROW()-12)),"")} | AE13: Rush | AF13: {=IFERROR(INDEX($B$1:$B$272,SMALL(IF($C$1:$C$272=$O$22, ROW($B$1:$B$272)-ROW($B$1)+1),ROWS($AF$12:AF13) ) ), "")} | AG13: {=IFERROR(INDEX($B$1:$B$272,SMALL(IF($O$24=$C$1:$C$272,ROW($C$1:$C$272)-MIN(ROW($B$1:$B$272))+1,""), ROW()-12)),"")} | AH13: {=IFERROR(INDEX($B$1:$B$272,SMALL(IF($O$32=$C$1:$C$272,ROW($C$1:$C$272)-MIN(ROW($B$1:$B$272))+1,""), ROW()-12)),"")} -> Brandee Foster- IL | AI13: {=IFERROR(INDEX($B$1:$B$31,SMALL(IF($O$4=$C$1:$C$31,ROW($C$1:$C$31)-MIN(ROW($B$1:$B$31))+1,""), ROW()-1)),"")} | AJ13: {=IFERROR(INDEX($B$32:$B$646,SMALL(IF($O$4=$C$32:$C$646,ROW($C$32:$C$646)-MIN(ROW($B$32:$B$646))+1,""), ROW()-1)),"")}
B14: {=IFERROR(_xlfn.IFS(E18=0,"",E18>0,E18),"")} -> Shvodra Anderson | C14: {=IFERROR(_xlfn.IFS(F18=0,"",F18>0,F18),"")} -> x | E14: Yordanka Manzanares | F14: x | G14: Ernesto Reyes Perez | I14: x | O14: DS | P14: Outbound Exception | Q14: =COUNTIFS($F$5:$F$33,O14)+COUNTIFS($I$5:$I$33,O14) -> 0 | S14: {=LOOKUP(U1,'Deployment needs'!$2:$2,('Deployment needs'!91:91+'Deployment needs'!92:92+'Deployment needs'!61:61))} -> 0.5662037 | U14: Clustered Carts | V14: 60 | AA14: {=IFERROR(INDEX($B$1:$B$272,SMALL(IF($O$11=$C$1:$C$272,ROW($C$1:$C$272)-MIN(ROW($B$1:$B$272))+1,""), ROW()-12)),"")} | AB14: {=IFERROR(INDEX($B$1:$B$272,SMALL(IF($O$16=$C$1:$C$272,ROW($C$1:$C$272)-MIN(ROW($B$1:$B$272))+1,""), ROW()-12)),"")} | AC14: {=IFERROR(INDEX($B$1:$B$272,SMALL(IF($O$14=$C$1:$C$272,ROW($C$1:$C$272)-MIN(ROW($B$1:$B$272))+1,""), ROW()-12)),"")} | AE14: Aged orders/Emails | AF14: {=IFERROR(INDEX($B$1:$B$272,SMALL(IF($C$1:$C$272=$O$22, ROW($B$1:$B$272)-ROW($B$1)+1),ROWS($AF$12:AF14) ) ), "")} | AG14: {=IFERROR(INDEX($B$1:$B$272,SMALL(IF($O$24=$C$1:$C$272,ROW($C$1:$C$272)-MIN(ROW($B$1:$B$272))+1,""), ROW()-12)),"")} | AH14: {=IFERROR(INDEX($B$1:$B$272,SMALL(IF($O$32=$C$1:$C$272,ROW($C$1:$C$272)-MIN(ROW($B$1:$B$272))+1,""), ROW()-12)),"")} -> Ailin Reynaldo | AI14: {=IFERROR(INDEX($B$1:$B$31,SMALL(IF($O$4=$C$1:$C$31,ROW($C$1:$C$31)-MIN(ROW($B$1:$B$31))+1,""), ROW()-1)),"")} | AJ14: {=IFERROR(INDEX($B$32:$B$646,SMALL(IF($O$4=$C$32:$C$646,ROW($C$32:$C$646)-MIN(ROW($B$32:$B$646))+1,""), ROW()-1)),"")}
B15: {=IFERROR(_xlfn.IFS(E19=0,"",E19>0,E19),"")} -> Laura Gonzalez Bustamante | C15: {=IFERROR(_xlfn.IFS(F19=0,"",F19>0,F19),"")} -> x | E15: Jackie Gomez | F15: x | G15: Yordany Miranda | I15: x | O15: MP | P15: DTC Putaway | Q15: =COUNTIFS($F$5:$F$33,O15)+COUNTIFS($I$5:$I$33,O15) -> 0 | S15: =LOOKUP(U1,'Deployment needs'!$2:$2,'Deployment needs'!95:95) -> 0.25 | U15: Multis to Pick | V15: 46186 | AA15: {=IFERROR(INDEX($B$1:$B$272,SMALL(IF($O$11=$C$1:$C$272,ROW($C$1:$C$272)-MIN(ROW($B$1:$B$272))+1,""), ROW()-12)),"")} | AB15: {=IFERROR(INDEX($B$1:$B$272,SMALL(IF($O$16=$C$1:$C$272,ROW($C$1:$C$272)-MIN(ROW($B$1:$B$272))+1,""), ROW()-12)),"")} | AC15: {=IFERROR(INDEX($B$1:$B$272,SMALL(IF($O$14=$C$1:$C$272,ROW($C$1:$C$272)-MIN(ROW($B$1:$B$272))+1,""), ROW()-12)),"")} | AF15: {=IFERROR(INDEX($B$1:$B$272,SMALL(IF($C$1:$C$272=$O$22, ROW($B$1:$B$272)-ROW($B$1)+1),ROWS($AF$12:AF15) ) ), "")} | AG15: {=IFERROR(INDEX($B$1:$B$272,SMALL(IF($O$24=$C$1:$C$272,ROW($C$1:$C$272)-MIN(ROW($B$1:$B$272))+1,""), ROW()-12)),"")} | AH15: {=IFERROR(INDEX($B$1:$B$272,SMALL(IF($O$32=$C$1:$C$272,ROW($C$1:$C$272)-MIN(ROW($B$1:$B$272))+1,""), ROW()-12)),"")} -> Eumary Quinones | AI15: {=IFERROR(INDEX($B$1:$B$31,SMALL(IF($O$4=$C$1:$C$31,ROW($C$1:$C$31)-MIN(ROW($B$1:$B$31))+1,""), ROW()-1)),"")} | AJ15: {=IFERROR(INDEX($B$32:$B$646,SMALL(IF($O$4=$C$32:$C$646,ROW($C$32:$C$646)-MIN(ROW($B$32:$B$646))+1,""), ROW()-1)),"")}
B16: {=IFERROR(_xlfn.IFS(E20=0,"",E20>0,E20),"")} -> Mbaya Kapita | C16: {=IFERROR(_xlfn.IFS(F20=0,"",F20>0,F20),"")} -> x | E16: Madelayne Oduardo | F16: x | G16: Carlos Molina | I16: x | O16: PC | P16: Picking CC | Q16: =COUNTIFS($F$5:$F$33,O16)+COUNTIFS($I$5:$I$33,O16) -> 0 | S16: =LOOKUP(U1,'Deployment needs'!$2:$2,'Deployment needs'!88:88) -> 2.4138889 | U16: Singles to Pick | V16: 46187 | AA16: {=IFERROR(INDEX($B$1:$B$272,SMALL(IF($O$11=$C$1:$C$272,ROW($C$1:$C$272)-MIN(ROW($B$1:$B$272))+1,""), ROW()-12)),"")} | AB16: {=IFERROR(INDEX($B$1:$B$272,SMALL(IF($O$16=$C$1:$C$272,ROW($C$1:$C$272)-MIN(ROW($B$1:$B$272))+1,""), ROW()-12)),"")} | AC16: ="CubiScan - in / out"&" "&R27 -> CubiScan - in / out 0 | AE16: Misspicks/DTC Putaway | AF16: {=IFERROR(INDEX($B$1:$B$272,SMALL(IF($C$1:$C$272=$O$22, ROW($B$1:$B$272)-ROW($B$1)+1),ROWS($AF$12:AF16) ) ), "")} | AG16: {=IFERROR(INDEX($B$1:$B$272,SMALL(IF($O$24=$C$1:$C$272,ROW($C$1:$C$272)-MIN(ROW($B$1:$B$272))+1,""), ROW()-12)),"")} | AH16: {=IFERROR(INDEX($B$1:$B$272,SMALL(IF($O$32=$C$1:$C$272,ROW($C$1:$C$272)-MIN(ROW($B$1:$B$272))+1,""), ROW()-12)),"")} | AI16: {=IFERROR(INDEX($B$1:$B$31,SMALL(IF($O$4=$C$1:$C$31,ROW($C$1:$C$31)-MIN(ROW($B$1:$B$31))+1,""), ROW()-1)),"")} | AJ16: {=IFERROR(INDEX($B$32:$B$646,SMALL(IF($O$4=$C$32:$C$646,ROW($C$32:$C$646)-MIN(ROW($B$32:$B$646))+1,""), ROW()-1)),"")}
B17: {=IFERROR(_xlfn.IFS(E21=0,"",E21>0,E21),"")} -> Tamara Izada Aguado | C17: {=IFERROR(_xlfn.IFS(F21=0,"",F21>0,F21),"")} -> x | E17: Roxana Lloret | F17: x | O17: OC | P17: Overstock CC | Q17: =COUNTIFS($F$5:$F$33,O17)+COUNTIFS($I$5:$I$33,O17) -> 0 | S17: =LOOKUP(U1,'Deployment needs'!$2:$2,'Deployment needs'!75:75) -> 1.0126111 | U17: UPP | V17: 4,2 | AA17: {=IFERROR(INDEX($B$1:$B$272,SMALL(IF($O$11=$C$1:$C$272,ROW($C$1:$C$272)-MIN(ROW($B$1:$B$272))+1,""), ROW()-12)),"")} | AB17: {=IFERROR(INDEX($B$1:$B$272,SMALL(IF($O$16=$C$1:$C$272,ROW($C$1:$C$272)-MIN(ROW($B$1:$B$272))+1,""), ROW()-12)),"")} | AC17: {=IFERROR(INDEX($B$1:$B$272,SMALL(IF($O$27=$C$1:$C$272,ROW($C$1:$C$272)-MIN(ROW($B$1:$B$272))+1,""), ROW()-16)),"")} | AE17: {=IFERROR(INDEX($B$1:$B$272,SMALL(IF($O$15=$C$1:$C$272,ROW($C$1:$C$272)-MIN(ROW($B$1:$B$272))+1,""), ROW()-16)),"")} | AF17: {=IFERROR(INDEX($B$1:$B$272,SMALL(IF($C$1:$C$272=$O$22, ROW($B$1:$B$272)-ROW($B$1)+1),ROWS($AF$12:AF17) ) ), "")} | AG17: ="Returns Putaway"&" "&R24 -> Returns Putaway 637 | AH17: {=IFERROR(INDEX($B$1:$B$272,SMALL(IF($O$32=$C$1:$C$272,ROW($C$1:$C$272)-MIN(ROW($B$1:$B$272))+1,""), ROW()-12)),"")} | AI17: {=IFERROR(INDEX($B$1:$B$31,SMALL(IF($O$4=$C$1:$C$31,ROW($C$1:$C$31)-MIN(ROW($B$1:$B$31))+1,""), ROW()-1)),"")} | AJ17: {=IFERROR(INDEX($B$32:$B$646,SMALL(IF($O$4=$C$32:$C$646,ROW($C$32:$C$646)-MIN(ROW($B$32:$B$646))+1,""), ROW()-1)),"")} | AL17: Rotation DTC putaway
B18: {=IFERROR(_xlfn.IFS(E22=0,"",E22>0,E22),"")} -> Hector Rocha | C18: p | E18: Shvodra Anderson | F18: x | O18: O | P18: Overstock putaway | Q18: =COUNTIFS($F$5:$F$33,O18)+COUNTIFS($I$5:$I$33,O18) -> 0 | R18: =LOOKUP($U$1-1,'Inbound SOS & EOD'!$1:$1,'Inbound SOS & EOD'!74:74) -> 140 | S18: =LOOKUP(U1,'Deployment needs'!$2:$2,'Deployment needs'!72:72) -> 4.4217778 | U18: Resets | V18: 0 | AA18: {=IFERROR(INDEX($B$1:$B$272,SMALL(IF($O$11=$C$1:$C$272,ROW($C$1:$C$272)-MIN(ROW($B$1:$B$272))+1,""), ROW()-12)),"")} | AB18: {=IFERROR(INDEX($B$1:$B$272,SMALL(IF(O$16=$C$1:$C$272,ROW($C$1:$C$272)-MIN(ROW($B$1:$B$272))+1,""), ROW()-12)),"")} | AC18: {=IFERROR(INDEX($B$1:$B$272,SMALL(IF($O$27=$C$1:$C$272,ROW($C$1:$C$272)-MIN(ROW($B$1:$B$272))+1,""), ROW()-16)),"")} | AE18: {=IFERROR(INDEX($B$1:$B$272,SMALL(IF($O$15=$C$1:$C$272,ROW($C$1:$C$272)-MIN(ROW($B$1:$B$272))+1,""), ROW()-16)),"")} | AF18: {=IFERROR(INDEX($B$1:$B$272,SMALL(IF($C$1:$C$272=$O$22, ROW($B$1:$B$272)-ROW($B$1)+1),ROWS($AF$12:AF18) ) ), "")} | AG18: {=IFERROR(INDEX($B$1:$B$272,SMALL(IF($O$25=$C$1:$C$272,ROW($C$1:$C$272)-MIN(ROW($B$1:$B$272))+1,""), ROW()-17)),"")} | AH18: {=IFERROR(INDEX($B$1:$B$272,SMALL(IF($O$32=$C$1:$C$272,ROW($C$1:$C$272)-MIN(ROW($B$1:$B$272))+1,""), ROW()-12)),"")} | AI18: {=IFERROR(INDEX($B$1:$B$31,SMALL(IF($O$4=$C$1:$C$31,ROW($C$1:$C$31)-MIN(ROW($B$1:$B$31))+1,""), ROW()-1)),"")} | AJ18: {=IFERROR(INDEX($B$32:$B$646,SMALL(IF($O$4=$C$32:$C$646,ROW($C$32:$C$646)-MIN(ROW($B$32:$B$646))+1,""), ROW()-1)),"")} | AL18: Groups | AM18: Sunday | AN18: Monday | AO18: Tuesday | AP18: Wednesday | AQ18: Thursday | AR18: Friday | AS18: Saturday
B19: {=IFERROR(_xlfn.IFS(E23=0,"",E23>0,E23),"")} -> Iraldo Rodriguez | C19: {=IFERROR(_xlfn.IFS(F23=0,"",F23>0,F23),"")} -> x | E19: Laura Gonzalez Bustamante | F19: x | O19: RP | P19: Replen Pull | Q19: =COUNTIFS($F$5:$F$33,O19)+COUNTIFS($I$5:$I$33,O19) -> 0 | R19: =LOOKUP($U$1-1,'Inbound SOS & EOD'!$1:$1,'Inbound SOS & EOD'!84:84) -> 88 | S19: =LOOKUP(U1,'Deployment needs'!$2:$2,'Deployment needs'!70:70) -> 0.30895062 | U19: Region 1 UPH | V19: TBD | Z19: Inbound | AA19: Reset Exceptions | AE19: {=IFERROR(INDEX($B$1:$B$272,SMALL(IF($O$15=$C$1:$C$272,ROW($C$1:$C$272)-MIN(ROW($B$1:$B$272))+1,""), ROW()-16)),"")} | AF19: {=IFERROR(INDEX($B$1:$B$272,SMALL(IF($C$1:$C$272=$O$22, ROW($B$1:$B$272)-ROW($B$1)+1),ROWS($AF$12:AF19) ) ), "")} | AG19: {=IFERROR(INDEX($B$1:$B$272,SMALL(IF($O$25=$C$1:$C$272,ROW($C$1:$C$272)-MIN(ROW($B$1:$B$272))+1,""), ROW()-17)),"")} | AH19: {=IFERROR(INDEX($B$1:$B$272,SMALL(IF($O$32=$C$1:$C$272,ROW($C$1:$C$272)-MIN(ROW($B$1:$B$272))+1,""), ROW()-12)),"")} | AI19: {=IFERROR(INDEX($B$1:$B$31,SMALL(IF($O$4=$C$1:$C$31,ROW($C$1:$C$31)-MIN(ROW($B$1:$B$31))+1,""), ROW()-1)),"")} | AJ19: {=IFERROR(INDEX($B$32:$B$646,SMALL(IF($O$4=$C$32:$C$646,ROW($C$32:$C$646)-MIN(ROW($B$32:$B$646))+1,""), ROW()-1)),"")} | AL19: 1st
B20: {=IFERROR(_xlfn.IFS(E25=0,"",E25>0,E25),"")} -> Jose Posse | C20: {=IFERROR(_xlfn.IFS(F25=0,"",F25>0,F25),"")} -> x | E20: Mbaya Kapita | F20: x | O20: RT | P20: Replen Throw | Q20: =COUNTIFS($F$5:$F$33,O20)+COUNTIFS($I$5:$I$33,O20) -> 0 | R20: =LOOKUP($U$1-1,'Inbound SOS & EOD'!$1:$1,'Inbound SOS & EOD'!85:85) -> 0 | S20: =LOOKUP(U1,'Deployment needs'!$2:$2,'Deployment needs'!71:71) -> 0.39722222 | U20: Region 2 UPH | V20: TBD | AA20: {=IFERROR(INDEX($B$1:$B$272,SMALL(IF($O$11=$C$1:$C$272,ROW($C$1:$C$272)-MIN(ROW($B$1:$B$272))+1,""), ROW()-12)),"")} | AE20: {=IFERROR(INDEX($B$1:$B$272,SMALL(IF($O$15=$C$1:$C$272,ROW($C$1:$C$272)-MIN(ROW($B$1:$B$272))+1,""), ROW()-16)),"")} | AF20: {=IFERROR(INDEX($B$1:$B$272,SMALL(IF($C$1:$C$272=$O$22, ROW($B$1:$B$272)-ROW($B$1)+1),ROWS($AF$12:AF20) ) ), "")} | AG20: {=IFERROR(INDEX($B$1:$B$272,SMALL(IF($O$25=$C$1:$C$272,ROW($C$1:$C$272)-MIN(ROW($B$1:$B$272))+1,""), ROW()-17)),"")} | AH20: {=IFERROR(INDEX($B$1:$B$272,SMALL(IF($O$32=$C$1:$C$272,ROW($C$1:$C$272)-MIN(ROW($B$1:$B$272))+1,""), ROW()-12)),"")} | AI20: {=IFERROR(INDEX($B$1:$B$31,SMALL(IF($O$4=$C$1:$C$31,ROW($C$1:$C$31)-MIN(ROW($B$1:$B$31))+1,""), ROW()-1)),"")} | AJ20: {=IFERROR(INDEX($B$32:$B$646,SMALL(IF($O$4=$C$32:$C$646,ROW($C$32:$C$646)-MIN(ROW($B$32:$B$646))+1,""), ROW()-1)),"")}
B21: {=IFERROR(_xlfn.IFS(E26=0,"",E26>0,E26),"")} -> John Franco Morenos Rosales | C21: {=IFERROR(_xlfn.IFS(F26=0,"",F26>0,F26),"")} -> x | E21: Tamara Izada Aguado | F21: x | O21: T | P21: Training | Q21: =COUNTIFS($F$5:$F$33,O21)+COUNTIFS($I$5:$I$33,O21) -> 0 | R21: 0 | S21: =LOOKUP(U1,'Deployment needs'!$2:$2,'Deployment needs'!94:94) -> 0 | U21: Region 12 UPH | V21: TBD | AA21: {=IFERROR(INDEX($B$1:$B$272,SMALL(IF($O$11=$C$1:$C$272,ROW($C$1:$C$272)-MIN(ROW($B$1:$B$272))+1,""), ROW()-12)),"")} | AB21: {=IFERROR(INDEX($B$1:$B$272,SMALL(IF(O$16=$C$1:$C$272,ROW($C$1:$C$272)-MIN(ROW($B$1:$B$272))+1,""), ROW()-12)),"")} | AC21: {=IFERROR(INDEX($B$1:$B$272,SMALL(IF($O$27=$C$1:$C$272,ROW($C$1:$C$272)-MIN(ROW($B$1:$B$272))+1,""), ROW()-16)),"")} | AE21: {=IFERROR(INDEX($B$1:$B$272,SMALL(IF($O$15=$C$1:$C$272,ROW($C$1:$C$272)-MIN(ROW($B$1:$B$272))+1,""), ROW()-16)),"")} | AF21: {=IFERROR(INDEX($B$1:$B$272,SMALL(IF($C$1:$C$272=$O$22, ROW($B$1:$B$272)-ROW($B$1)+1),ROWS($AF$12:AF21) ) ), "")} | AG21: {=IFERROR(INDEX($B$1:$B$272,SMALL(IF($O$25=$C$1:$C$272,ROW($C$1:$C$272)-MIN(ROW($B$1:$B$272))+1,""), ROW()-17)),"")} | AH21: {=IFERROR(INDEX($B$1:$B$272,SMALL(IF($O$32=$C$1:$C$272,ROW($C$1:$C$272)-MIN(ROW($B$1:$B$272))+1,""), ROW()-12)),"")} | AI21: {=IFERROR(INDEX($B$1:$B$272,SMALL(IF($O$4=$C$1:$C$272,ROW($C$1:$C$272)-MIN(ROW($B$1:$B$272))+1,""), ROW()-1)),"")} | AJ21: {=IFERROR(INDEX($B$32:$B$646,SMALL(IF($O$4=$C$32:$C$646,ROW($C$32:$C$646)-MIN(ROW($B$32:$B$646))+1,""), ROW()-1)),"")}
E22: Hector Rocha | F22: x | O22: RN | P22: Returns Processing | Q22: =COUNTIFS($F$5:$F$33,O22)+COUNTIFS($I$5:$I$33,O22) -> 0 | R22: =LOOKUP($U$1-1,'Inbound SOS & EOD'!$1:$1,'Inbound SOS & EOD'!41:41) -> 535 | S22: =LOOKUP(U1,'Deployment needs'!$2:$2,'Deployment needs'!81:81) -> 0.7027134 | AA22: {=IFERROR(INDEX($B$1:$B$272,SMALL(IF($O$11=$C$1:$C$272,ROW($C$1:$C$272)-MIN(ROW($B$1:$B$272))+1,""), ROW()-12)),"")} | AB22: {=IFERROR(INDEX($B$1:$B$272,SMALL(IF(O$16=$C$1:$C$272,ROW($C$1:$C$272)-MIN(ROW($B$1:$B$272))+1,""), ROW()-12)),"")} | AC22: Replen pull | AD22: Priority | AE22: {=IFERROR(INDEX($B$1:$B$272,SMALL(IF($O$15=$C$1:$C$272,ROW($C$1:$C$272)-MIN(ROW($B$1:$B$272))+1,""), ROW()-16)),"")} | AF22: {=IFERROR(INDEX($B$1:$B$272,SMALL(IF($C$1:$C$272=$O$22, ROW($B$1:$B$272)-ROW($B$1)+1),ROWS($AF$12:AF22) ) ), "")} | AG22: {=IFERROR(INDEX($B$1:$B$272,SMALL(IF($O$25=$C$1:$C$272,ROW($C$1:$C$272)-MIN(ROW($B$1:$B$272))+1,""), ROW()-17)),"")} | AH22: {=IFERROR(INDEX($B$1:$B$272,SMALL(IF($O$32=$C$1:$C$272,ROW($C$1:$C$272)-MIN(ROW($B$1:$B$272))+1,""), ROW()-12)),"")} | AI22: {=IFERROR(INDEX($B$1:$B$272,SMALL(IF($O$4=$C$1:$C$272,ROW($C$1:$C$272)-MIN(ROW($B$1:$B$272))+1,""), ROW()-1)),"")} | AJ22: {=IFERROR(INDEX($B$32:$B$646,SMALL(IF($O$4=$C$32:$C$646,ROW($C$32:$C$646)-MIN(ROW($B$32:$B$646))+1,""), ROW()-1)),"")}
E23: Iraldo Rodriguez | F23: x | O23: RE | P23: Returns Exceptions | Q23: =COUNTIFS($F$5:$F$33,O23)+COUNTIFS($I$5:$I$33,O23) -> 0 | R23: =LOOKUP($U$1-1,'Inbound SOS & EOD'!$1:$1,'Inbound SOS & EOD'!45:45) -> 40 | S23: =LOOKUP(U1,'Deployment needs'!$2:$2,'Deployment needs'!82:82) -> 0.062215434 | AA23: ="Receiving"&" "&R32 -> Receiving | AB23: Task | AC23: {=IFERROR(INDEX($B$1:$B$272,SMALL(IF($C$1:$C$272=$O$19, ROW($B$1:$B$272)-ROW($B$1)+1),ROWS($AC$23:AC23) ) ), "")} | AD23: All | AE23: {=IFERROR(INDEX($B$1:$B$272,SMALL(IF($O$15=$C$1:$C$272,ROW($C$1:$C$272)-MIN(ROW($B$1:$B$272))+1,""), ROW()-16)),"")} | AF23: {=IFERROR(INDEX($B$1:$B$272,SMALL(IF($C$1:$C$272=$O$22, ROW($B$1:$B$272)-ROW($B$1)+1),ROWS($AF$12:AF23) ) ), "")} | AG23: {=IFERROR(INDEX($B$1:$B$272,SMALL(IF($O$25=$C$1:$C$272,ROW($C$1:$C$272)-MIN(ROW($B$1:$B$272))+1,""), ROW()-17)),"")} | AH23: {=IFERROR(INDEX($B$1:$B$272,SMALL(IF($O$32=$C$1:$C$272,ROW($C$1:$C$272)-MIN(ROW($B$1:$B$272))+1,""), ROW()-12)),"")} | AI23: {=IFERROR(INDEX($B$1:$B$272,SMALL(IF($O$4=$C$1:$C$272,ROW($C$1:$C$272)-MIN(ROW($B$1:$B$272))+1,""), ROW()-1)),"")} | AJ23: {=IFERROR(INDEX($B$32:$B$646,SMALL(IF($O$4=$C$32:$C$646,ROW($C$32:$C$646)-MIN(ROW($B$32:$B$646))+1,""), ROW()-1)),"")}
E24: Jose Miro Quintana | F24: x | O24: RS | P24: Returns Sorting | Q24: =COUNTIFS($F$5:$F$33,O24)+COUNTIFS($I$5:$I$33,O24) -> 0 | R24: =LOOKUP($U$1-1,'Inbound SOS & EOD'!$1:$1,'Inbound SOS & EOD'!59:59) -> 637 | S24: =LOOKUP(U1,'Deployment needs'!$2:$2,'Deployment needs'!83:83) -> 0.22219798 | AJ24: {=IFERROR(INDEX($B$32:$B$646,SMALL(IF($O$4=$C$32:$C$646,ROW($C$32:$C$646)-MIN(ROW($B$32:$B$646))+1,""), ROW()-1)),"")}
E25: Jose Posse | F25: x | O25: RPA | P25: Returns put-away | Q25: =COUNTIFS($F$5:$F$33,O25)+COUNTIFS($I$5:$I$33,O25) -> 0 | AA25: {=IFERROR(INDEX($B$1:$B$272,SMALL(IF($C$1:$C$272=$O$26, ROW($B$1:$B$272)-ROW($B$1)+1),ROWS($AA$25:AA25) ) ), "")} | AC25: {=IFERROR(INDEX($B$1:$B$272,SMALL(IF($C$1:$C$272=$O$19, ROW($B$1:$B$272)-ROW($B$1)+1),ROWS($AC$23:AC25) ) ), "")} | AE25: Replen throw | AF25: {=IFERROR(INDEX($B$1:$B$272,SMALL(IF($C$1:$C$272=$O$22, ROW($B$1:$B$272)-ROW($B$1)+1),ROWS($AF$12:AF25) ) ), "")} | AG25: {=IFERROR(INDEX($B$1:$B$272,SMALL(IF($O$25=$C$1:$C$272,ROW($C$1:$C$272)-MIN(ROW($B$1:$B$272))+1,""), ROW()-17)),"")} | AH25: {=IFERROR(INDEX($B$1:$B$272,SMALL(IF($O$32=$C$1:$C$272,ROW($C$1:$C$272)-MIN(ROW($B$1:$B$272))+1,""), ROW()-12)),"")} | AI25: {=IFERROR(INDEX($B$1:$B$272,SMALL(IF($O$4=$C$1:$C$272,ROW($C$1:$C$272)-MIN(ROW($B$1:$B$272))+1,""), ROW()-1)),"")} | AJ25: {=IFERROR(INDEX($B$32:$B$646,SMALL(IF($O$4=$C$32:$C$646,ROW($C$32:$C$646)-MIN(ROW($B$32:$B$646))+1,""), ROW()-1)),"")}
E26: John Franco Morenos Rosales | F26: x | O26: RC | P26: Receiving | Q26: =COUNTIFS($F$5:$F$33,O26)+COUNTIFS($I$5:$I$33,O26) -> 0 | R26: =LOOKUP($U$1-1,'Inbound SOS & EOD'!$1:$1,'Inbound SOS & EOD'!56:56) -> 0 | S26: =LOOKUP(U1,'Deployment needs'!$2:$2,'Deployment needs'!73:73) -> 1.4739259 | AA26: {=IFERROR(INDEX($B$1:$B$272,SMALL(IF($C$1:$C$272=$O$26, ROW($B$1:$B$272)-ROW($B$1)+1),ROWS($AA$25:AA26) ) ), "")} | AC26: {=IFERROR(INDEX($B$1:$B$272,SMALL(IF($C$1:$C$272=$O$19, ROW($B$1:$B$272)-ROW($B$1)+1),ROWS($AC$23:AC26) ) ), "")} | AE26: {=IFERROR(INDEX($B$1:$B$272,SMALL(IF($C$1:$C$272=$O$20, ROW($B$1:$B$272)-ROW($B$1)+1),ROWS($AE$26:AE26) ) ), "")} | AF26: {=IFERROR(INDEX($B$1:$B$272,SMALL(IF($C$1:$C$272=$O$22, ROW($B$1:$B$272)-ROW($B$1)+1),ROWS($AF$12:AF26) ) ), "")} | AG26: {=IFERROR(INDEX($B$1:$B$272,SMALL(IF($O$25=$C$1:$C$272,ROW($C$1:$C$272)-MIN(ROW($B$1:$B$272))+1,""), ROW()-17)),"")} | AH26: {=IFERROR(INDEX($B$1:$B$272,SMALL(IF($O$32=$C$1:$C$272,ROW($C$1:$C$272)-MIN(ROW($B$1:$B$272))+1,""), ROW()-12)),"")} | AI26: {=IFERROR(INDEX($B$1:$B$272,SMALL(IF($O$4=$C$1:$C$272,ROW($C$1:$C$272)-MIN(ROW($B$1:$B$272))+1,""), ROW()-1)),"")} | AJ26: {=IFERROR(INDEX($B$32:$B$646,SMALL(IF($O$4=$C$32:$C$646,ROW($C$32:$C$646)-MIN(ROW($B$32:$B$646))+1,""), ROW()-1)),"")}
E27: David Almaguer-Benitez | F27: x | O27: CS | P27: Cubiscan | Q27: =COUNTIFS($F$5:$F$33,O27)+COUNTIFS($I$5:$I$33,O27) -> 0 | R27: =LOOKUP($U$1-1,'Inbound SOS & EOD'!$1:$1,'Inbound SOS & EOD'!57:57) -> 0 | S27: =LOOKUP(U1,'Deployment needs'!$2:$2,'Deployment needs'!74:74) -> 1.6581667 | AA27: {=IFERROR(INDEX($B$1:$B$272,SMALL(IF($C$1:$C$272=$O$26, ROW($B$1:$B$272)-ROW($B$1)+1),ROWS($AA$25:AA27) ) ), "")} | AC27: {=IFERROR(INDEX($B$1:$B$272,SMALL(IF($C$1:$C$272=$O$19, ROW($B$1:$B$272)-ROW($B$1)+1),ROWS($AC$23:AC27) ) ), "")} | AE27: {=IFERROR(INDEX($B$1:$B$272,SMALL(IF($C$1:$C$272=$O$20, ROW($B$1:$B$272)-ROW($B$1)+1),ROWS($AE$26:AE27) ) ), "")} | AF27: {=IFERROR(INDEX($B$1:$B$272,SMALL(IF($C$1:$C$272=$O$22, ROW($B$1:$B$272)-ROW($B$1)+1),ROWS($AF$12:AF27) ) ), "")} | AG27: {=IFERROR(INDEX($B$1:$B$272,SMALL(IF($O$25=$C$1:$C$272,ROW($C$1:$C$272)-MIN(ROW($B$1:$B$272))+1,""), ROW()-17)),"")} | AH27: {=IFERROR(INDEX($B$1:$B$272,SMALL(IF($O$32=$C$1:$C$272,ROW($C$1:$C$272)-MIN(ROW($B$1:$B$272))+1,""), ROW()-12)),"")} | AI27: {=IFERROR(INDEX($B$1:$B$272,SMALL(IF($O$4=$C$1:$C$272,ROW($C$1:$C$272)-MIN(ROW($B$1:$B$272))+1,""), ROW()-1)),"")} | AJ27: {=IFERROR(INDEX($B$32:$B$646,SMALL(IF($O$4=$C$32:$C$646,ROW($C$32:$C$646)-MIN(ROW($B$32:$B$646))+1,""), ROW()-1)),"")}
O28: BB | P28: Baby Bundle Project | Q28: =COUNTIFS($F$5:$F$33,O28)+COUNTIFS($I$5:$I$33,O28) -> 0 | R28: ='[3]2025 Progress tracker'!$D$15 -> 0 | U28: hours | V28: 2.5 | W28: 5 | X28: 10 | AA28: {=IFERROR(INDEX($B$1:$B$272,SMALL(IF($C$1:$C$272=$O$26, ROW($B$1:$B$272)-ROW($B$1)+1),ROWS($AA$25:AA28) ) ), "")} | AC28: {=IFERROR(INDEX($B$1:$B$272,SMALL(IF($O$19=$C$1:$C$272,ROW($C$1:$C$272)-MIN(ROW($B$1:$B$272))+1,""), ROW()-21)),"")} | AE28: {=IFERROR(INDEX($B$1:$B$272,SMALL(IF($C$1:$C$272=$O$20, ROW($B$1:$B$272)-ROW($B$1)+1),ROWS($AE$26:AE28) ) ), "")} | AF28: ="Returns Exceptions"&" "&$X$48 -> Returns Exceptions estimate | AG28: {=IFERROR(INDEX($B$1:$B$272,SMALL(IF($O$25=$C$1:$C$272,ROW($C$1:$C$272)-MIN(ROW($B$1:$B$272))+1,""), ROW()-17)),"")} | AH28: {=IFERROR(INDEX($B$1:$B$272,SMALL(IF($O$32=$C$1:$C$272,ROW($C$1:$C$272)-MIN(ROW($B$1:$B$272))+1,""), ROW()-12)),"")} | AI28: {=IFERROR(INDEX($B$1:$B$272,SMALL(IF($O$4=$C$1:$C$272,ROW($C$1:$C$272)-MIN(ROW($B$1:$B$272))+1,""), ROW()-1)),"")} | AJ28: {=IFERROR(INDEX($B$32:$B$646,SMALL(IF($O$4=$C$32:$C$646,ROW($C$32:$C$646)-MIN(ROW($B$32:$B$646))+1,""), ROW()-1)),"")}
O29: WU | P29: Warehouse Utility | Q29: =COUNTIFS($F$5:$F$33,O29)+COUNTIFS($I$5:$I$33,O29) -> 0 | U29: region | V29: # pickers | W29: UPH | X29: estimate | AA29: {=IFERROR(INDEX($B$1:$B$272,SMALL(IF($C$1:$C$272=$O$26, ROW($B$1:$B$272)-ROW($B$1)+1),ROWS($AA$25:AA29) ) ), "")} | AC29: Aisle & DC Cleanup | AE29: {=IFERROR(INDEX($B$1:$B$272,SMALL(IF($C$1:$C$272=$O$20, ROW($B$1:$B$272)-ROW($B$1)+1),ROWS($AE$26:AE29) ) ), "")} | AF29: {=IFERROR(INDEX($B$1:$B$272,SMALL(IF($O$23=$C$1:$C$272,ROW($C$1:$C$272)-MIN(ROW($B$1:$B$272))+1,""), ROW()-26)),"")} | AG29: {=IFERROR(INDEX($B$1:$B$272,SMALL(IF($O$25=$C$1:$C$272,ROW($C$1:$C$272)-MIN(ROW($B$1:$B$272))+1,""), ROW()-17)),"")} | AH29: {=IFERROR(INDEX($B$1:$B$272,SMALL(IF($O$32=$C$1:$C$272,ROW($C$1:$C$272)-MIN(ROW($B$1:$B$272))+1,""), ROW()-12)),"")} | AI29: {=IFERROR(INDEX($B$1:$B$272,SMALL(IF($O$4=$C$1:$C$272,ROW($C$1:$C$272)-MIN(ROW($B$1:$B$272))+1,""), ROW()-1)),"")} | AJ29: {=IFERROR(INDEX($B$32:$B$646,SMALL(IF($O$4=$C$32:$C$646,ROW($C$32:$C$646)-MIN(ROW($B$32:$B$646))+1,""), ROW()-1)),"")}
O30: SL | P30: Support | Q30: =COUNTIFS($F$5:$F$33,O30)+COUNTIFS($I$5:$I$33,O30) -> 2 | U30: Picking- Bulk | V30: 20 | W30: 175 | X30: =W30*V30*$W$28 -> 17500 | AA30: {=IFERROR(INDEX($B$1:$B$272,SMALL(IF($C$1:$C$272=$O$26, ROW($B$1:$B$272)-ROW($B$1)+1),ROWS($AA$25:AA30) ) ), "")} | AC30: {=IFERROR(INDEX($B$1:$B$272,SMALL(IF($O$33=$C$1:$C$272,ROW($C$1:$C$272)-MIN(ROW($B$1:$B$272))+1,""), ROW()-26)),"")} | AE30: {=IFERROR(INDEX($B$1:$B$272,SMALL(IF($C$1:$C$272=$O$20, ROW($B$1:$B$272)-ROW($B$1)+1),ROWS($AE$26:AE30) ) ), "")} | AF30: {=IFERROR(INDEX($B$1:$B$272,SMALL(IF($O$23=$C$1:$C$272,ROW($C$1:$C$272)-MIN(ROW($B$1:$B$272))+1,""), ROW()-26)),"")} | AG30: {=IFERROR(INDEX($B$1:$B$272,SMALL(IF($O$25=$C$1:$C$272,ROW($C$1:$C$272)-MIN(ROW($B$1:$B$272))+1,""), ROW()-17)),"")} | AH30: {=IFERROR(INDEX($B$1:$B$272,SMALL(IF($O$32=$C$1:$C$272,ROW($C$1:$C$272)-MIN(ROW($B$1:$B$272))+1,""), ROW()-12)),"")} | AI30: {=IFERROR(INDEX($B$1:$B$272,SMALL(IF($O$4=$C$1:$C$272,ROW($C$1:$C$272)-MIN(ROW($B$1:$B$272))+1,""), ROW()-1)),"")} | AJ30: {=IFERROR(INDEX($B$32:$B$646,SMALL(IF($O$4=$C$32:$C$646,ROW($C$32:$C$646)-MIN(ROW($B$32:$B$646))+1,""), ROW()-1)),"")} | AL30: 2nd
O31: SP | P31: Special Projects | Q31: =COUNTIFS($F$5:$F$33,O31)+COUNTIFS($I$5:$I$33,O31) -> 0 | S31: =LOOKUP(U1,'Deployment needs'!$2:$2,'Deployment needs'!96:96) -> 0 | U31: Picking- Singles | V31: 0 | W31: 175 | X31: =W31*V31*$V$28 -> 0 | AA31: {=IFERROR(INDEX($B$1:$B$272,SMALL(IF($C$1:$C$272=$O$26, ROW($B$1:$B$272)-ROW($B$1)+1),ROWS($AA$25:AA31) ) ), "")} | AC31: {=IFERROR(INDEX($B$1:$B$272,SMALL(IF($O$33=$C$1:$C$272,ROW($C$1:$C$272)-MIN(ROW($B$1:$B$272))+1,""), ROW()-26)),"")} | AE31: {=IFERROR(INDEX($B$1:$B$272,SMALL(IF($C$1:$C$272=$O$20, ROW($B$1:$B$272)-ROW($B$1)+1),ROWS($AE$26:AE31) ) ), "")} | AF31: {=IFERROR(INDEX($B$1:$B$272,SMALL(IF($O$23=$C$1:$C$272,ROW($C$1:$C$272)-MIN(ROW($B$1:$B$272))+1,""), ROW()-26)),"")} | AG31: {=IFERROR(INDEX($B$1:$B$272,SMALL(IF($O$25=$C$1:$C$272,ROW($C$1:$C$272)-MIN(ROW($B$1:$B$272))+1,""), ROW()-17)),"")} | AH31: {=IFERROR(INDEX($B$1:$B$272,SMALL(IF($O$32=$C$1:$C$272,ROW($C$1:$C$272)-MIN(ROW($B$1:$B$272))+1,""), ROW()-12)),"")} | AI31: {=IFERROR(INDEX($B$1:$B$272,SMALL(IF($O$4=$C$1:$C$272,ROW($C$1:$C$272)-MIN(ROW($B$1:$B$272))+1,""), ROW()-1)),"")} | AJ31: {=IFERROR(INDEX($B$32:$B$646,SMALL(IF($O$4=$C$32:$C$646,ROW($C$32:$C$646)-MIN(ROW($B$32:$B$646))+1,""), ROW()-1)),"")}
B32: {=IFERROR(_xlfn.IFS(G5=0,"",G5>0,G5),"")} -> Deja Andersson | C32: {=IFERROR(_xlfn.IFS(I5=0,"",I5>0,I5),"")} -> SL | O32: I | P32: Inventory functions | Q32: =COUNTIFS($F$5:$F$33,O32)+COUNTIFS($I$5:$I$33,O32) -> 3 | S32: {=LOOKUP(U1,'Deployment needs'!$2:$2,('Deployment needs'!76:76+'Deployment needs'!89:89+'Deployment needs'!90:90))} -> 0.5 | AA32: Overstock Cycle Count | AB32: ="Overstock Putaway"&" "&T37 -> Overstock Putaway | AC32: {=IFERROR(INDEX($B$1:$B$272,SMALL(IF($O$33=$C$1:$C$272,ROW($C$1:$C$272)-MIN(ROW($B$1:$B$272))+1,""), ROW()-26)),"")} | AE32: {=IFERROR(INDEX($B$1:$B$272,SMALL(IF($C$1:$C$272=$O$20, ROW($B$1:$B$272)-ROW($B$1)+1),ROWS($AE$26:AE32) ) ), "")} | AF32: {=IFERROR(INDEX($B$1:$B$272,SMALL(IF($O$23=$C$1:$C$272,ROW($C$1:$C$272)-MIN(ROW($B$1:$B$272))+1,""), ROW()-26)),"")} | AG32: {=IFERROR(INDEX($B$1:$B$272,SMALL(IF($O$25=$C$1:$C$272,ROW($C$1:$C$272)-MIN(ROW($B$1:$B$272))+1,""), ROW()-17)),"")} | AH32: {=IFERROR(INDEX($B$1:$B$272,SMALL(IF($O$32=$C$1:$C$272,ROW($C$1:$C$272)-MIN(ROW($B$1:$B$272))+1,""), ROW()-12)),"")} | AI32: {=IFERROR(INDEX($B$1:$B$272,SMALL(IF($O$4=$C$1:$C$272,ROW($C$1:$C$272)-MIN(ROW($B$1:$B$272))+1,""), ROW()-1)),"")} | AJ32: {=IFERROR(INDEX($B$32:$B$646,SMALL(IF($O$4=$C$32:$C$646,ROW($C$32:$C$646)-MIN(ROW($B$32:$B$646))+1,""), ROW()-1)),"")}
B33: {=IFERROR(_xlfn.IFS(G6=0,"",G6>0,G6),"")} -> Eumary Quinones | C33: {=IFERROR(_xlfn.IFS(I6=0,"",I6>0,I6),"")} -> I | E33: =COUNTIFS(E5:E32,"*") -> 23 | F33: =COUNTIFS(F5:F32,$O$38)+COUNTIFS(F5:F32,$O$39)+COUNTIFS(F5:F32,$O$40)+COUNTIFS(F5:F32,$O$41)+COUNTIFS(F5:F32,$O$42)+COUNTIFS(F5:F32,$O$43)+COUNTIFS(F5:F32,$O$44)+COUNTIFS(F5:F32,$O$45)+COUNTIFS(F5:F32,$O$198) -> 20 | G33: =COUNTIFS(G5:G32,"*") -> 12 | I33: =COUNTIFS(I5:I32,$O$38)+COUNTIFS(I5:I32,$O$39)+COUNTIFS(I5:I32,$O$40)+COUNTIFS(I5:I32,$O$41)+COUNTIFS(I5:I32,$O$42)+COUNTIFS(I5:I32,$O$43)+COUNTIFS(I5:I32,$O$44)+COUNTIFS(I5:I32,$O$45)+COUNTIFS(F5:I32,$O$198) -> 10 | J33: =COUNTIFS(L5:L32,"*") -> 0 | L33: =COUNTIFS(L5:L33,$O$77)+COUNTIFS(L5:L33,$O$78)+COUNTIFS(L5:L33,$O$194)+COUNTIFS(L5:L33,$O$195)+COUNTIFS(L5:L33,$O$196)+COUNTIFS(L5:L33,$O$197)+COUNTIFS(L5:L33,$O$199)+COUNTIFS(L5:L33,$O$200) -> 0 | O33: W | P33: Warehouse Cleaning | Q33: =COUNTIFS($F$5:$F$33,O33)+COUNTIFS($I$5:$I$33,O33) -> 0 | S33: =LOOKUP(U1,'Deployment needs'!$2:$2,'Deployment needs'!77:77) -> 1 | U33: TOTAL | X33: =SUM(X30:X32) -> 17500 | AA33: {=IFERROR(INDEX($B$1:$B$272,SMALL(IF($O$17=$C$1:$C$272,ROW($C$1:$C$272)-MIN(ROW($B$1:$B$272))+1,""), ROW()-31)),"")} | AB33: {=IFERROR(INDEX($B$1:$B$272,SMALL(IF($O$18=$C$1:$C$272,ROW($C$1:$C$272)-MIN(ROW($B$1:$B$272))+1,""), ROW()-31)),"")} | AC33: {=IFERROR(INDEX($B$1:$B$272,SMALL(IF($O$33=$C$1:$C$272,ROW($C$1:$C$272)-MIN(ROW($B$1:$B$272))+1,""), ROW()-26)),"")} | AE33: {=IFERROR(INDEX($B$1:$B$272,SMALL(IF($O$20=$C$1:$C$272,ROW($C$1:$C$272)-MIN(ROW($B$1:$B$272))+1,""), ROW()-20)),"")} | AF33: {=IFERROR(INDEX($B$1:$B$272,SMALL(IF($O$23=$C$1:$C$272,ROW($C$1:$C$272)-MIN(ROW($B$1:$B$272))+1,""), ROW()-26)),"")} | AG33: {=IFERROR(INDEX($B$1:$B$272,SMALL(IF($O$25=$C$1:$C$272,ROW($C$1:$C$272)-MIN(ROW($B$1:$B$272))+1,""), ROW()-17)),"")} | AH33: {=IFERROR(INDEX($B$1:$B$272,SMALL(IF($O$32=$C$1:$C$272,ROW($C$1:$C$272)-MIN(ROW($B$1:$B$272))+1,""), ROW()-12)),"")} | AI33: {=IFERROR(INDEX($B$1:$B$272,SMALL(IF($O$4=$C$1:$C$272,ROW($C$1:$C$272)-MIN(ROW($B$1:$B$272))+1,""), ROW()-1)),"")} | AJ33: {=IFERROR(INDEX($B$32:$B$646,SMALL(IF($O$4=$C$32:$C$646,ROW($C$32:$C$646)-MIN(ROW($B$32:$B$646))+1,""), ROW()-1)),"")}
B34: {=IFERROR(_xlfn.IFS(G7=0,"",G7>0,G7),"")} -> Sunia Hernandez | C34: {=IFERROR(_xlfn.IFS(I7=0,"",I7>0,I7),"")} -> x | P34: Total | Q34: =F36-F33-I33 -> 5 | S34: =SUM(S3:S33) -> 23.431665 | AA34: {=IFERROR(INDEX($B$1:$B$272,SMALL(IF($O$17=$C$1:$C$272,ROW($C$1:$C$272)-MIN(ROW($B$1:$B$272))+1,""), ROW()-31)),"")} | AB34: {=IFERROR(INDEX($B$1:$B$272,SMALL(IF($O$18=$C$1:$C$272,ROW($C$1:$C$272)-MIN(ROW($B$1:$B$272))+1,""), ROW()-31)),"")} | AC34: {=IFERROR(INDEX($B$1:$B$272,SMALL(IF($O$33=$C$1:$C$272,ROW($C$1:$C$272)-MIN(ROW($B$1:$B$272))+1,""), ROW()-26)),"")} | AE34: Warehouse Utility | AF34: {=IFERROR(INDEX($B$1:$B$272,SMALL(IF($O$23=$C$1:$C$272,ROW($C$1:$C$272)-MIN(ROW($B$1:$B$272))+1,""), ROW()-26)),"")} | AG34: {=IFERROR(INDEX($B$1:$B$272,SMALL(IF($O$25=$C$1:$C$272,ROW($C$1:$C$272)-MIN(ROW($B$1:$B$272))+1,""), ROW()-17)),"")} | AH34: {=IFERROR(INDEX($B$1:$B$272,SMALL(IF($O$32=$C$1:$C$272,ROW($C$1:$C$272)-MIN(ROW($B$1:$B$272))+1,""), ROW()-12)),"")} | AI34: {=IFERROR(INDEX($B$1:$B$272,SMALL(IF($O$4=$C$1:$C$272,ROW($C$1:$C$272)-MIN(ROW($B$1:$B$272))+1,""), ROW()-1)),"")} | AJ34: {=IFERROR(INDEX($B$32:$B$646,SMALL(IF($O$4=$C$32:$C$646,ROW($C$32:$C$646)-MIN(ROW($B$32:$B$646))+1,""), ROW()-1)),"")}
